Workbook

Sheet 5.arrchage arbre
A1: Chantier | D1: Tâche
A2: BARBAZAN | D2: ARRACHAGE OU ABATTAGE ET DESSOUCHAGE D’ARBRES
A3: Tache immédiatement antécédante | E3: Quantité | F3: Unité | G3: Rendement | H3: durée
E4: 8 | F4: Unité | G4: 13min/u | H4: 1h44min
A5: Descriptif (source CCTP bordereau …)
A6: Ce prix rémunère à l'unité l'arrachage ou abattage et dessouchage d'arbres.Il comprend l'arrachage ou abattage et dessouchage des arbres dont la circonférence mesurée à 1 m du sol est supérieure à 0.60 m ou leur abattage et l'extraction de leur souche - l'évacuation des produits après brûlage éventuel dans un dépôt agrée par le maître d'oeuvre.
A7: Matériel | E7: Main d'œuvre
A8: désignation | B8: Qté | C8: affectation tâche | E8: désignation | F8: Quantité | G8: affectation tâche
A9: pelle | B9: 1 | C9: dessouchage & transport | E9: OHQ | F9: 1 | G9: découpe arbre
A10: tronçonneuse | B10: 1 | C10: découpe arbre | E10: conducteur pelle | F10: 1 | G10: conduit la pelle
A11: Description du mode opératoire
A12: Un homme utilise la tronçonneuse pour découper et faire tomber si possible les arbres en toute sécurité. Un homme conduit la pelle, il creuse autour des souches pour faire sauter les racines, puis la souche. Il évacue les déchets dans la benne prévu pour.
A15: Calcul de rendement, métré de fourniture, calcul de temps de transport, nombre de tours
A16: Donnée | B16: Quantité | D16: Donnée | E16: Quantité
A17: Nombre d'arbre | B17: =E4 -> 8
A18: Tronçonnage
A19: Temps (min)/arbre | B19: 3
A20: Temps total (min) | B20: =B19*B17 -> 24
A21: Dessouchage
A22: Temps (min)/arbre | B22: 10
A23: Temps total (min) | B23: =B22*B17 -> 80
A25: Temps TOTAL (min) | B25: =B20+B23 -> 104
B26: =B25/60/24 -> 0.072222222
A28: FOURNITURE & SOUS-TRAITANCE | F28: Fournisseur
A29: désignation | B29: Qté | C29: Unité | D29: P.U. | E29: Total | F29: Qui? | G29: Distance chantier | H29: Nbre de tours/jour
D31: =IF(A31="","",VLOOKUP(A31,$O$3:$P$13,2,FALSE)) | E31: =IF(A31="","",B31*D31)

Sheet 6.démo découpe chaussée
A1: Chantier | D1: Tâche
A2: BARBAZAN | D2: DEMOLITION DECOUPE CHAUSSEE A LA SCIE HYDRAULIQUE ( Y COMPRIS ÉVACUATION DES GRAVATS)
A3: Tache immédiatement antécédante | E3: Quantité | F3: Unité | G3: Rendement | H3: durée
E4: 223.8 | F4: m2 | G4: 72,32m3/h | H4: 37min08s
A5: Descriptif (source CCTP bordereau …)
A6: Ce prix rémunère au mètre carré la découpe de la chaussée à la scie hydraulique et la démolition sur 0.20 m de profondeur . Il comprend le chargement, le transport et le déchargement des produits au lieu de dépôt agréé par le maître d'œuvre.
A7: Matériel | E7: Main d'œuvre
A8: désignation | B8: Qté | C8: affectation tâche | E8: désignation | F8: Quantité | G8: affectation tâche
A9: camion 25t | B9: 5 | C9: évacuation déchet | E9: pelle | F9: 1 | G9: décroute et transfert au camion les déchets
A11: Description du mode opératoire
A12: La pelle décroute la chaussée préalablement découpé, puis transfert les déchets dans le camion. Le camion une fois remplis, part pour évacuer les déchets en centre de recyclage.
A15: Calcul de rendement, métré de fourniture, calcul de temps de transport, nombre de tours
A16: Donnée | B16: Quantité | D16: Donnée | E16: Quantité
A17: Surface | B17: =E4 -> 223.8 | D17: Transport
A18: epaisseur | B18: 0.2 | D18: Capacité (T) | E18: 25
A19: volume | B19: =B18*B17 -> 44.76 | D19: Densité | E19: 2.5
A20: Décroutage chaussée | D20: Capacité (m3) | E20: =E18/E19 -> 10
A21: Godet (L) | B21: 1000 | D21: nb cycle remplissage | E21: =E20/B22 -> 10
A22: Godet (m3) | B22: =B21/1000 -> 1 | D22: Arrondi | E22: =ROUNDUP(E21,0) -> 10
A23: Nb godet nécessaire | B23: =B19/B22 -> 44.76 | D23: Temps remplissage (s) | E23: =E22*B31 -> 373.33333
A24: T1 (s) | B24: 10 | D24: temps en minutes | E24: =E23/60 -> 6.2222222
A25: T2 (s) | B25: 6 | D25: Distance (Km) | E25: =+G43 -> 27
A26: T3 (s) | B26: 6 | D26: vitesse en (Km/h) | E26: 50
A27: T4 (s) | B27: 6 | D27: Temps de voyage (min) | E27: =E25/E26*60 -> 32.4
A28: Total 1 cycle (s) | B28: =SUM(B24:B27) -> 28 | D28: T1 (min) | E28: =E24 -> 6.2222222
A29: Efficience volume | B29: =60/80 -> 0.75 | D29: T2 (min) | E29: =E27 -> 32.4
A30: Efficience temps | B30: =80/60 -> 1.3333333 | D30: T3 (min) | E30: 5
A31: 1cycle efficient (s) | B31: =B28*B30 -> 37.333333 | D31: T4 (min) | E31: =E27 -> 32.4
A32: cycle / min | B32: =60/B31 -> 1.6071429 | D32: Total 1 cycle (min) | E32: =SUM(E28:E31) -> 76.022222
A33: cycle / heure | B33: =B32*60 -> 96.428571 | D33: Nombre de camions saturation | E33: =E32/E28 -> 12.217857
A34: Volume / heure (m3) | B34: =B33*B22 -> 96.428571 | D34: arrondi | E34: =ROUNDUP(E33,0) -> 13
A35: Volume / heure effecient (m3) | B35: =B34*B29 -> 72.321429 | D35: volume total des camions (m3) | E35: =E34*E20 -> 130
A36: Temps d'activité décimale | B36: =B19/B35 -> 0.6189037 | D36: nombre de tour/camion | E36: =B19/E35 -> 0.34430769
A37: Temps d'activité sexagésimal | B37: =B36/24 -> 0.025787654 | D37: arrondi | E37: =ROUNDUP(E36,0) -> 1
D38: Temps des camions (min) | E38: =E32*E39 -> 380.11111
D39: Nombre de camion nécessaire | E39: =ROUNDUP(B19/E20,0) -> 5
D40: Temps des camions (H) | E40: =E38/60/24 -> 0.26396605
A41: FOURNITURE & SOUS-TRAITANCE | F41: Fournisseur
A42: désignation | B42: Qté | C42: Unité | D42: P.U. | E42: Total | F42: Qui? | G42: Distance chantier | H42: Nbre de tours/jour
A43: centre de recyclage | B43: =B19*E19 -> 111.9 | C43: T | D43: 3 | E43: =B43*D43 -> 335.7 | F43: PSI? 570 RUE DE PEYRHITTE 65300 LANNEMEZAN | G43: 27 | H43: 5
...

Sheet 7.sciage de chaussé
A1: Chantier | D1: Tâche
A2: BARBAZAN | D2: SCIAGE DE CHAUSSEE A LA SCIE HYDRAULIQUE
A3: Tache immédiatement antécédante | E3: Quantité | F3: Unité | G3: Rendement | H3: durée
E4: 300 | F4: ml | G4: 60ml/h | H4: =B19 -> 0.20833333
A5: Descriptif (source CCTP bordereau …)
A6: Ce prix rémunère au mètre linéaire le sciage de chaussée à la scie hydraulique sur 0.20m de profondeur. Il comprend le sciage, le chargement, le transport et le déchargement des produits dans un dépôt proposé par l'entrepreneur et agréé par le maître d'oeuvre.
A7: Matériel | E7: Main d'œuvre
A8: désignation | B8: Qté | C8: affectation tâche | E8: désignation | F8: Quantité | G8: affectation tâche
A9: scie à sol | B9: 1 | C9: découpe l'ancienne chaussée | E9: manœuvre | F9: 1 | G9: utilise la scie à sol
A11: Description du mode opératoire
A12: un homme utilise la scie à sol pour découper la chaussée sur 20cm de profondeur sur les endroits choisis.
A13: Calcul de rendement, métré de fourniture, calcul de temps de transport, nombre de tours
A14: Donnée | B14: Quantité
A15: Metre linéraire | B15: =E4 -> 300
A16: Scie à sol
A17: Vitesse (m/min) | B17: 1
A18: Temps de découpe (min) | B18: =B17*B15 -> 300
B19: =B18/60/24 -> 0.20833333
A20: rdm | B20: =300/5 -> 60
A25: FOURNITURE & SOUS-TRAITANCE | F25: Fournisseur
A26: désignation | B26: Qté | C26: Unité | D26: P.U. | E26: Total | F26: Qui? | G26: Distance chantier | H26: Nbre de tours/jour
D28: =IF(A28="","",VLOOKUP(A28,$O$3:$P$12,2,FALSE)) | E28: =IF(A28="","",B28*D28)

Sheet 8.rabottage
A1: Chantier | D1: Tâche
A2: BARBAZAN | D2: RABOTAGE DE CHAUSSEE
A3: Tache immédiatement antécédante | E3: Quantité | F3: Unité | G3: Rendement | H3: durée
E4: 263.52 | F4: m2 | G4: 10m2/min | H4: =E19 -> 0.021772222
A5: Descriptif (source CCTP bordereau …)
A6: Ce prix rémunère au mètre carré de surface effective le rabotage de chaussée. Il comprend le rabotage du revêtement existant sur une épaisseur jusqu'à 6 cm, l'extraction des matériaux, leur évacuation à la décharge ou la mise en dépôt provisoire.
A7: Matériel | E7: Main d'œuvre
A8: désignation | B8: Qté | C8: affectation tâche | E8: désignation | F8: Quantité | G8: affectation tâche
A9: Fraiseuse à froid 200 i | B9: 1 | C9: rabote l'ancienne chaussée
A10: camion 25t | B10: 2 | C10: suit rabotteuse + évacuation
A11: Description du mode opératoire
A12: La fraiseuse à froid va rabotter la zone définie, un camion sera devant pour récupérer les déchets par la rampe. Une fois remplie, le camion plein par pour la déchetterie, et un autre prend sa place.
A15: Calcul de rendement, métré de fourniture, calcul de temps de transport, nombre de tours
A16: Donnée | B16: Quantité | D16: Donnée | E16: Quantité
A17: dimension chaussée | D17: temps changement de camion (min) | E17: 5
A18: surface | B18: =E4 -> 263.52 | E18: =E17/60/24 -> 0.0034722222
A19: ep | B19: 0.06 | D19: temps total | E19: =E18+B29 -> 0.021772222
A20: volume | B20: =B19*B18 -> 15.8112
A21: densité | B21: 2.5
A22: Tonne | B22: =B21*B20 -> 39.528
A23: raboteuse
A24: vitesse (m/min) | B24: 5
A25: largeur de fraisage (m) | B25: 2
A26: Rdmt (m2/min) | B26: =B25*B24 -> 10
A27: m3/min | B27: =B26*B19 -> 0.6
A28: temps rabotage (min) | B28: =B18/B26 -> 26.352
B29: =B28/60/24 -> 0.0183
A30: Camion
A31: capacité (t) | B31: 25
A32: en m3 | B32: =B31/B21 -> 10
A33: nombre de camion nec | B33: =B20/B32 -> 1.58112
A34: arrondi | B34: =ROUNDUP(B33,0) -> 2
A35: Temps remplissage camion N°1 | B35: =B32/B27 -> 16.666667
B36: =B35/60/24 -> 0.011574074
A37: Temps remplissage camion N°2 | B37: =B29-B36 -> 0.0067259259
A38: FOURNITURE & SOUS-TRAITANCE | F38: Fournisseur
A39: désignation | B39: Qté | C39: Unité | D39: P.U. | E39: Total | F39: Qui? | G39: Distance chantier | H39: Nbre de tours/jour
A40: centre de recyclage | B40: =B22 -> 39.528 | C40: t | D40: 3 | E40: =B40*D40 -> 118.584 | F40: PSI? 570 RUE DE PEYRHITTE 65300 LANNEMEZAN | G40: 27 | H40: 1
D41: =IF(A41="","",VLOOKUP(A41,$O$3:$P$13,2,FALSE)) | E41: =IF(A41="","",B41*D41)

Sheet 9.démolition trottoir illot
A1: Chantier | D1: Tâche
A2: BARBAZAN | D2: DEMOLITION DE TROTTOIRS OU D’ILOTS
A3: Tache immédiatement antécédante | E3: Quantité | F3: Unité | G3: Rendement | H3: durée
E4: 303.91 | F4: m2 | G4: 289m2/h | H4: =B37 -> 0.043773045
A5: =M24 -> 0
A6: Ce prix rémunère au mètre carré les travaux de démolition aux engins mécaniques de trottoirs béton ou d'ilots sur 0,20 m d'épaisseur, et l'évacuation des déblais.
A7: Matériel | E7: Main d'œuvre
A8: désignation | B8: Qté | C8: affectation tâche | E8: désignation | F8: Quantité | G8: affectation tâche
A9: camion 25t | B9: 5 | C9: évacuation déchet | E9: conducteur de pelle | F9: 1 | G9: décroute et transfert au camion les déchets
A10: pelle | B10: 1 | C10: décroute et transfert au camion les déchets
A11: Description du mode opératoire
A12: La pelle démolit les trottoirs et ilots présents sur l'emprise, puis transfert les déchets dans le camion. Le camion une fois remplis, part pour évacuer les déchets en centre de recyclage.
A15: Calcul de rendement, métré de fourniture, calcul de temps de transport, nombre de tours
A16: Donnée | B16: Quantité | D16: Donnée | E16: Quantité
A17: Surface | B17: =E4 -> 303.91 | D17: Transport
A18: epaisseur | B18: 0.2 | D18: Capacité (T) | E18: 25 | G18: rdm | H18: =E4/B36 -> 289.28571
A19: volume | B19: =B18*B17 -> 60.782 | D19: Densité | E19: 2.5
A20: Décroutage chaussée | D20: Capacité (m3) | E20: =E18/E19 -> 10
A21: Godet (L) | B21: 800 | D21: nb cycle remplissage | E21: =E20/B22 -> 12.5
A22: Godet (m3) | B22: =B21/1000 -> 0.8 | D22: Arrondi | E22: =ROUNDUP(E21,0) -> 13
A23: Nb godet nécessaire | B23: =B19/B22 -> 75.9775 | D23: Temps remplissage (s) | E23: =E22*B31 -> 485.33333
A24: T1 (s) | B24: 10 | D24: temps en minutes | E24: =E23/60 -> 8.0888889
A25: T2 (s) | B25: 6 | D25: Distance (Km) | E25: =G43 -> 8.2
A26: T3 (s) | B26: 6 | D26: vitesse en (Km/h) | E26: 50
A27: T4 (s) | B27: 6 | D27: Temps de voyage (min) | E27: =E25/E26*60 -> 9.84
A28: Total 1 cycle (s) | B28: =SUM(B24:B27) -> 28 | D28: T1 (min) | E28: =E24 -> 8.0888889
A29: Efficience volume | B29: =60/80 -> 0.75 | D29: T2 (min) | E29: =E27 -> 9.84
A30: Efficience temps | B30: =80/60 -> 1.3333333 | D30: T3 (min) | E30: 5
A31: 1cycle efficient (s) | B31: =B28*B30 -> 37.333333 | D31: T4 (min) | E31: =E27 -> 9.84
A32: cycle / min | B32: =60/B31 -> 1.6071429 | D32: Total 1 cycle (min) | E32: =SUM(E28:E31) -> 32.768889
A33: cycle / heure | B33: =B32*60 -> 96.428571 | D33: Nombre de camions saturation | E33: =E32/E28 -> 4.0510989
A34: Volume / heure (m3) | B34: =B33*B22 -> 77.142857 | D34: arrondi | E34: =ROUNDUP(E33,0) -> 5
A35: Volume / heure effecient (m3) | B35: =B34*B29 -> 57.857143 | D35: volume total des camions (m3) | E35: =E34*E20 -> 50
A36: Temps d'activité décimale | B36: =B19/B35 -> 1.0505531 | D36: nombre de tour/camion | E36: =B19/E35 -> 1.21564
A37: Temps d'activité sexagésimal | B37: =B36/24 -> 0.043773045 | D37: arrondi | E37: =ROUNDUP(E36,0) -> 2
D38: Temps des camions (min) | E38: =E32*E39 -> 229.38222
D39: Nombre de camion nécessaire | E39: =ROUNDUP(B19/E20,0) -> 7
D40: Temps des camions (H) | E40: =E38/60/24 -> 0.15929321
A41: FOURNITURE & SOUS-TRAITANCE | F41: Fournisseur
A42: désignation | B42: Qté | C42: Unité | D42: P.U. | E42: Total | F42: Qui? | G42: Distance chantier | H42: Nbre de tours/jour
...

Sheet 10.décapage terre végé
A1: Chantier | D1: Tâche
A2: BARBAZAN | D2: DECAPAGE TERRE VEGETALE
A3: Tache immédiatement antécédante | E3: Quantité | F3: Unité | G3: Rendement | H3: durée
E4: 3100 | F4: m2 | G4: 241m2/h | H4: =B37 -> 0.53580247
A5: Descriptif (source CCTP bordereau …)
A6: Ce prix rémunère au mètre carré le décapage de terre végétale. Il comprend : - l'enlèvement de la terre végétale sur 0.30 m d'épaisseur, - l'élimination des produits étrangers (grosses racines, pierres, déchets divers...), - le chargement, le transport, le déchargement et la mise en dépôt soit sur le chantier pour son éventuel réemploi, soit dans un lieu agrée par le maître d'oeuvre.
A7: Matériel | E7: Main d'œuvre
A8: désignation | B8: Qté | C8: affectation tâche | E8: désignation | F8: Quantité | G8: affectation tâche
A9: pelle | B9: 1 | C9: décapage et tranfert | E9: conducteur de pelle | F9: 1 | G9: conduit la pelle
A11: Description du mode opératoire
A12: La pelle décape les zones identifiées sur 0,30 m de profondeur. Elle met en stockage sur place la terre végétale pour une tache utlérieur.
A15: Calcul de rendement, métré de fourniture, calcul de temps de transport, nombre de tours
A16: Donnée | B16: Quantité | D16: Donnée | E16: Quantité
A17: Surface (m²) | B17: =E4 -> 3100 | D17: Transport
A18: Epaisseur (m) | B18: 0.3 | D18: Capacité (T) | E18: 26
A19: Volume (m3) | B19: =B17*B18 -> 930 | D19: Densité | E19: 1.5
A20: Déblais Terre végétale | D20: Capacité (m3) | E20: =E18/E19 -> 17.333333
A21: Godet (L) | B21: 1000 | D21: nb cycle remplissage | E21: =E20/B22 -> 17.333333
A22: Godet (m3) | B22: =B21/1000 -> 1 | D22: Arrondi | E22: =ROUNDUP(E21,0) -> 18 | G22: rdm | H22: =E4/B36 -> 241.07143
A23: Nb cycle nécessaire | B23: =B19/B22 -> 930 | D23: Temps remplissage (s) | E23: =E22*B31 -> 672
A24: T1 (s) | B24: 10 | D24: temps en minutes | E24: =E23/60 -> 11.2
A25: T2 (s) | B25: 6 | D25: Distance (Km) | E25: 1
A26: T3 (s) | B26: 6 | D26: vitesse en (Km/h) | E26: 30
A27: T4 (s) | B27: 6 | D27: Temps de voyage (min) | E27: =E25/E26*60 -> 2
A28: Total 1 cycle (s) | B28: =SUM(B24:B27) -> 28 | D28: T1 (min) | E28: =E24 -> 11.2
A29: Efficience volume | B29: =60/80 -> 0.75 | D29: T2 (min) | E29: =E27 -> 2
A30: Efficience temps | B30: =80/60 -> 1.3333333 | D30: T3 (min) | E30: 2
A31: 1cycle efficient (s) | B31: =B28*B30 -> 37.333333 | D31: T4 (min) | E31: =E27 -> 2
A32: cycle / min | B32: =60/B31 -> 1.6071429 | D32: Total 1 cycle (min) | E32: =SUM(E28:E31) -> 17.2
A33: cycle / heure | B33: =B32*60 -> 96.428571 | D33: Nombre de camions saturation | E33: =E32/E28 -> 1.5357143
A34: Volume / heure (m3) | B34: =B33*B22 -> 96.428571 | D34: arrondi | E34: =ROUNDUP(E33,0) -> 2
A35: Volume / heure effecient (m3) | B35: =B34*B29 -> 72.321429 | D35: volume total des camions (m3) | E35: =E34*E20 -> 34.666667
A36: Temps (h) d'activité décimale | B36: =B19/B35 -> 12.859259 | D36: nombre de tour/camion | E36: =B19/E35 -> 26.826923
A37: Temps (h) d'activité sexagésimal | B37: =B36/24 -> 0.53580247 | D37: arrondi | E37: =ROUNDUP(E36,0) -> 27
D38: Temps des camions (min) | E38: =E37*E32*E34 -> 928.8
D39: Nombre de camion nécessaire | E39: =ROUNDUP(B19/E20,0) -> 54
D40: Temps des camions (H) | E40: =E38/60/24 -> 0.645
A41: FOURNITURE & SOUS-TRAITANCE | F41: Fournisseur
A42: désignation | B42: Qté | C42: Unité | D42: P.U. | E42: Total | F42: Qui? | G42: Distance chantier | H42: Nbre de tours/jour
A43: stockage sur place | B43: =B19*E19 -> 1395 | C43: t
...

Sheet 11.remblai d'apport
A1: Chantier | D1: Tâche
A2: BARBAZAN | D2: REMBLAIS D’EMPRUNT
A3: Tache immédiatement antécédante | E3: Quantité | F3: Unité | G3: Rendement | H3: durée
E4: 1500 | F4: m3 | G4: 17,45m3/h | H4: 85h56min25s
A5: Descriptif (source CCTP bordereau …)
A6: Ce prix rémunère le mètre cube en oeuvre de remblais d'emprunt ayant un coefficient de frottement interne phi au moins égal à 35 degrés. Il comprend, conformément au CCTP, la fourniture et le transport du matériau, le réglage en couches d'épaisseur conforme aux exigences du marché, l'arrosage et la scarification dans les conditions définies dans le marché, le compactage jusqu'à obtention des exigences prévues au C.C.T.P., le réglage de la plate-forme et des talus au profil définitif y compris l'évacuation des terres excédentaires, la protection de la plate-forme et des talus contre les eaux de ruissellement y compris l'exécution et l'entretien des ouvrages correspondants. Comprend les deux couches de GNT (0/20 et 0/80).
A7: Matériel | E7: Main d'œuvre
A8: désignation | B8: Qté | C8: affectation tâche | E8: désignation | F8: Quantité | G8: affectation tâche
A9: pelle | B9: 1 | C9: réglage | E9: chauffeur d'engin | F9: 2 | G9: conduit pellet et compacteur
A10: camion | B10: 6 | C10: apport matériau | E10: chauffeur camion | F10: 6 | G10: allez retour pour matériaux
A11: compacteur | B11: 1 | C11: compactage | E11: chef de chantier | F11: 1 | G11: conduit l'atelier
A13: Description du mode opératoire
A14: Un camion arrive sur chantier avec les matériaux, et déverse sur la zone indiqué. La pelle répartie et règle les matériaux. Le compacteur viens compacter le sol. une première couche de 0/80 est à mettre pincipalement sur les accotements (environ 0,40m) et une autre couche de 0/20 est à répartir entre la chaussée (0,10m), la chaussée en giratoire (0,10m), les trottoirs (0,80m) et les ilots (0,15m).
A18: Calcul de rendement, métré de fourniture, calcul de temps de transport, nombre de tours
A19: Donnée | B19: Quantité | C19: Donnée | D19: Quantité | E19: Donnée2 | F19: Quantité3 | G19: Donnée3 | H19: Quantité33
A20: Transport | C20: Mise en place granulat | E20: Compactage | F20: 0/80 | G20: Compactage | H20: 0/20
A21: Capacité (T) | B21: 26 | C21: Godet (L) | D21: 1000 | E21: mise en place des remblais | G21: mise en place des remblais
A22: Densité | B22: 1.8 | C22: Godet (m3) | D22: =D21/1000 -> 1 | E22: Hauteur (m) | F22: 0.4 | G22: Hauteur (m) | H22: =0.2 -> 0.2
A23: Capacité (m3) | B23: =B21/B22 -> 14.444444 | C23: largeur de bras (m) | D23: 1.5 | E23: TV 0/80 D3 epaisseur | F23: 0.3 | G23: GNT 0/20 D3 epaisseur | H23: 0.3
A24: Surface (m2) | B24: 4560.83 | C24: longueur de bras (m) | D24: 4.5 | E24: TV 0/80 D3 nb de passe | F24: 6 | G24: GNT 0/20 D3 nb de passe | H24: 6
A25: Volume (m3) | B25: =E4 -> 1500 | C25: Largeur de travail (m2) | D25: =D24*D23 -> 6.75 | E25: TV 0/80 D3 vitesse | F25: 2 | G25: GNT 0/20 D3 vitesse | H25: 2
A26: Distance (Km) | B26: =+G48 -> 9.6 | C26: 2 temps de réglage | E26: nombre de couche | F26: =ROUNDUP(F22/F23,0) -> 2 | G26: nombre de couche | H26: =ROUNDUP(H22/H23,0) -> 1
A27: vitesse en (Km/h) | B27: 60 | C27: T1 réglage grossier (s) | D27: 8 | E27: Compacteur | G27: Compacteur
A28: Temps de voyage (min) | B28: =B26/B27*60 -> 9.6 | C28: T1 réglage fin (s) | D28: 15 | E28: largeur moy | F28: 2 | G28: largeur moy | H28: 8
A29: T1 (min) (remplissage) | B29: 5 | C29: T2 retour (s) | D29: 4 | E29: longueur | F29: =118.37+128.13+92.7+110.37 -> 449.57 | G29: longueur | H29: =118.37+128.13+92.7+110.37 -> 449.57
A30: T2 (min) (allez) | B30: =B28 -> 9.6 | C30: Total grossier | D30: =D29+D27 -> 12 | E30: Largeur compacteur (m) | F30: 2.134 | G30: Largeur compacteur (m) | H30: 2.134
A31: T3 (min) (pose) | B31: 5 | C31: total fin | D31: =D29+D28 -> 19 | E31: Nombre de passage/largeur | F31: =ROUNDUP(1.5/F30,0) -> 1 | G31: Nombre de passage/largeur | H31: =ROUNDUP(H28/H30,0) -> 4
A32: T4 (min) (retour) | B32: =B28 -> 9.6 | C32: nb réglage grossier | D32: 3 | E32: compactage | G32: compactage
A33: Total 1 cycle (min) | B33: =SUM(B29:B32) -> 29.2 | C33: nb réglage fin | D33: 2 | E33: Q3 | G33: Q3
A34: Nombre de camions saturation | B34: =B33/B29 -> 5.84 | C34: nb total réglage | D34: =D33+D32 -> 5 | E34: Nombre de passage compacteur | F34: =F31*F24*F26 -> 12 | G34: Nombre de passage compacteur | H34: =H31*H24*H26 -> 24
A35: arrondi | B35: =ROUNDUP(B34,0) -> 6 | C35: temps total grossier | D35: =D30*D32 -> 36 | E35: nombre de metre linéaire | F35: =F34*F29 -> 5394.84 | G35: nombre de metre linéaire | H35: =H34*H29 -> 10789.68
A36: Nombre de camion nécessaire | B36: =ROUNDUP(B25/B23,0) -> 104 | C36: temps total fin | D36: =D31*D33 -> 38 | E36: temps de passage | F36: =F35/(F25*1000)/24 -> 0.1123925 | G36: temps de passage | H36: =H35/(H25*1000)/24 -> 0.224785
A37: volume total des camions (m3) | B37: =B35*B23 -> 86.666667 | C37: temps total (s) | D37: =D36+D35 -> 74 | E37: Facteur de difficulté | F37: 1.15 | G37: Facteur de difficulté | H37: 1.15
A38: nombre de tour/camion | B38: =B25/B37 -> 17.307692 | C38: efficience temps | D38: =8/6 -> 1.3333333 | E38: Temps de passage efficient | F38: =F36*F37 -> 0.12925138 | G38: Temps de passage efficient | H38: =H36*H37 -> 0.25850275
A39: arrondi | B39: =ROUNDUP(B38,0) -> 18 | C39: coefficient difficulté | D39: =1.3 -> 1.3
A40: Temps des camions (min) | B40: =B39*B33*B35 -> 3153.6 | C40: temps réglage eff (s/largeur de travail m2) | D40: =D38*D37 -> 98.666667 | E40: Volume 0/80 | F40: =F22*F29*F28 -> 359.656 | G40: volume 0/20 | H40: =H29*H28*H22 -> 719.312
A41: Temps des camions (H) | B41: =B40/60/24 -> 2.19 | C41: temps réglage coef | D41: =D40*D39 -> 128.26667 | E41: tonne | F41: =F40*B22 -> 647.3808 | G41: tonne | H41: =H40*B22 -> 1294.7616
C42: temps réglage total terrain (s) | D42: =B24/D25*D41 -> 86667.031 | G42: Temps total | H42: =F38+H38+D44+B41 -> 3.5808448
C43: (h) | D43: =D42/3600 -> 24.074175 | G43: nb jours | H43: =H42/8*24 -> 10.742534
D44: =D43/24 -> 1.0030906 | G44: rendement atelier | H44: =B25/(H42*24) -> 17.453982
...

Sheet 12.couche de reprofilage
A1: Chantier | D1: Tâche
A2: BARBAZAN | D2: COUCHE DE REPROFILAGE EN GRAVE BITUME CLASSE 2
A3: Tache immédiatement antécédante | E3: Quantité | F3: Unité | G3: Rendement | H3: durée
E4: 306.153 | F4: T | G4: 24T/H | H4: 12h
A5: Descriptif (source CCTP bordereau …)
A6: Ce prix rémunère à la tonne mesurée en place, l'exécution d'une couche de reprofilage en grave bitume de classe 2. Il comprend la fourniture, le chargement, le transport, le déchargement au lieu d'emploi, la mise en oeuvre, le réglage, le compactage et les essais d'atelier de compactage, définis au CCTP.
A7: Matériel | E7: Main d'œuvre
A8: désignation | B8: Qté | C8: affectation tâche | E8: désignation | F8: Quantité | G8: affectation tâche
A9: niveleuse | B9: 1 | E9: conducteur d'engin | F9: 5
A10: compacteur | B10: 1 | E10: chef de chantier | F10: 1
A11: camion | B11: 4
A12: Description du mode opératoire
A13: Un camion arrive et déverse la grave bitume sur la zone indiqué. La niveleuse met à niveau la GB. Le compacteur compacte de la façon attendu.
A16: Calcul de rendement, métré de fourniture, calcul de temps de transport, nombre de tours
A17: Donnée | B17: Quantité | D17: Donnée | E17: Quantité | G17: Donnée | H17: Quantité
A18: Transport | D18: Niveleuse | G18: Compactage
A19: Capacité (T) | B19: 26 | D19: Largeur de lame (m) | E19: 3.7 | G19: mise en place des remblais
A20: Densité | B20: 2.5 | D20: largeur de travail (m) | E20: =ROUND(E19*SIN(RADIANS(E21)),2) -> 2.62 | G20: Hauteur (m) | H20: =B22 -> 0.04
A21: Capacité (m3) | B21: =B19/B20 -> 10.4 | D21: Degré de rotation de lame (°) | E21: 45 | G21: D3 epaisseur | H21: 0.3
A22: ep | B22: 0.04 | D22: Vitesse de travail (m/h) | E22: =2*1000 -> 2000 | G22: D3 nb de passe | H22: 6
A23: Volume (m3) | B23: =B24/B20 -> 122.4612 | D23: Vitesse de recul (m/h) | E23: =30*1000 -> 30000 | G23: D3 vitesse | H23: 2
A24: Tonnage (T) | B24: =E4 -> 306.153 | D24: nb total bande | E24: =ROUNDUP(B44/E20,0) -> 3 | G24: nombre de couche | H24: =ROUNDUP(H20/H21,0) -> 1
A25: Distance (Km) | B25: =G48 -> 16.6 | D25: metre linéaire total | E25: =B45*E24 -> 1348.71 | G25: Compacteur
A26: vitesse en (Km/h) | B26: 60 | D26: Efficience | E26: =8/6 -> 1.3333333 | G26: Largeur compacteur (m) | H26: 2.134
A27: Temps de voyage (min) | B27: =B25/B26*60 -> 16.6 | D27: réglage grossier | E27: =3 -> 3 | G27: Nombre de passage/largeur | H27: =ROUNDUP(B44/H26,0) -> 4
A28: T1 (min) (remplissage) | B28: 5 | D28: réglagle fin | E28: 2 | G28: compactage
A29: T2 (min) (allez) | B29: =B27 -> 16.6 | D29: Mètre linéaire marche avant | E29: =(E27+E28)*E25 -> 6743.55 | G29: Q3
A30: T3 (min) (pose) | B30: 5 | D30: Mètre linéaire marche arrière | E30: =E29 -> 6743.55 | G30: Nombre de passage compacteur | H30: =H27*H22*H24 -> 24
A31: T4 (min) (retour) | B31: =B27 -> 16.6 | D31: temps de travail (h) | E31: =E29/E22 -> 3.371775 | G31: nombre de metre linéaire | H31: =H30*B45 -> 10789.68
A32: Total 1 cycle (min) | B32: =SUM(B28:B31) -> 43.2 | D32: temps de recul (h) | E32: =E30/E23 -> 0.224785 | G32: temps de passage | H32: =H31/(H23*1000)/24 -> 0.224785
A33: Nombre de camions saturation | B33: =B32/B28 -> 8.64 | D33: Temps de travail efficient (h) | E33: =((E31+E32)*E26) -> 4.7954133 | G33: Facteur de difficulté | H33: 1.15
A34: arrondi | B34: =ROUNDUP(B33,0) -> 9 | D34: coeffficient de difficulté | E34: 1.3 | G34: Temps de passage efficient | H34: =H32*H33 -> 0.25850275
A35: Nombre de camion nécessaire | B35: =ROUNDUP(B23/B21,0) -> 12 | D35: temps avec coef difficulté (h) | E35: =E33*E34 -> 6.2340373
A36: Nombre de camion choisi | B36: 4 | E36: =E35/24 -> 0.25975156 | G36: Temps total | H36: =H34+E36 -> 0.51825431
A37: volume total des camions (m3) | B37: =B34*B21 -> 93.6 | D37: rendement à l'heure (m²/h) | E37: =(B23/B22)/E35 -> 491.09908 | G37: nb jours | H37: =H36/8*24 -> 1.5547629
A38: nombre de tour/camion | B38: =B23/B37 -> 1.3083462 | D38: rendement à l'heure (s/m²) | E38: =E35/(B23/B22)*3600 -> 7.3304963 | G38: rendement atelier | H38: =E4/12.5 -> 24.49224
A39: arrondi | B39: =ROUNDUP(B38,0) -> 2
A40: choisi | B40: 3
A41: Temps des camions (min) | B41: =B40*B32*B36 -> 518.4
A42: Temps des camions (H) | B42: =B41/60/24 -> 0.36
...

Sheet 13.couche de fondation
A1: Chantier | D1: Tâche
A2: BARBAZAN | D2: COUCHE DE FONDATION EN GRAVE BITUME CLASSE 3 EP=12 CM
A3: Tache immédiatement antécédante | E3: Quantité | F3: Unité | G3: Rendement | H3: durée
E4: 1836.918 | F4: T | G4: 24T/H | H4: =H38 -> 3.1965086
A5: Descriptif (source CCTP bordereau …)
A6: Ce prix rémunère à la tonne mesurée en place, l'exécution d'une couche de fondation en grave bitume de classe 3. Il comprend la fourniture, le chargement, le transport, le déchargement au lieu d'emploi, la mise en oeuvre, le réglage, le compactage et les essais d'atelier de compactage, définis au CCTP.
A7: Matériel | E7: Main d'œuvre
A8: désignation | B8: Qté | C8: affectation tâche | E8: désignation | F8: Quantité | G8: affectation tâche
A9: niveleuse | B9: 1 | E9: conducteur d'engin | F9: 12
A10: compacteur | B10: 1 | E10: chef de chantier | F10: 1
A11: camion | B11: 9
A12: Description du mode opératoire
A13: Un camion arrive et déverse la grave bitume sur la zone indiqué. La niveleuse met à niveau la GB. Le compacteur compacte de la façon attendu.
A16: Calcul de rendement, métré de fourniture, calcul de temps de transport, nombre de tours
A17: Donnée | B17: Quantité | D17: Donnée | E17: Quantité | G17: Donnée | H17: Quantité
A18: Transport | D18: Niveleuse | G18: Compactage
A19: Capacité (T) | B19: 26 | D19: Largeur de lame (m) | E19: 3.7 | G19: mise en place des remblais
A20: Densité | B20: 2.5 | D20: largeur de travail (m) | E20: =ROUND(E19*SIN(RADIANS(E21)),2) -> 2.62 | G20: Hauteur (m) | H20: 0.12
A21: Capacité (m3) | B21: =B19/B20 -> 10.4 | D21: Degré de rotation de lame (°) | E21: 45 | G21: D3 epaisseur | H21: 0.3
A22: ep | B22: 0.24 | D22: Vitesse de travail (m/h) | E22: =2*1000 -> 2000 | G22: D3 nb de passe | H22: 6
A23: Volume (m3) | B23: =B24/B20 -> 734.7672 | D23: Vitesse de recul (m/h) | E23: =30*1000 -> 30000 | G23: D3 vitesse | H23: 2
A24: Tonnage (T) | B24: =E4 -> 1836.918 | D24: nb total bande | E24: =ROUNDUP(B44/E20,0) -> 3 | G24: nombre de couche | H24: =ROUNDUP(H20/H21,0) -> 1
A25: Distance (Km) | B25: =G48 -> 16.6 | D25: metre linéaire total | E25: =B45*E24 -> 1348.71 | G25: Compacteur
A26: vitesse en (Km/h) | B26: 60 | D26: Efficience | E26: =8/6 -> 1.3333333 | G26: Largeur compacteur (m) | H26: 2.134
A27: Temps de voyage (min) | B27: =B25/B26*60 -> 16.6 | D27: réglage grossier | E27: =3 -> 3 | G27: Nombre de passage/largeur | H27: =ROUNDUP(B44/H26,0) -> 4
A28: T1 (min) (remplissage) | B28: 5 | D28: réglagle fin | E28: 2 | G28: compactage
A29: T2 (min) (allez) | B29: =B27 -> 16.6 | D29: Mètre linéaire marche avant | E29: =(E27+E28)*E25 -> 6743.55 | G29: Q3
A30: T3 (min) (pose) | B30: 5 | D30: Mètre linéaire marche arrière | E30: =E29 -> 6743.55 | G30: Nombre de passage compacteur | H30: =H27*H22*H24 -> 24
A31: T4 (min) (retour) | B31: =B27 -> 16.6 | D31: temps de travail (h) | E31: =E29/E22 -> 3.371775 | G31: nombre de metre linéaire | H31: =H30*B45 -> 10789.68
A32: Total 1 cycle (min) | B32: =SUM(B28:B31) -> 43.2 | D32: temps de recul (h) | E32: =E30/E23 -> 0.224785 | G32: temps de passage | H32: =H31/(H23*1000)/24 -> 0.224785
A33: Nombre de camions saturation | B33: =B32/B28 -> 8.64 | D33: Temps de travail efficient (h) | E33: =((E31+E32)*E26) -> 4.7954133 | G33: Facteur de difficulté | H33: 1.15
A34: arrondi | B34: =ROUNDUP(B33,0) -> 9 | D34: coeffficient de difficulté | E34: 1.3 | G34: Temps de passage efficient | H34: =H32*H33 -> 0.25850275
A35: Nombre de camion nécessaire | B35: =ROUNDUP(B23/B21,0) -> 71 | D35: temps avec coef difficulté (h) | E35: =E33*E34 -> 6.2340373 | G35: temps pour les 2 couches | H35: =H34*2 -> 0.5170055
A36: Nombre de camion choisi | B36: 9 | E36: =E35/24 -> 0.25975156
A37: volume total des camions (m3) | B37: =B34*B21 -> 93.6 | D37: temps pour les deux couches | E37: =E35*2 -> 12.468075
A38: nombre de tour/camion | B38: =B23/B37 -> 7.8500769 | E38: =E36*2 -> 0.51950311 | G38: Temps total | H38: =H35+E38+B42 -> 3.1965086
A39: arrondi | B39: =ROUNDUP(B38,0) -> 8 | D39: rendement à l'heure (m²/h) | E39: =(B23/B22)/E37 -> 245.54954 | G39: nb jours | H39: =H38/8*24 -> 9.5895258
A40: choisi | B40: 8 | D40: rendement à l'heure (s/m²) | E40: =E37/(B23/B22)*3600 -> 14.660993 | G40: rendement atelier | H40: =E4/76.5 -> 24.012
A41: Temps des camions (min) | B41: =B40*B32*B36 -> 3110.4
A42: Temps des camions (H) | B42: =B41/60/24 -> 2.16
...

Sheet 14.couche de réglage
A1: Chantier | D1: Tâche
A2: BARBAZAN | D2: COUCHE DE REGLAGE GRAVES CONCASSEES 0/20 EP. 10 CM
A3: Tache immédiatement antécédante | E3: Quantité | F3: Unité | G3: Rendement | H3: durée
E4: 306.153 | F4: M3 | G4: 10,35m3/h | H4: =H38 -> 1.2382543
A5: Descriptif (source CCTP bordereau …)
A6: Ce prix rémunère au mètre cube mesuré en place, l'exécution d'une couche de réglage en graves concassées 0/20 de 0.10 m moyen. Il comprend la fourniture des matériaux, le chargement, le transport, la mise en oeuvre, le réglage, le compactage, les essais de l'atelier de compactage, la fourniture et le transport de l'eau d'arrosage et l'arrosage.
A7: Matériel | E7: Main d'œuvre
A8: désignation | B8: Qté | C8: affectation tâche | E8: désignation | F8: Quantité | G8: affectation tâche
A9: niveleuse | B9: 1 | E9: conducteur d'engin | F9: 7
A10: compacteur | B10: 1 | E10: chef de chantier | F10: 1
A11: camion | B11: 6
A12: Description du mode opératoire
A13: Un camion arrive et déverse la grave bitume sur la zone indiqué. La niveleuse met à niveau la GB. Le compacteur compacte de la façon attendu.
A16: Calcul de rendement, métré de fourniture, calcul de temps de transport, nombre de tours
A17: Donnée | B17: Quantité | D17: Donnée | E17: Quantité | G17: Donnée | H17: Quantité
A18: Transport | D18: Niveleuse | G18: Compactage | H18: 0/20
A19: Capacité (T) | B19: 26 | D19: Largeur de lame (m) | E19: 3.7 | G19: mise en place des remblais
A20: Densité | B20: 1.8 | D20: largeur de travail (m) | E20: =ROUND(E19*SIN(RADIANS(E21)),2) -> 2.62 | G20: Hauteur (m) | H20: 0.1
A21: Capacité (m3) | B21: =B19/B20 -> 14.444444 | D21: Degré de rotation de lame (°) | E21: 45 | G21: GNT 0/20 D3 epaisseur | H21: 0.3
A22: ep | B22: 0.1 | D22: Vitesse de travail (m/h) | E22: =2*1000 -> 2000 | G22: GNT 0/20 D3 nb de passe | H22: 6
A23: Volume (m3) | B23: =306.153 -> 306.153 | D23: Vitesse de recul (m/h) | E23: =30*1000 -> 30000 | G23: GNT 0/20 D3 vitesse | H23: 2
A24: Tonnage (T) | B24: =B23*1.8 -> 551.0754 | D24: nb total bande | E24: =ROUNDUP(B44/E20,0) -> 3 | G24: nombre de couche | H24: =ROUNDUP(H20/H21,0) -> 1
A25: Distance (Km) | B25: =G48 -> 16.6 | D25: metre linéaire total | E25: =B45*E24 -> 1348.71 | G25: Compacteur
A26: vitesse en (Km/h) | B26: 60 | D26: Efficience | E26: =8/6 -> 1.3333333 | G26: largeur moy | H26: 8
A27: Temps de voyage (min) | B27: =B25/B26*60 -> 16.6 | D27: réglage grossier | E27: =3 -> 3 | G27: longueur | H27: =118.37+128.13+92.7+110.37 -> 449.57
A28: T1 (min) (remplissage) | B28: 5 | D28: réglagle fin | E28: 2 | G28: Largeur compacteur (m) | H28: 2.134
A29: T2 (min) (allez) | B29: =B27 -> 16.6 | D29: Mètre linéaire marche avant | E29: =(E27+E28)*E25 -> 6743.55 | G29: Nombre de passage/largeur | H29: =ROUNDUP(H26/H28,0) -> 4
A30: T3 (min) (pose) | B30: 5 | D30: Mètre linéaire marche arrière | E30: =E29 -> 6743.55 | G30: compactage
A31: T4 (min) (retour) | B31: =B27 -> 16.6 | D31: temps de travail (h) | E31: =E29/E22 -> 3.371775 | G31: Q3
A32: Total 1 cycle (min) | B32: =SUM(B28:B31) -> 43.2 | D32: temps de recul (h) | E32: =E30/E23 -> 0.224785 | G32: Nombre de passage compacteur | H32: =H29*H22*H24 -> 24
A33: Nombre de camions saturation | B33: =B32/B28 -> 8.64 | D33: Temps de travail efficient (h) | E33: =((E31+E32)*E26) -> 4.7954133 | G33: nombre de metre linéaire | H33: =H32*H27 -> 10789.68
A34: arrondi | B34: =ROUNDUP(B33,0) -> 9 | D34: coeffficient de difficulté | E34: 1.3 | G34: temps de passage | H34: =H33/(H23*1000)/24 -> 0.224785
A35: Nombre de camion nécessaire | B35: =ROUNDUP(B23/B21,0) -> 22 | D35: temps avec coef difficulté (h) | E35: =E33*E34 -> 6.2340373 | G35: Facteur de difficulté | H35: 1.15
A36: Nombre de camion choisi | B36: 6 | E36: =E35/24 -> 0.25975156 | G36: Temps de passage efficient | H36: =H34*H35 -> 0.25850275
A37: volume total des camions (m3) | B37: =B34*B21 -> 130 | D37: rendement à l'heure (m²/h) | E37: =(B23/B22)/E35 -> 491.09908
A38: nombre de tour/camion | B38: =B23/B37 -> 2.3550231 | D38: rendement à l'heure (s/m²) | E38: =E35/(B23/B22)*3600 -> 7.3304963 | G38: Temps total | H38: =H36+E36+B42 -> 1.2382543
A39: arrondi | B39: =ROUNDUP(B38,0) -> 3 | G39: nb jours | H39: =H38/8*24 -> 3.7147629
A40: choisi | B40: 4 | G40: rendement atelier | H40: =E4/29.5 -> 10.378068
A41: Temps des camions (min) | B41: =B40*B32*B36 -> 1036.8
A42: Temps des camions (H) | B42: =B41/60/24 -> 0.72
...

Sheet 15.couche de roulement
A1: Chantier | D1: Tâche
A2: BARBAZAN | D2: COUCHE DE ROULEMENT EN BETON BITUMINEUX SEMI GRENU 0/14 DE CLASSE 3
A3: Tache immédiatement antécédante | E3: Quantité | F3: Unité | G3: Rendement | H3: durée
E4: 525.462 | F4: T | G4: 20,21T/h | H4: =H59 -> 1.0846435
A5: Descriptif (source CCTP bordereau …)
A6: Ce prix rémunère à la tonne mesurée en place, la réalisation d'une couche roulement en béton bitumineux semi grenu 0/14 de classe 3, dans les conditions fixées au C.C.T.P. Il comprend la fourniture, le transport, la mise en oeuvre, le réglage, le compactage, les essais d'atelier de compactage, ainsi que la réalisation si nécessaire du raccordement à la chaussée existante.
A7: Matériel | E7: Main d'œuvre
A8: désignation | B8: Qté | C8: affectation tâche | E8: désignation | F8: Quantité | G8: affectation tâche
A9: finisseur | B9: 1 | C9: place l'enrobé au sol | E9: conducteur finisseur | F9: 1 | G9: conduit finisseur
A10: bouille | B10: 1 | C10: dispose une couche d'accroche au sol | E10: conducteur épendeuse | F10: 1 | G10: conduit épendeuse
A11: compacteur tandem | B11: 1 | C11: compacte l'enrobé | E11: conducteur compacteur | F11: 1 | G11: conduit compacteur
A12: chargeuse | B12: 1 | C12: effectue des transferts d'enrobé | E12: conducteur chargeuse | F12: 1 | G12: conduit chargeuse
A13: camion d'enrobée | B13: 3 | C13: livre l'enrobé | E13: manœuvre | F13: 4 | G13: tire les bandes manuels le long des bords
A14: Description du mode opératoire
A15: Le camion arrive avec l'enrobé ont prépare une petite partit a la main afin de donné une base de départ au finisheur ensuite le camion se place a l'arriere du finnisheur et benne l'enrobé tout en suivant son avancé; le finisheur étale de manière régulière l'enrobé puis le compacteur passe plusieur fois afin de compacté et éffacé les traces.
A16: Calcul de rendement, métré de fourniture, calcul de temps de transport, nombre de tours
A17: Donnée | B17: Quantité | D17: Donnée | E17: Quantité | G17: Donnée | H17: Quantité
A18: Finisseur | D18: Finisseur | G18: Compactage
A19: largeur de table | B19: 5 | D19: Nombre de départ | E19: =B43+B45 -> 2.4 | G19: mise en place des remblais
A20: epaisseur enrobé | B20: 0.06 | D20: Temps par départ (s) | E20: 1 | G20: Hauteur (m) | H20: 0.06
A21: vitesse (m/min) avant | B21: 8 | D21: Total temps des départs (s) | E21: =(E20*E19)/3600/24 -> 2.7777778e-05 | G21: Enrobé bb 0/10 epaisseur | H21: 0.05
A22: vitesse (m/min) arriere | B22: 25 | D22: Nombre de marche arriere | E22: 0 | G22: Enrobé bb 0/10 nb de passe | H22: 4
A23: densité | B23: 2.5 | D23: distance marche arriere | E23: =E22*B44+B45*B27 -> 7 | G23: Enrobé bb 0/10 vitesse | H23: 4
A24: Semi contenance en T | B24: 25 | D24: temps total de recul | E24: =(E23/B22)/60/24 -> 0.00019444444 | G24: nombre de couche | H24: =ROUNDUP(H20/H21,0) -> 2
A25: vitesse du semi (km/h) | B25: 45 | G25: Compacteur
A26: Dimension du terrain | D26: Temps Total pour finisseur | E26: =E21+E24+B48 -> 0.34744444 | G26: Largeur compacteur (m) | H26: 2.134
A27: Largeur | B27: 7 | D27: Efficience | E27: =8/6 -> 1.3333333 | G27: Nombre de passage/largeur | H27: =ROUNDUP(B27/H26,0) -> 4
A28: Longueur | B28: 500 | D28: Temps Total pour finisseur efficient | E28: =E27*E26 -> 0.46325926 | G28: compactage
A29: Zone préparer à la main pour niveau | D29: Approvisionnement du finisseur | G29: Q3
A30: Longueur | B30: 5 | D30: distance chantier/central (km) | E30: 20 | G30: Nombre de passage compacteur | H30: =H27*H22*H24 -> 32
A31: Largeur | B31: 5 | D31: T1 - chargement central | E31: 20 | G31: nombre de metre linéaire | H31: =H30*B28 -> 16000
A32: largeur pour finisseur | B32: 5 | D32: T2 - aller sur chantier | E32: =E30*60/B25 -> 26.666667 | G32: temps de passage | H32: =H31/(H23*1000)/24 -> 0.16666667
A33: Enrobé | D33: T3 - déchargement | E33: =B24/B40 -> 4.1666667 | G33: Facteur de difficulté | H33: 1.15
A34: Volume total | B34: =B20*B28*B27 -> 210 | D34: T4 - retour à la central | E34: =E30*60/B25 -> 26.666667 | G34: Temps de passage efficient | H34: =H32*H33 -> 0.19166667
A35: Tonne | B35: 525.462 | D35: temps pour un cycle | E35: =SUM(E31:E34)/60/24 -> 0.053819444 | G35: Couche d'accroche émulsion | H35: 0.65
D36: Nombre de camion saturation | E36: =(E35/E33)*60*24 -> 18.6 | G36: couche liant (Kg/m2) | H36: 0.3
A37: Consommation des enrobés | D37: arrondi | E37: =ROUNDUP(E36,0) -> 19 | G37: en Kg | H37: =(H36*B27*B28) -> 1050
A38: m3 pour un ml | B38: =B19*B20*1 -> 0.3 | D38: volume total des camions (m3) | E38: =E37*B24 -> 475 | G38: en tonne | H38: =H37/1000 -> 1.05
A39: Tonnage/ml | B39: =B38*B23 -> 0.75 | D39: nombre de tour/camion | E39: =B34/E38 -> 0.44210526 | G39: couche gravillon (L/m2) | H39: 10
A40: tonnage par min | B40: =B39*B21 -> 6 | D40: Nombre de camion réel | E40: =B35/B24 -> 21.01848 | G40: en Litre | H40: =(H39*B27*B28) -> 35000
...

Sheet 16.reprise terre végé
A1: Chantier | D1: Tâche
A2: BARBAZAN | D2: REPRISE DE TERRE VEGETALE SUR DEPOT
A3: Tache immédiatement antécédante | E3: Quantité | F3: Unité | G3: Rendement | H3: durée
E4: 277.413 | F4: M3 | G4: 72,3m3/h | H4: =E17 -> 0.15982642
A5: Descriptif (source CCTP bordereau …)
A6: Ce prix rémunère au mètre cube, la reprise de terre végétale sur dépôt. Il comprend le chargement des matériaux depuis le lieu de dépôt, le transport, la mise en oeuvre, le réglage, le compactage, la fourniture, le transport de l'eau d'arrosage, et l'arrosage.
A7: Matériel | E7: Main d'œuvre
A8: désignation | B8: Qté | C8: affectation tâche | E8: désignation | F8: Quantité | G8: affectation tâche
A9: pelle | B9: 1 | E9: conducteur d'engin | F9: 1
E10: chef de chantier | F10: 1
A11: Description du mode opératoire
A12: la pelle transporte la terre végétale du dépôt sur place, aux endroits choisis.
A13: Calcul de rendement, métré de fourniture, calcul de temps de transport, nombre de tours
A14: Donnée | B14: Quantité | D14: Donnée | E14: Quantité
A15: Volume (m3) | B15: =E4 -> 277.413 | D15: Temps de travail
A16: Epaulement terre végétale | D16: Temps travaillé par jours (h) | E16: 8
A17: Godet (L) | B17: 1000 | D17: Total de temps de chantier h | E17: =B33 -> 0.15982642
A18: Godet (m3) | B18: =B17/1000 -> 1 | D18: temps jours | E18: =E17/E16 -> 0.019978302
A19: Nb cycle nécessaire | B19: =B15/B18 -> 277.413 | D19: rdm | E19: =E4/B32 -> 72.321429
A20: T1 (s) | B20: 10
A21: T2 (s) | B21: 6
A22: T3 (s) | B22: 6
A23: T4 (s) | B23: 6
A24: Total 1 cycle (s) | B24: =SUM(B20:B23) -> 28
A25: Efficience volume | B25: =60/80 -> 0.75
A26: Efficience temps | B26: =80/60 -> 1.3333333
A27: 1cycle efficient (s) | B27: =B24*B26 -> 37.333333
A28: cycle / min | B28: =60/B27 -> 1.6071429
A29: cycle / heure | B29: =B28*60 -> 96.428571
A30: Volume / heure (m3) | B30: =B29*B18 -> 96.428571
A31: Volume / heure effecient (m3) | B31: =B30*B25 -> 72.321429
A32: Temps d'activité décimale | B32: =B15/B31 -> 3.8358341
A33: Temps d'activité sexagésimal | B33: =B32/24 -> 0.15982642
A36: FOURNITURE & SOUS-TRAITANCE | F36: Fournisseur
A37: désignation | B37: Qté | C37: Unité | D37: P.U. | E37: Total | F37: Qui? | G37: Distance chantier | H37: Nbre de tours/jour
D39: =IF(A39="","",VLOOKUP(A39,$O$3:$P$12,2,FALSE)) | E39: =IF(A39="","",B39*D39)

Sheet 17.bordure d'ilot type 1
A1: Chantier | D1: Tâche
A2: BARBAZAN | D2: BORDURES D’ILOTS DE TYPE I1
A3: Tache immédiatement antécédante | E3: Quantité | F3: Unité | G3: Rendement | H3: durée
E4: 180.7 | F4: ML | G4: 14,75ml/h | H4: =H33 -> 0.50970556
A5: Descriptif (source CCTP bordereau …)
A6: Ce prix rémunère au mètre linéaire la fourniture et la pose de bordures d'îlots en béton de type I1. Il comprend la fourniture et la mise en place des bordures préfabriquées posées sur socle de 0,15 m d'épaisseur de béton B16/20 y compris le béton de calage à l'arrière de la bordure, les terrassements tous terrains, y compris chaussées, façon des joints et nivellement.
A7: Matériel | E7: Main d'œuvre
A8: désignation | B8: Qté | C8: affectation tâche | E8: désignation | F8: Quantité | G8: affectation tâche
A9: pelle | B9: 1 | C9: transport des palletes & bordures | E9: Maçon | F9: 1 | G9: mise en place des bordures, béton & joints
A10: Camion | B10: 1 | C10: transport des palletes & bordures | E10: manœuvre | F10: 2 | G10: mise en place des bordures, béton & joints
E11: chauffeur de pelle | F11: 1 | G11: conduit la pelle
A13: Description du mode opératoire
A14: Le camion apporte les fournitures sur site. La pelle positionne les palletes le longs de la zone choisi. La toupie coule le béton le long de la zone où les bordures doivent être placé. Les manoeuvres régle le béton à la hauteur voulu. Un homme positionne la pince à bordure pour soulever les bordures. La pelle positionne au plus proche la bordure. Les manoeuvres placent la bordure le long du cordeau, puis le maçon règle la bordure. Une fois que la bordure est positionné, les manoeuvres positionnent l'épaulement (devant et derrière la bordure). Dès que la pose de bordure est fini, le maçon commenceça la jointure.
A17: Calcul de rendement, métré de fourniture, calcul de temps de transport, nombre de tours
A18: Donnée | B18: Quantité | D18: Donnée | E18: Quantité | G18: Donnée | H18: Quantité
A19: Bordure Dimension | D19: mise en place béton | G19: confection mortier
A20: hauteur haute | B20: 0.13 | D20: vitesse de mise en place (s/ml) | E20: 3 | G20: Surface bordure (m²) | H20: =B20*B21 -> 0.0325
A21: largeur longue | B21: 0.25 | D21: temps en seconde | E21: =E20*B22 -> 542.1 | G21: epaisseur joint (m) | H21: 0.05
A22: Longueur à mettre (ml) | B22: =E4 -> 180.7 | D22: temps en minute | E22: =E21/3600/24 -> 0.0062743056 | G22: volume joint (m3) | H22: =H21*H20 -> 0.001625
A23: longueur d'une bordure | B23: 1 | D23: eclatage béton | G23: volume en litre / joint | H23: =H22*1000 -> 1.625
A24: Nombre de bordure | B24: =ROUNDUP(B22*B23,0) -> 181 | D24: vitesse mep à la pelle (s/ml) | E24: 3 | G24: temps (min) / 35L | H24: =15/60/24 -> 0.010416667
A25: Semelle Béton | D25: temps en seconde | E25: =E24*B22 -> 542.1 | G25: volume en litre total | H25: =H29*H23 -> 292.0125
A26: Largeur semelle béton | B26: =ROUNDUP(B21+B31+B34,1) -> 0.4 | D26: temps | E26: =E25/3600/24 -> 0.0062743056 | G26: temps (min) / 35L | H26: =H24*(ROUNDUP(H25/35,0)) -> 0.09375
A27: Hauteur semelle béton | B27: =0.15 -> 0.15 | D27: Règlage béton | G27: confection joint
A28: Surface semelle béton | B28: =B27*B26 -> 0.06 | D28: vitesse (s/ml) | E28: 3 | G28: temps par joint (s) | H28: 30
A29: Volume semelle béton | B29: =B28*B22 -> 10.842 | D29: temps en seconde | E29: =E28*B22 -> 542.1 | G29: nombre de joint | H29: =B22-1+H38 -> 179.7
A30: Epaulement Béton | D30: temps | E30: =E29/3600/24 -> 0.0062743056 | G30: temps | H30: =H28*H29/3600/24 -> 0.062395833
A31: Hauteur épaulement trottoire | B31: =(2/3)*B20 -> 0.086666667 | D31: Approvisionnement bordures | G31: Temps total | H31: =E22+E26+E30+E34+E41+E45+E54+H26+H30 -> 0.31856597
A32: Surface épaulement trottoire | B32: =(B31*B31)/2 -> 0.0037555556 | D32: 1 palette + pince (s) | E32: 30 | G32: Efficience | H32: =8/5 -> 1.6
A33: Volume épaulement trottoire | B33: =B32*B22 -> 0.67862889 | D33: trajet (s) | E33: 30 | G33: Temps total efficient | H33: =H31*H32 -> 0.50970556
A34: Hauteur épaulement chaussée | B34: =0.06*2/3 -> 0.04 | D34: temps total | E34: =(E32+E33)*B46/3600/24 -> 0.0076388889 | G34: Nombre de jours travaillé | H34: =H33/8 -> 0.063713194
A35: Surface épaulement chaussée | B35: =(B34*B34)/2 -> 0.0008 | D35: mise en place bordures | G35: rdm | H35: =E4/12.25 -> 14.75102
A36: Volume épaulement chaussée | B36: =B35*B22 -> 0.14456 | D36: Temps de bardage / 1 ml (s) | E36: 5
A37: Volume Totale béton pour 1 ml | B37: =B28+B32+B35 -> 0.064555556 | D37: temps | E37: =B45*E36/3600/24 -> 0.0010416667
A38: Convertion en Litre | B38: =B37*1000 -> 64.555556 | D38: temps mep cordo / 1ml (s) | E38: 5
A39: Volume total béton (m3) | B39: =B29+B33+B36 -> 11.665189 | D39: temps | E39: =E38*B45/3600/24 -> 0.0010416667
A40: Toupie Béton | D40: Temps mep bordure / 1ml | E40: =E39+E37 -> 0.0020833333
A41: Contenance d'une Toupie (m3) | B41: 5.5 | D41: Temps Total | E41: =E40*B46 -> 0.022916667
A42: Nombre de Toupie necessaire | B42: =B39/B41 -> 2.1209434 | D42: Reglage Bordure
A43: ml réalisable par Toupie | B43: =B41/B37 -> 85.197935 | D43: réglage d'une bordure (nb coups) | E43: 10
...

Sheet 18.bordure d'ilot type 2
A1: Chantier | D1: Tâche
A2: BARBAZAN | D2: BORDURES D’ILOTS DE TYPE I2
A3: Tache immédiatement antécédante | E3: Quantité | F3: Unité | G3: Rendement | H3: durée
E4: 70 | F4: ML | G4: 13ml/h | H4: =H33 -> 0.22111111
A5: Descriptif (source CCTP bordereau …)
A6: Ce prix rémunère au mètre linéaire la fourniture et la pose de bordures d'îlots en béton de type I2. Il comprend la fourniture et la mise en place des bordures préfabriquées posées sur socle de 0,15 m d'épaisseur dosé à 250 kgs/m3 y compris le béton de calage à l'arrière de la bordure, les terrassements tous terrains, y compris chaussées, façon des joints et nivellement.
A7: Matériel | E7: Main d'œuvre
A8: désignation | B8: Qté | C8: affectation tâche | E8: désignation | F8: Quantité | G8: affectation tâche
A9: pelle | B9: 1 | C9: transport des palletes & bordures | E9: Maçon | F9: 1 | G9: mise en place des bordures, béton & joints
A10: Camion | B10: 1 | C10: transport des palletes & bordures | E10: manœuvre | F10: 2 | G10: mise en place des bordures, béton & joints
E11: chauffeur de pelle | F11: 1 | G11: conduit la pelle
A13: Description du mode opératoire
A14: Le camion apporte les fournitures sur site. La pelle positionne les palletes le longs de la zone choisi. La toupie coule le béton le long de la zone où les bordures doivent être placé. Les manoeuvres régle le béton à la hauteur voulu. Un homme positionne la pince à bordure pour soulever les bordures. La pelle positionne au plus proche la bordure. Les manoeuvres placent la bordure le long du cordeau, puis le maçon règle la bordure. Une fois que la bordure est positionné, les manoeuvres positionnent l'épaulement (devant et derrière la bordure). Dès que la pose de bordure est fini, le maçon commenceça la jointure.
A17: Calcul de rendement, métré de fourniture, calcul de temps de transport, nombre de tours
A18: Donnée | B18: Quantité | D18: Donnée | E18: Quantité | G18: Donnée | H18: Quantité
A19: Bordure Dimension | D19: mise en place béton | G19: confection mortier
A20: hauteur haute | B20: 0.18 | D20: vitesse de mise en place (s/ml) | E20: 3 | G20: Surface bordure (m²) | H20: =B20*B21 -> 0.045
A21: largeur longue | B21: 0.25 | D21: temps en seconde | E21: =E20*B22 -> 210 | G21: epaisseur joint (m) | H21: 0.05
A22: Longueur à mettre (ml) | B22: =E4 -> 70 | D22: temps en minute | E22: =E21/3600/24 -> 0.0024305556 | G22: volume joint (m3) | H22: =H21*H20 -> 0.00225
A23: longueur d'une bordure | B23: 1 | D23: eclatage béton | G23: volume en litre / joint | H23: =H22*1000 -> 2.25
A24: Nombre de bordure | B24: =B22*B23 -> 70 | D24: vitesse mep à la pelle (s/ml) | E24: 3 | G24: temps (min) / 35L | H24: =15/60/24 -> 0.010416667
A25: Semelle Béton | D25: temps en seconde | E25: =E24*B22 -> 210 | G25: volume en litre total | H25: =H29*H23 -> 155.25
A26: Largeur semelle béton | B26: =ROUNDUP(B21+B31+B34,1) -> 0.5 | D26: temps | E26: =E25/3600/24 -> 0.0024305556 | G26: temps (min) / 35L | H26: =H24*(ROUNDUP(H25/35,0)) -> 0.052083333
A27: Hauteur semelle béton | B27: =0.15 -> 0.15 | D27: Règlage béton | G27: confection joint
A28: Surface semelle béton | B28: =B27*B26 -> 0.075 | D28: vitesse (s/ml) | E28: 3 | G28: temps par joint (s) | H28: 30
A29: Volume semelle béton | B29: =B28*B22 -> 5.25 | D29: temps en seconde | E29: =E28*B22 -> 210 | G29: nombre de joint | H29: =B22-1+H38 -> 69
A30: Epaulement Béton | D30: temps | E30: =E29/3600/24 -> 0.0024305556 | G30: temps | H30: =H28*H29/3600/24 -> 0.023958333
A31: Hauteur épaulement trottoire | B31: =(2/3)*B20 -> 0.12 | D31: Approvisionnement bordures | G31: Temps total | H31: =E22+E26+E30+E34+E41+E45+E54+H26+H30 -> 0.13819444
A32: Surface épaulement trottoire | B32: =(B31*B31)/2 -> 0.0072 | D32: 1 palette + pince (s) | E32: 30 | G32: Efficience | H32: =8/5 -> 1.6
A33: Volume épaulement trottoire | B33: =B32*B22 -> 0.504 | D33: trajet (s) | E33: 30 | G33: Temps total efficient | H33: =H31*H32 -> 0.22111111
A34: Hauteur épaulement chaussée | B34: =0.11*2/3 -> 0.073333333 | D34: temps total | E34: =(E32+E33)*B46/3600/24 -> 0.0027777778 | G34: Nombre de jours travaillé | H34: =H33/8 -> 0.027638889
A35: Surface épaulement chaussée | B35: =(B34*B34)/2 -> 0.0026888889 | D35: mise en place bordures | G35: rdm | H35: =E4/5.25 -> 13.333333
A36: Volume épaulement chaussée | B36: =B35*B22 -> 0.18822222 | D36: Temps de bardage / 1 ml (s) | E36: 5
A37: Volume Totale béton pour 1 ml | B37: =B28+B32+B35 -> 0.084888889 | D37: temps | E37: =B45*E36/3600/24 -> 0.0010416667
A38: Convertion en Litre | B38: =B37*1000 -> 84.888889 | D38: temps mep cordo / 1ml (s) | E38: 5
A39: Volume total béton (m3) | B39: =B29+B33+B36 -> 5.9422222 | D39: temps | E39: =E38*B45/3600/24 -> 0.0010416667
A40: Toupie Béton | D40: Temps mep bordure / 1ml | E40: =E39+E37 -> 0.0020833333
A41: Contenance d'une Toupie (m3) | B41: 5.5 | D41: Temps Total | E41: =E40*B46 -> 0.0083333333
A42: Nombre de Toupie necessaire | B42: =B39/B41 -> 1.080404 | D42: Reglage Bordure
A43: ml réalisable par Toupie | B43: =B41/B37 -> 64.790576 | D43: réglage d'une bordure (nb coups) | E43: 10
...

Sheet 20.trottoir
A1: Chantier | D1: Tâche
A2: BARBAZAN | D2: CONFECTION DE TROTTOIR EN GRAVE 0/20 + BI-COUCHE
A3: Tache immédiatement antécédante | E3: Quantité | F3: Unité | G3: Rendement | H3: durée
E4: 90.66 | F4: M2 | G4: 71,5m2/h | H4: =H21 -> 0.053083333
A5: Descriptif (source CCTP bordereau …)
A6: Ce prix rémunère au mètre carré la réalisation d'un trottoir, suivant les épaisseurs et prescriptions définies au CCTP . - grave 0/20 sur 20 cm d'épaisseur - revêtement bicouche Il comprend la fourniture, le transport, le stockage et la mise en oeuvre de l'émulsion de bitume et des gravillons, et le compactage, définis au CCTP.
A7: Matériel | E7: Main d'œuvre
A8: désignation | B8: Qté | C8: affectation tâche | E8: désignation | F8: Quantité | G8: affectation tâche
E9: Maçon | F9: 1 | G9: mise en place béton
E10: manœuvre | F10: 2 | G10: mise en place béton
E11: chef de chantier | F11: 1
A13: Description du mode opératoire
A14: une toupie vient déposer le béton, les hommes lissent le béton.
A17: Calcul de rendement, métré de fourniture, calcul de temps de transport, nombre de tours
A18: Donnée | B18: Quantité | D18: Donnée | E18: Quantité
A19: Dimension | B19: =E3 -> Quantité | D19: Lissage | G19: Temps total | H19: =B29+E26+E22 -> 0.033177083
A20: Surface | B20: =E4 -> 90.66 | D20: vitesse lissage (s/²) | E20: 15 | G20: Efficience | H20: =8/5 -> 1.6
A21: épaisseur | B21: =0.1 -> 0.1 | D21: temps en seconde | E21: =E20*B20 -> 1359.9 | G21: Temps total efficient | H21: =H19*H20 -> 0.053083333
A22: Volume | B22: =B20*B21 -> 9.066 | D22: temps en minute | E22: =E21/3600/24 -> 0.015739583 | G22: Nombre de jours travaillé | H22: =H21/8 -> 0.0066354167
A23: Toupie Béton | D23: coup de balaye | G23: rdm | H23: =E4/(1+16/60) -> 71.573684
A24: Contenance d'une Toupie (m3) | B24: 5.5 | D24: vitesse balaye (s/m²) | E24: 10
A25: Nombre de Toupie necessaire | B25: =B22/B24 -> 1.6483636 | D25: temps en seconde | E25: =E24*B20 -> 906.6
A26: arrondi | B26: =ROUNDUP(B25,0) -> 2 | D26: temps | E26: =E25/3600/24 -> 0.010493056
A27: Temps coulage par toupie (s) | B27: =60*5 -> 300
A28: temps total | B28: =B27*B26 -> 600
B29: =B28/24/3600 -> 0.0069444444
A33: FOURNITURE & SOUS-TRAITANCE | F33: Fournisseur
A34: désignation | B34: Qté | C34: Unité | D34: P.U. | E34: Total | F34: Qui? | G34: Distance chantier | H34: Nbre de tours/jour
A35: béton c25/30 | B35: =B22 -> 9.066 | C35: m3
A36: toupie | B36: =B26 -> 2 | C36: voyage | F36: Sablières de Saléchan - ABCVL La Gerle, Gouasquet, 65370 Saléchan | H36: 9.6

Sheet 19.CC1
A1: Chantier | D1: Tâche
A2: BARBAZAN | D2: BORDURES CANIVEAUX DE TYPE CC1
A3: Tache immédiatement antécédante | E3: Quantité | F3: Unité | G3: Rendement | H3: durée
E4: 8.36 | F4: ML | G4: 10ml/h | H4: =H33 -> 0.035308889
A5: Descriptif (source CCTP bordereau …)
A6: Ce prix rémunère au mètre linéaire, la fourniture et la pose de bordures caniveaux en béton de type CC1. Il comprend la fourniture et la mise en place des bordures préfabriquées posées sur socle de 0,15 m d'épaisseur de béton B16/20 y compris le béton de calage à l'arrière de la bordure, les terrassements tous terrains, y compris chaussées, le béton de pose sur fondation de 0,15 m en grave concassée 0/31.5, façon des joints et nivellement.
A7: Matériel | E7: Main d'œuvre
A8: désignation | B8: Qté | C8: affectation tâche | E8: désignation | F8: Quantité | G8: affectation tâche
A9: pelle | B9: 1 | C9: transport des palletes & bordures | E9: Maçon | F9: 1 | G9: mise en place des bordures, béton & joints
A10: Camion | B10: 1 | C10: transport des palletes & bordures | E10: manœuvre | F10: 2 | G10: mise en place des bordures, béton & joints
E11: chauffeur de pelle | F11: 1 | G11: conduit la pelle
A13: Description du mode opératoire
A14: Le camion apporte les fournitures sur site. La pelle positionne les palletes le longs de la zone choisi. La toupie coule le béton le long de la zone où les bordures doivent être placé. Les manoeuvres régle le béton à la hauteur voulu. Un homme positionne la pince à bordure pour soulever les bordures. La pelle positionne au plus proche la bordure. Les manoeuvres placent la bordure le long du cordeau, puis le maçon règle la bordure. Une fois que la bordure est positionné, les manoeuvres positionnent l'épaulement (devant et derrière la bordure). Dès que la pose de bordure est fini, le maçon commenceça la jointure.
A17: Calcul de rendement, métré de fourniture, calcul de temps de transport, nombre de tours
A18: Donnée | B18: Quantité | D18: Donnée | E18: Quantité | G18: Donnée | H18: Quantité
A19: Bordure Dimension | D19: mise en place béton | G19: confection mortier
A20: hauteur haute | B20: 0.12 | D20: vitesse de mise en place (s/ml) | E20: 3 | G20: Surface bordure (m²) | H20: =B20*B21 -> 0.018
A21: largeur longue | B21: 0.15 | D21: temps en seconde | E21: =E20*B22 -> 25.08 | G21: epaisseur joint (m) | H21: 0.05
A22: Longueur à mettre (ml) | B22: =E4 -> 8.36 | D22: temps en minute | E22: =E21/3600/24 -> 0.00029027778 | G22: volume joint (m3) | H22: =H21*H20 -> 0.0009
A23: longueur d'une bordure | B23: 1 | D23: eclatage béton | G23: volume en litre / joint | H23: =H22*1000 -> 0.9
A24: Nombre de bordure | B24: =ROUNDUP(B22*B23,0) -> 9 | D24: vitesse mep à la pelle (s/ml) | E24: 3 | G24: temps (min) / 35L | H24: =15/60/24 -> 0.010416667
A25: Semelle Béton | D25: temps en seconde | E25: =E24*B22 -> 25.08 | G25: volume en litre total | H25: =H29*H23 -> 6.624
A26: Largeur semelle béton | B26: =ROUNDUP(B21+B31+B34,1) -> 0.4 | D26: temps | E26: =E25/3600/24 -> 0.00029027778 | G26: temps (min) / 35L | H26: =H24*(ROUNDUP(H25/35,0)) -> 0.010416667
A27: Hauteur semelle béton | B27: =0.15 -> 0.15 | D27: Règlage béton | G27: confection joint
A28: Surface semelle béton | B28: =B27*B26 -> 0.06 | D28: vitesse (s/ml) | E28: 3 | G28: temps par joint (s) | H28: 30
A29: Volume semelle béton | B29: =B28*B22 -> 0.5016 | D29: temps en seconde | E29: =E28*B22 -> 25.08 | G29: nombre de joint | H29: =B22-1+H38 -> 7.36
A30: Epaulement Béton | D30: temps | E30: =E29/3600/24 -> 0.00029027778 | G30: temps | H30: =H28*H29/3600/24 -> 0.0025555556
A31: Hauteur épaulement trottoire | B31: =(2/3)*B20 -> 0.08 | D31: Approvisionnement bordures | G31: Temps total | H31: =E22+E26+E30+E34+E41+E45+E54+H26+H30 -> 0.022068056
A32: Surface épaulement trottoire | B32: =(B31*B31)/2 -> 0.0032 | D32: 1 palette + pince (s) | E32: 30 | G32: Efficience | H32: =8/5 -> 1.6
A33: Volume épaulement trottoire | B33: =B32*B22 -> 0.026752 | D33: trajet (s) | E33: 30 | G33: Temps total efficient | H33: =H31*H32 -> 0.035308889
A34: Hauteur épaulement chaussée | B34: =2/3*0.12 -> 0.08 | D34: temps total | E34: =(E32+E33)*B46/3600/24 -> 0.00069444444 | G34: Nombre de jours travaillé | H34: =H33/8 -> 0.0044136111
A35: Surface épaulement chaussée | B35: =(B34*B34)/2 -> 0.0032 | D35: mise en place bordures | G35: rdm | H35: =E4/H36 -> 10.032
A36: Volume épaulement chaussée | B36: =B35*B22 -> 0.026752 | D36: Temps de bardage / 1 ml (s) | E36: 5 | H36: =50/60 -> 0.83333333
