Workbook
Name OLE_LINK1: '1.2'!#REF!
Name OLE_LINK1_1: '1.6'!#REF!

Sheet Bilan
P1: Fichier publié le 19/08/2021
C4: QCM CONCEPTEUR "C" | F4: QCM ENCADRANT "E" | I4: QCM OPERATEUR "O" | L4: Nombre Questions | P4: Légendes :
C5: Nb | D5: Prio. | E5: Illust. | F5: Nb | G5: Prio. | H5: Illust. | I5: Nb | J5: Prio. | K5: Illust. | L5: Nb | M5: Prio. | N5: Illust. | P5: QCM illustré (1) | T5: I
B6: 1. Responsable de projet avant les chantiers | P6: QCM dit "prioritaire" | T6: P
B7: 1.1 DT | C7: ='1.1'!#REF! -> #REF! | D7: ='1.1'!#REF! -> #REF! | E7: ='1.1'!#REF! -> #REF! | F7: ='1.1'!C$4 -> 11 | G7: ='1.1'!C$6 -> 2 | H7: ='1.1'!C$5 -> 2 | I7: ='1.1'!#REF! -> #REF! | J7: ='1.1'!#REF! -> #REF! | K7: ='1.1'!#REF! -> #REF! | L7: ='1.1'!D$4 -> 12 | M7: ='1.1'!D$6 -> 2 | N7: ='1.1'!D$5 -> 2 | P7: QCM du "tronc commun Opérateur" | T7: TC OPERATEUR
B8: 1.2 Analyse des réponses - IC - Cartographie | C8: ='1.2'!#REF! -> #REF! | D8: ='1.2'!#REF! -> #REF! | E8: ='1.2'!#REF! -> #REF! | F8: ='1.2'!C$4 -> 9 | G8: ='1.2'!C$6 -> 0 | H8: ='1.2'!C$5 -> 2 | I8: ='1.2'!#REF! -> #REF! | J8: ='1.2'!#REF! -> #REF! | K8: ='1.2'!#REF! -> #REF! | L8: ='1.2'!D$4 -> 9 | M8: ='1.2'!D$6 -> 0 | N8: ='1.2'!D$5 -> 2 | P8: Référerences réglementaires du QCM | T8: R554-25
B9: 1.3 Clauses dans les marchés et DCE | C9: ='1.3'!#REF! -> #REF! | D9: ='1.3'!#REF! -> #REF! | E9: ='1.3'!#REF! -> #REF! | F9: ='1.3'!C$4 -> 2 | G9: ='1.3'!C$6 -> 0 | H9: ='1.3'!C$5 -> 0 | I9: ='1.3'!#REF! -> #REF! | J9: ='1.3'!#REF! -> #REF! | K9: ='1.3'!#REF! -> #REF! | L9: ='1.3'!D$4 -> 2 | M9: ='1.3'!D$6 -> 0 | N9: ='1.3'!D$5 -> 0
B10: 1.4 Marquage - Piquetage | C10: ='1.4'!#REF! -> #REF! | D10: ='1.4'!#REF! -> #REF! | E10: ='1.4'!#REF! -> #REF! | F10: ='1.4'!C$4 -> 7 | G10: ='1.4'!C$6 -> 1 | H10: ='1.4'!C$5 -> 3 | I10: ='1.4'!#REF! -> #REF! | J10: ='1.4'!#REF! -> #REF! | K10: ='1.4'!#REF! -> #REF! | L10: ='1.4'!D$4 -> 7 | M10: ='1.4'!D$6 -> 1 | N10: ='1.4'!D$5 -> 3 | P10: (1) Toutes les illustrations sont dans le fichier ZIP joint
B11: 1.5 Compétences des personnels | C11: ='1.5'!#REF! -> #REF! | D11: ='1.5'!#REF! -> #REF! | E11: ='1.5'!#REF! -> #REF! | F11: ='1.5'!C$4 -> 0 | G11: ='1.5'!C$6 -> 0 | H11: ='1.5'!C$5 -> 0 | I11: ='1.5'!#REF! -> #REF! | J11: ='1.5'!#REF! -> #REF! | K11: ='1.5'!#REF! -> #REF! | L11: ='1.5'!D$4 -> 0 | M11: ='1.5'!D$6 -> 0 | N11: ='1.5'!D$5 -> 0 | P11: Nota important : parmi les 250 QCM de ce fichier, 103 ont fait l'objet d'une modification ou ont été ajoutée. Elle sont publiées pour information sur le site du GU le 19/08/2021
B12: 1.6 Cartographie | C12: ='1.6'!#REF! -> #REF! | D12: ='1.6'!#REF! -> #REF! | E12: ='1.6'!#REF! -> #REF! | F12: ='1.6'!C$4 -> 8 | G12: ='1.6'!C$6 -> 1 | H12: ='1.6'!C$5 -> 1 | I12: ='1.6'!#REF! -> #REF! | J12: ='1.6'!#REF! -> #REF! | K12: ='1.6'!#REF! -> #REF! | L12: ='1.6'!D$4 -> 8 | M12: ='1.6'!D$6 -> 1 | N12: ='1.6'!D$5 -> 1 | P12: en application du V de l'article 3 Arrêté du 22 décembre 2015 relatif au contrôle des compétences des personnes intervenant dans les travaux à proximité des réseaux
B13: 2. Exécutants avant les chantiers | P13: et seront suceptibles de figurer à l'examen à complter du 19 novembre 2021
B14: 2.1 DICT | C14: ='2.1'!#REF! -> #REF! | D14: ='2.1'!#REF! -> #REF! | E14: ='2.1'!#REF! -> #REF! | F14: ='2.1'!C$4 -> 3 | G14: ='2.1'!C$6 -> 1 | H14: ='2.1'!C$5 -> 0 | I14: ='2.1'!#REF! -> #REF! | J14: ='2.1'!#REF! -> #REF! | K14: ='2.1'!#REF! -> #REF! | L14: ='2.1'!D$4 -> 3 | M14: ='2.1'!D$6 -> 1 | N14: ='2.1'!D$5 -> 0 | P14: 1-1_007 | Q14: 1-5_011 | R14: 2-4_014 | S14: 2-5_026 | T14: 3-2_017o | U14: 3-3_051
B15: 2.2 Analyse des réponses, du DCE et du marché | C15: ='2.2'!#REF! -> #REF! | D15: ='2.2'!#REF! -> #REF! | E15: ='2.2'!#REF! -> #REF! | F15: ='2.2'!C$4 -> 17 | G15: ='2.2'!C$6 -> 3 | H15: ='2.2'!C$5 -> 4 | I15: ='2.2'!#REF! -> #REF! | J15: ='2.2'!#REF! -> #REF! | K15: ='2.2'!#REF! -> #REF! | L15: ='2.2'!D$4 -> 17 | M15: ='2.2'!D$6 -> 3 | N15: ='2.2'!D$5 -> 4 | P15: 1-1_012 | Q15: 1-6_011 | R15: 2-4_019o | S15: 2-5_031 | T15: 3-2_028 | U15: 3-3_052
B16: 2.3 Compétences des personnels | C16: ='2.3'!#REF! -> #REF! | D16: ='2.3'!#REF! -> #REF! | E16: ='2.3'!#REF! -> #REF! | F16: ='2.3'!C$4 -> 16 | G16: ='2.3'!C$6 -> 4 | H16: ='2.3'!C$5 -> 14 | I16: ='2.3'!#REF! -> #REF! | J16: ='2.3'!#REF! -> #REF! | K16: ='2.3'!#REF! -> #REF! | L16: ='2.3'!D$4 -> 16 | M16: ='2.3'!D$6 -> 4 | N16: ='2.3'!D$5 -> 14 | P16: 1-1_013 | Q16: 1-6_016ce | R16: 2-4_019ce | S16: 2-5_032 | T16: 3-2_029 | U16: 3-3_053
B17: 2.4 Application du guide technique | C17: ='2.4'!#REF! -> #REF! | D17: ='2.4'!#REF! -> #REF! | E17: ='2.4'!#REF! -> #REF! | F17: ='2.4'!C$4 -> 28 | G17: ='2.4'!C$6 -> 4 | H17: ='2.4'!C$5 -> 16 | I17: ='2.4'!#REF! -> #REF! | J17: ='2.4'!#REF! -> #REF! | K17: ='2.4'!#REF! -> #REF! | L17: ='2.4'!D$4 -> 28 | M17: ='2.4'!D$6 -> 4 | N17: ='2.4'!D$5 -> 16 | P17: 1-1_015 | Q17: 1-6_018 | R17: 2-4_033 | S17: 2-5_033 | T17: 3-3_007
B18: 2.5 Lecture des indices et affleurants | C18: ='2.5'!#REF! -> #REF! | D18: ='2.5'!#REF! -> #REF! | E18: ='2.5'!#REF! -> #REF! | F18: ='2.5'!C$4 -> 25 | G18: ='2.5'!C$6 -> 1 | H18: ='2.5'!C$5 -> 23 | I18: ='2.5'!#REF! -> #REF! | J18: ='2.5'!#REF! -> #REF! | K18: ='2.5'!#REF! -> #REF! | L18: ='2.5'!D$4 -> 25 | M18: ='2.5'!D$6 -> 1 | N18: ='2.5'!D$5 -> 23 | P18: 1-1_016 | Q18: 2-1_005 | R18: 2-4_036 | S18: 3-1_010 | T18: 3-3_008
B19: 2.6 Travaux sans tranchée | C19: ='2.6'!C$4 -> 1 | D19: ='2.6'!C$6 -> 0 | E19: ='2.6'!C$5 -> 1 | F19: ='2.6'!D$4 -> 1 | G19: ='2.6'!D$6 -> 0 | H19: ='2.6'!D$5 -> 1 | I19: ='2.6'!E$4 -> 1 | J19: ='2.6'!E$6 -> 0 | K19: ='2.6'!E$5 -> 1 | L19: ='2.6'!F$4 -> 1 | M19: ='2.6'!F$6 -> 0 | N19: ='2.6'!F$5 -> 1 | P19: 1-1_031 | Q19: 2-2_007 | R19: 2-4_038 | S19: 3-1_011 | T19: 3-3_009
B20: 3. Au cours du chantier | P20: 1-1_032 | Q20: 2-2_008 | R20: 2-4_042 | S20: 3-1_011e | T20: 3-3_011
B21: 3.1 Constat d'arrêt ou de sursis | C21: ='3.1'!#REF! -> #REF! | D21: ='3.1'!#REF! -> #REF! | E21: ='3.1'!#REF! -> #REF! | F21: ='3.1'!C$4 -> 7 | G21: ='3.1'!C$6 -> 1 | H21: ='3.1'!C$5 -> 5 | I21: ='3.1'!#REF! -> #REF! | J21: ='3.1'!#REF! -> #REF! | K21: ='3.1'!#REF! -> #REF! | L21: ='3.1'!D$4 -> 7 | M21: ='3.1'!D$6 -> 1 | N21: ='3.1'!D$5 -> 5 | P21: 1-1_033 | Q21: 2-2_009 | R21: 2-4_043 | S21: 3-1_012 | T21: 3-3_015
B22: 3.2 Constat de dommage | C22: ='3.2'!#REF! -> #REF! | D22: ='3.2'!#REF! -> #REF! | E22: ='3.2'!#REF! -> #REF! | F22: ='3.2'!C$4 -> 14 | G22: ='3.2'!C$6 -> 3 | H22: ='3.2'!C$5 -> 9 | I22: ='3.2'!#REF! -> #REF! | J22: ='3.2'!#REF! -> #REF! | K22: ='3.2'!#REF! -> #REF! | L22: ='3.2'!D$4 -> 15 | M22: ='3.2'!D$6 -> 3 | N22: ='3.2'!D$5 -> 10 | P22: 1-2_003 | Q22: 2-2_014 | R22: 2-4_044 | S22: 3-1_013 | T22: 3-3_017
B23: 3.3 Opérations sur chantier | C23: ='3.3'!#REF! -> #REF! | D23: ='3.3'!#REF! -> #REF! | E23: ='3.3'!#REF! -> #REF! | F23: ='3.3'!C$4 -> 34 | G23: ='3.3'!C$6 -> 1 | H23: ='3.3'!C$5 -> 28 | I23: ='3.3'!#REF! -> #REF! | J23: ='3.3'!#REF! -> #REF! | K23: ='3.3'!#REF! -> #REF! | L23: ='3.3'!D$4 -> 34 | M23: ='3.3'!D$6 -> 1 | N23: ='3.3'!D$5 -> 28 | P23: 1-2_004 | Q23: 2-2_015 | R23: 2-4_045 | S23: 3-1_014o | T23: 3-3_033
B24: TOTAL | C24: =SUM(C7:C23) -> #REF! | D24: =SUM(D7:D23) -> #REF! | E24: =SUM(E7:E23) -> #REF! | F24: =SUM(F7:F23) -> 182 | G24: =SUM(G7:G23) -> 22 | H24: =SUM(H7:H23) -> 108 | I24: =SUM(I7:I23) -> #REF! | J24: =SUM(J7:J23) -> #REF! | ... N24: =SUM(N7:N23) -> 109 | P24: 1-2_006 | Q24: 2-3_018 | R24: 2-4_046 | S24: 3-1_014e | T24: 3-3_041
P25: 1-2_007 | Q25: 2-3_020 | R25: 2-4_047 | S25: 3-1_015 | T25: 3-3_042
P26: 1-2_009 | Q26: 2-3_016 | R26: 2-4_048 | S26: 3-1_016 | T26: 3-3_043
P27: 1-2_023 | Q27: 2-3_028 | R27: 2-5_005 | S27: 3-1_017 | T27: 3-3_044
P28: 1-3_011 | Q28: 2-3_029 | R28: 2-5_008 | S28: 3-1_018 | T28: 3-3_045
P29: 1-3_012 | Q29: 2-4_004 | R29: 2-5_009 | S29: 3-1_019 | T29: 3-3_046
P30: 1-4_004 | Q30: 2-4_007 | R30: 2-5_010 | S30: 3-1_020 | T30: 3-3_047
P31: 1-4_008 | Q31: 2-4_008 | R31: 2-5_011 | S31: 3-2_014e | T31: 3-3_048
P32: 1-5_001 | Q32: 2-4_011 | R32: 2-5_012 | S32: 3-2_014 | T32: 3-3_049
P33: 1-5_002 | Q33: 2-4_012 | R33: 2-5_013 | S33: 3-2_017e | T33: 3-3_050

Sheet 1.1
A1: =Bilan!B7 -> 1.1 DT
C3: E | D3: Total
B4: Nb quest. | C4: =COUNTIF(C8:C630,C3) -> 11 | D4: =COUNTA(B8:B630) -> 12
B5: Illust. | C5: =COUNTIF(C8:C630,"i")+COUNTIF(C8:C630,"p i") -> 2 | D5: =COUNTIF(A8:A630,"I") -> 2
B6: Prio | C6: =COUNTIF(C8:C630,"p")+COUNTIF(C8:C630,"p i") -> 2 | D6: =COUNTIF(A8:A630,"P") -> 2
B8: 1-1_001 | D8: Si je ne prévois pas de clause particulière dans le marché de travaux, je devrai renouveler la DT au bout de :
C9: =IF(C8="E",IF(A9="P",IF(A8="I","p i","p"),IF(A8="I","i"," ")),"") | D9: A | E9: 1 mois
A10: R554-33I | D10: B | E10: 3 mois
D11: C | E11: 6 mois
D12: D | E12: Je ne sais pas
B14: 1-1_002 | C14: E | D14: Qui doit établir la DT ?
A15: P | C15: =IF(C14="E",IF(A15="P",IF(A14="I","p i","p"),IF(A14="I","i"," ")),"") -> p | D15: A | E15: Le responsable de projet
A16: R554-21 | D16: B | E16: L’exécutant des travaux
D17: C | E17: L’exploitant de réseau
D18: D | E18: Je ne sais pas
B20: 1-1_003 | C20: E | D20: Qui doit envoyer la DT aux exploitants des réseaux concernés ?
C21: =IF(C20="E",IF(A21="P",IF(A20="I","p i","p"),IF(A20="I","i"," ")),"") | D21: A | E21: Le guichet unique
A22: R554-21 | D22: B | E22: Le responsable de projet
D23: C | E23: Le responsable de l'entreprise exécutant les travaux
D24: D | E24: Je ne sais pas
B26: 1-1_006 | C26: E | D26: Parmi les travaux suivants, quels sont ceux qui répondent à la définition de "Travaux Urgents" ?
C27: =IF(C26="E",IF(A27="P",IF(A26="I","p i","p"),IF(A26="I","i"," ")),"") | D27: A | E27: Les travaux de rétablissement d'un service public après une coupure accidentelle
A28: R554-32 | D28: B | E28: Les travaux de raccordement d’une nouvelle habitation
D29: C | E29: La pose de mobiliers urbains pour une manifestation
D30: D | E30: Je ne sais pas
B32: 1-1_007 | C32: E | D32: La procédure d'Avis de Travaux Urgents diffère notamment selon :
C33: =IF(C32="E",IF(A33="P",IF(A32="I","p i","p"),IF(A32="I","i"," ")),"") | D33: A | E33: Le délai d'intervention et le type de réseaux présents
A34: R554-32 | D34: B | E34: Le gestionnaire du lieu d'intervention
D35: C | E35: La personne qui l'envoie
D36: D | E36: Je ne sais pas
B39: 1-1_008 | C39: E | D39: Dans lequel des cas suivants le responsable de projet est dispensé de DT ?
C40: =IF(C39="E",IF(A40="P",IF(A39="I","p i","p"),IF(A39="I","i"," ")),"") | D40: A | E40: Le reprofilage de fossés
A41: R554-1 | D41: B | E41: Les travaux agricoles ou horticoles à moins de 40 cm de profondeur
D42: C | E42: Le décapage d'une chaussée à moins de 15 cm de profondeur
D43: D | E43: Je ne sais pas
A45: I | B45: 1-1_009 | C45: E | D45: La DT et la DICT sont obligatoires si les travaux s'approchent, en projection horizontale, d'une ligne aérienne à très haute tension et à conducteurs nus à moins de : | G45: x
C46: =IF(C45="E",IF(A46="P",IF(A45="I","p i","p"),IF(A45="I","i"," ")),"") -> i | D46: A | E46: 7 mètres
A47: R554-1 | D47: B | E47: 3 mètres
D48: C | E48: 5 mètres
D49: D | E49: Je ne sais pas
...

Sheet 1.2
A1: =Bilan!B8 -> 1.2 Analyse des réponses - IC - Cartographie
C3: E | D3: Total
B4: Nb quest. | C4: =COUNTIF(C8:C642,C3) -> 9 | D4: =COUNTA(B8:B642) -> 9
B5: Illust. | C5: =COUNTIF(C8:C642,"i")+COUNTIF(C8:C642,"p i") -> 2 | D5: =COUNTIF(A8:A642,"I") -> 2
B6: Prio | C6: =COUNTIF(C8:C642,"p")+COUNTIF(C8:C642,"p i") -> 0 | D6: =COUNTIF(A8:A642,"P") -> 0
B9: 1-2_009 | C9: E | D9: Un exploitant de réseau mentionne la classe de précision C dans les plans envoyés en réponse à une DT ou une DICT. Cela signifie que l'incertitude maximale de localisation pour le réseau principal est :
C10: =IF(C9="E",IF(A10="P",IF(A9="I","p i","p"),IF(A9="I","i"," ")),"") | D10: A | E10: Inférieure ou égale à 50 cm
A11: A15-2-12/art1-3° | D11: B | E11: Inférieure ou égale à 1,5 m
D12: C | E12: Supérieure à 1,5 m
D13: D | E13: Je ne sais pas
B15: 1-2_010 | C15: E | D15: Un exploitant de réseau mentionne la classe de précision B dans les plans envoyés en réponse à une DT ou une DICT. Cela signifie que l'incertitude maximale de localisation pour le réseau principal est :
C16: =IF(C15="E",IF(A16="P",IF(A15="I","p i","p"),IF(A15="I","i"," ")),"") | D16: A | E16: Inférieure ou égale à 50 cm
A17: A15-2-12/art1-3° | D17: B | E17: Inférieure ou égale à 1,5 m
D18: C | E18: Supérieure à 1,5 m
D19: D | E19: Je ne sais pas
B21: 1-2_011 | C21: E | D21: Un exploitant de réseau flexible mentionne la classe de précision A dans les plans envoyés en réponse à une DT ou une DICT. Cela signifie que l'incertitude maximale de localisation est :
C22: =IF(C21="E",IF(A22="P",IF(A21="I","p i","p"),IF(A21="I","i"," ")),"") | D22: A | E22: Inférieure ou égale à 40 cm
A23: A15-2-12/art1-3° | D23: B | E23: Inférieure ou égale à 50 cm
D24: C | E24: Inférieure ou égale à 1,5 m
D25: E | E25: Je ne sais pas
B27: 1-2_012 | C27: E | D27: Un exploitant de réseau rigide mentionne la classe de précision A dans les plans envoyés en réponse à une DT ou une DICT. Cela signifie que l'incertitude maximale de localisation est :
C28: =IF(C27="E",IF(A28="P",IF(A27="I","p i","p"),IF(A27="I","i"," ")),"") | D28: A | E28: Inférieure ou égale à 40 cm
A29: A15-2-12/art1-3° | D29: B | E29: Inférieure ou égale à 50 cm
D30: C | E30: Inférieure ou égale à 1,5 m
D31: E | E31: Je ne sais pas
B33: 1-2_013 | C33: E | D33: En réponse à une DT ou une DICT, lorsqu'un exploitant de réseau fournit les données de localisation de son réseau lors d'une réunion sur site sans préciser la classe de précision de ces données, la classe de précision à retenir est :
C34: =IF(C33="E",IF(A34="P",IF(A33="I","p i","p"),IF(A33="I","i"," ")),"") | D34: A | E34: Toujours la classe A
A35: A15-2-12/art5 | D35: B | E35: La classe A si le réseau est sensible, la classe B ou C si le réseau n'est pas sensible
D36: C | E36: La classe de précision doit toujours être précisée par l'exploitant
D37: D | E37: Je ne sais pas
A39: I | B39: 1-2_014 | C39: E | D39: Parmi les réseaux suivants, un seul est classé non sensible pour la sécurité par la règlementation. Lequel ?
C40: =IF(C39="E",IF(A40="P",IF(A39="I","p i","p"),IF(A39="I","i"," ")),"") -> i | D40: A | E40: Un réseau de chaleur
A41: R554-2 | D41: B | E41: Un réseau de tramway
D42: C | E42: Un réseau d'assainissement
D43: D | E43: Je ne sais pas
A45: I | B45: 1-2_015 | C45: E | D45: Parmi les réseaux suivants, un seul est classé sensible pour la sécurité par la règlementation. Lequel ?
C46: =IF(C45="E",IF(A46="P",IF(A45="I","p i","p"),IF(A45="I","i"," ")),"") -> i | D46: A | E46: Un réseau de télécommunication
A47: R554-2 | D47: B | E47: Un réseau électrique
D48: C | E48: Un réseau d'eau potable
D49: D | E49: Je ne sais pas
...

Sheet 1.3
A1: =Bilan!B9 -> 1.3 Clauses dans les marchés et DCE
C3: E | D3: Total
B4: Nb quest. | C4: =COUNTIF(C8:C608,C3) -> 2 | D4: =COUNTA(B8:B608) -> 2
B5: Illust. | C5: =COUNTIF(C8:C608,"i")+COUNTIF(C8:C608,"p i") -> 0 | D5: =COUNTIF(A8:A608,"I") -> 0
B6: Prio | C6: =COUNTIF(C8:C608,"p")+COUNTIF(C8:C608,"p i") -> 0 | D6: =COUNTIF(A8:A608,"P") -> 0
B8: 1-3_001 | C8: E | D8: Si le marché de travaux ne prévoit pas de clauses spécifiques, la DT :
A9: R554-22V | D9: A | E9: Reste valide sans limite de temps
D10: B | E10: Est seulement valide 3 mois
D11: C | E11: Est seulement valide 6 mois
D12: D | E12: Je ne sais pas
B14: 1-3_003 | C14: E | D14: Dans le cas où un exploitant de réseau sensible ne répond pas dans le délai réglementaire à la DICT et à sa relance, l'exécutant :
C15: =IF(C14="E",IF(A15="P",IF(A14="I","p i","p"),IF(A14="I","i"," ")),"") | D15: A | E15: Ne démarre pas les travaux et ne subit pas de préjudice lié au report
A16: R554-26VI | D16: B | E16: Démarre les travaux après un délai complémentaire de 9 jours
D17: C | E17: Démarre les travaux en prenant les précautions particulières prévues par le guide technique
D18: D | E18: Je ne sais pas
C55: =IF(C54="E",IF(A55="P",IF(A54="I","p i","p"),IF(A54="I","i"," ")),"")
C62: =IF(C61="E",IF(A62="P",IF(A61="I","p i","p"),IF(A61="I","i"," ")),"")
C69: =IF(C68="E",IF(A69="P",IF(A68="I","p i","p"),IF(A68="I","i"," ")),"")
C76: =IF(C75="E",IF(A76="P",IF(A75="I","p i","p"),IF(A75="I","i"," ")),"")
C83: =IF(C82="E",IF(A83="P",IF(A82="I","p i","p"),IF(A82="I","i"," ")),"")
C90: =IF(C89="E",IF(A90="P",IF(A89="I","p i","p"),IF(A89="I","i"," ")),"")
C97: =IF(C96="E",IF(A97="P",IF(A96="I","p i","p"),IF(A96="I","i"," ")),"")
C104: =IF(C103="E",IF(A104="P",IF(A103="I","p i","p"),IF(A103="I","i"," ")),"")
C111: =IF(C110="E",IF(A111="P",IF(A110="I","p i","p"),IF(A110="I","i"," ")),"")
C118: =IF(C117="E",IF(A118="P",IF(A117="I","p i","p"),IF(A117="I","i"," ")),"")
C125: =IF(C124="E",IF(A125="P",IF(A124="I","p i","p"),IF(A124="I","i"," ")),"")
C132: =IF(C131="E",IF(A132="P",IF(A131="I","p i","p"),IF(A131="I","i"," ")),"")
C139: =IF(C138="E",IF(A139="P",IF(A138="I","p i","p"),IF(A138="I","i"," ")),"")
C140: =IF(C139="E",IF(A140="Prioritaire",IF(A139="I","p i","p"),IF(A139="I","i"," ")),"")
C146: =IF(C145="E",IF(A146="P",IF(A145="I","p i","p"),IF(A145="I","i"," ")),"")
C153: =IF(C152="E",IF(A153="P",IF(A152="I","p i","p"),IF(A152="I","i"," ")),"")
C160: =IF(C159="E",IF(A160="P",IF(A159="I","p i","p"),IF(A159="I","i"," ")),"")
C167: =IF(C166="E",IF(A167="P",IF(A166="I","p i","p"),IF(A166="I","i"," ")),"")
C174: =IF(C173="E",IF(A174="P",IF(A173="I","p i","p"),IF(A173="I","i"," ")),"")
C181: =IF(C180="E",IF(A181="P",IF(A180="I","p i","p"),IF(A180="I","i"," ")),"")
C188: =IF(C187="E",IF(A188="P",IF(A187="I","p i","p"),IF(A187="I","i"," ")),"")
C195: =IF(C194="E",IF(A195="P",IF(A194="I","p i","p"),IF(A194="I","i"," ")),"")
C202: =IF(C201="E",IF(A202="P",IF(A201="I","p i","p"),IF(A201="I","i"," ")),"")
C209: =IF(C208="E",IF(A209="P",IF(A208="I","p i","p"),IF(A208="I","i"," ")),"")
C216: =IF(C215="E",IF(A216="P",IF(A215="I","p i","p"),IF(A215="I","i"," ")),"")
...

Sheet 1.4
A1: =Bilan!B10 -> 1.4 Marquage - Piquetage
C3: E | D3: Total
B4: Nb quest. | C4: =COUNTIF(C8:C640,C3) -> 7 | D4: =COUNTA(B8:B640) -> 7
B5: Illust. | C5: =COUNTIF(C8:C640,"i")+COUNTIF(C8:C640,"p i") -> 3 | D5: =COUNTIF(A8:A640,"I") -> 3
B6: Prio | C6: =COUNTIF(C8:C640,"p")+COUNTIF(C8:C640,"p i") -> 1 | D6: =COUNTIF(A8:A640,"P") -> 1
B8: 1-4_001 | C8: E | D8: Lorsque l’exploitant de réseau ne fournit pas de plan en réponse à la DICT, qui a la responsabilité du marquage-piquetage dans le cadre d'une réunion sur site ?
C9: =IF(C8="E",IF(A9="P",IF(A8="I","p i","p"),IF(A8="I","i"," ")),"") | D9: A | E9: L’entreprise de travaux
A10: R554-27III | D10: B | E10: Le responsable du projet (ou maître d'ouvrage)
D11: C | E11: L’exploitant du réseau
D12: D | E12: Je ne sais pas
B14: 1-4_002 | C14: E | D14: Lorsque l’exploitant a joint un plan au récépissé de DICT, qui a la responsabilité d'effectuer le marquage-piquetage ? | O14: Prioritaire
A15: P | C15: =IF(C14="E",IF(A15="P",IF(A14="I","p i","p"),IF(A14="I","i"," ")),"") -> p | D15: A | E15: L’entreprise de travaux
A16: R554-27I | D16: B | E16: Le responsable du projet (ou maître d'ouvrage)
D17: C | E17: L’exploitant
D18: E | E18: Je ne sais pas
B20: 1-4_004 | C20: E | D20: Pourquoi le compte rendu de marquage-piquetage doit être transmis à l’exécutant des travaux ?
D21: A | E21: Pour assurer la traçabilité des informations de localisation des réseaux existants
A22: R554-27 | D22: B | E22: Pour permettre à l'exécutant de produire un plan projet du réseau neuf à poser
D23: C | E23: Pour transférer à l'exécutant toute la responsabilité des travaux réalisés
D24: D | E24: Je ne sais pas
B27: 1-4_005 | C27: E | D27: Le marquage piquetage doit être effectué pour tout réseau situé dans l'emprise des travaux augmentée de :
C28: =IF(C27="E",IF(A28="P",IF(A27="I","p i","p"),IF(A27="I","i"," ")),"") | D28: A | E28: 1,5 mètres
A29: R554-27I | D29: B | E29: 2 mètres
D30: C | E30: 3 mètres
D31: D | E31: Je ne sais pas
A33: I | B33: 1-4_006 | C33: E | D33: Qui doit maintenir en état le marquage piquetage pendant toute la durée des travaux ?
C34: =IF(C33="E",IF(A34="P",IF(A33="I","p i","p"),IF(A33="I","i"," ")),"") -> i | D34: A | E34: Le service technique de la commune
A35: R554-27IV | D35: B | E35: L’exploitant du réseau
D36: C | E36: L'exécutant des travaux
D37: D | E37: Je ne sais pas
A39: I | B39: 1-4_007 | C39: E | D39: Sur un chantier, un marquage au sol de couleur jaune signale un réseau :
C40: =IF(C39="E",IF(A40="P",IF(A39="I","p i","p"),IF(A39="I","i"," ")),"") -> i | D40: A | E40: D'eaux usées
A41: NF S 70-003-1 | D41: B | E41: De gaz
A42: annexe E | D42: C | E42: De télécommunication
D43: D | E43: Je ne sais pas
A45: I | B45: 1-4_008 | C45: E | D45: Quelle mesure permet de prévenir un risque d'endommagement d'une canalisation électrique enterrée ?
C46: =IF(C45="E",IF(A46="P",IF(A45="I","p i","p"),IF(A45="I","i"," ")),"") -> i | D46: A | E46: La mise hors tension de la canalisation électrique
A47: NF C 18-510 | D47: B | E47: La consignation de la canalisation électrique
D48: C | E48: La localisation précise de la canalisation et son marquage au sol
D49: D | E49: Je ne sais pas
...

Sheet 1.5
A1: =Bilan!B11 -> 1.5 Compétences des personnels
C3: E | D3: Total
B4: Nb quest. | C4: =COUNTIF(C14:C612,C3) -> 0 | D4: =COUNTA(B14:B612) -> 0
B5: Illust. | C5: =COUNTIF(C14:C612,"i")+COUNTIF(C14:C612,"p i") -> 0 | D5: =COUNTIF(A14:A612,"I") -> 0
B6: Prio | C6: =COUNTIF(C14:C612,"p")+COUNTIF(C14:C612,"p i") -> 0 | D6: =COUNTIF(A14:A612,"P") -> 0
B8: 1-5_001 | C8: E | D8: Lequel de ces éléments ne permet pas la délivrance de l'Autorisation d'Intervention à Proximité des Réseaux ?
D9: A | E9: Un diplôme obtenu depuis plus de 5 ans
A10: A15-2-12/art21I-3° | D10: B | E10: Une attestation de compétences en cours de validité
D11: C | E11: Un CACES en cours de validité prenant en compte la réforme anti-endommagement
D12: D | E12: Je ne sais pas
C24: =IF(C23="E",IF(A24="P",IF(A23="I","p i","p"),IF(A23="I","i"," ")),"")
C31: =IF(C30="E",IF(A31="P",IF(A30="I","p i","p"),IF(A30="I","i"," ")),"")
C38: =IF(C37="E",IF(A38="P",IF(A37="I","p i","p"),IF(A37="I","i"," ")),"")
C45: =IF(C44="E",IF(A45="P",IF(A44="I","p i","p"),IF(A44="I","i"," ")),"")
C52: =IF(C51="E",IF(A52="P",IF(A51="I","p i","p"),IF(A51="I","i"," ")),"")
C59: =IF(C58="E",IF(A59="P",IF(A58="I","p i","p"),IF(A58="I","i"," ")),"")
C66: =IF(C65="E",IF(A66="P",IF(A65="I","p i","p"),IF(A65="I","i"," ")),"")
C73: =IF(C72="E",IF(A73="P",IF(A72="I","p i","p"),IF(A72="I","i"," ")),"")
C80: =IF(C79="E",IF(A80="P",IF(A79="I","p i","p"),IF(A79="I","i"," ")),"")
C87: =IF(C86="E",IF(A87="P",IF(A86="I","p i","p"),IF(A86="I","i"," ")),"")
C94: =IF(C93="E",IF(A94="P",IF(A93="I","p i","p"),IF(A93="I","i"," ")),"")
C101: =IF(C100="E",IF(A101="P",IF(A100="I","p i","p"),IF(A100="I","i"," ")),"")
... C143: =IF(C142="E",IF(A143="P",IF(A142="I","p i","p"),IF(A142="I","i"," ")),"")
C144: =IF(C143="E",IF(A144="Prioritaire",IF(A143="I","p i","p"),IF(A143="I","i"," ")),"")
C150: =IF(C149="E",IF(A150="P",IF(A149="I","p i","p"),IF(A149="I","i"," ")),"")
C157: =IF(C156="E",IF(A157="P",IF(A156="I","p i","p"),IF(A156="I","i"," ")),"")
C164: =IF(C163="E",IF(A164="P",IF(A163="I","p i","p"),IF(A163="I","i"," ")),"")
C171: =IF(C170="E",IF(A171="P",IF(A170="I","p i","p"),IF(A170="I","i"," ")),"")
C178: =IF(C177="E",IF(A178="P",IF(A177="I","p i","p"),IF(A177="I","i"," ")),"")
C185: =IF(C184="E",IF(A185="P",IF(A184="I","p i","p"),IF(A184="I","i"," ")),"")
C192: =IF(C191="E",IF(A192="P",IF(A191="I","p i","p"),IF(A191="I","i"," ")),"")
C199: =IF(C198="E",IF(A199="P",IF(A198="I","p i","p"),IF(A198="I","i"," ")),"")
C206: =IF(C205="E",IF(A206="P",IF(A205="I","p i","p"),IF(A205="I","i"," ")),"")
C213: =IF(C212="E",IF(A213="P",IF(A212="I","p i","p"),IF(A212="I","i"," ")),"")
C220: =IF(C219="E",IF(A220="P",IF(A219="I","p i","p"),IF(A219="I","i"," ")),"")
C227: =IF(C226="E",IF(A227="P",IF(A226="I","p i","p"),IF(A226="I","i"," ")),"")
... C409: =IF(C408="E",IF(A409="P",IF(A408="I","p i","p"),IF(A408="I","i"," ")),"")
C416: =IF(C415="E",IF(A416="Prioritaire",IF(A415="I","p i","p"),IF(A415="I","i"," ")),"")
C423: =IF(C422="E",IF(A423="Prioritaire",IF(A422="I","p i","p"),IF(A422="I","i"," ")),"")
C430: =IF(C429="E",IF(A430="Prioritaire",IF(A429="I","p i","p"),IF(A429="I","i"," ")),"")

Sheet 1.6
A1: =Bilan!B12 -> 1.6 Cartographie
C3: E | D3: Total
B4: Nb quest. | C4: =COUNTIF(C8:C539,C3) -> 8 | D4: =COUNTA(B8:B539) -> 8
B5: Illust. | C5: =COUNTIF(C8:C539,"i")+COUNTIF(C8:C539,"p i") -> 1 | D5: =COUNTIF(A8:A539,"I") -> 1
B6: Prio | C6: =COUNTIF(C8:C539,"p")+COUNTIF(C8:C539,"p i") -> 1 | D6: =COUNTIF(A8:A539,"P") -> 1
B8: 1-6_001 | C8: E | D8: En matière de cartographie, laquelle de ces affirmations est exacte ?
C9: =IF(C8="E",IF(A9="P",IF(A8="I","p i","p"),IF(A8="I","i"," ")),"") | D9: A | E9: La classe de précision figure dans le récépissé de l’exploitant à une DT ou DICT
A10: A15-2-12/art5 | D10: B | E10: Tous les branchements gaz sont reportés sur la cartographie
D11: C | E11: Les indications quant à la position des ouvrages enterrés figurant sur les plans sont précises à plus ou moins 40 cm
D12: D | E12: Je ne sais pas
B14: 1-6_003 | C14: E | D14: En topographie, le terme planimétrie se rapporte à la localisation d'un point :
C15: =IF(C14="E",IF(A15="P",IF(A14="I","p i","p"),IF(A14="I","i"," ")),"") | D15: A | E15: A l'horizontale
A16: NFS70-003-3 | D16: B | E16: A la verticale
D17: C | E17: Sur une droite
D18: D | E18: Je ne sais pas
B20: 1-6_004 | C20: E | D20: La génératrice supérieure d'un réseau enterré est :
C21: =IF(C20="E",IF(A21="P",IF(A20="I","p i","p"),IF(A20="I","i"," ")),"") | D21: A | E21: Le point le plus haut de la paroi extérieure de ce réseau ou de son fourreau
A22: A15-2-12/art15 | D22: B | E22: Le fil d'eau de ce réseau ou de son fourreau
D23: C | E23: L'axe central de ce réseau ou de son fourreau
D24: D | E24: Je ne sais pas
B27: 1-6_011 | C27: E | D27: L'échelle d'un plan est :
C28: =IF(C27="E",IF(A28="P",IF(A27="I","p i","p"),IF(A27="I","i"," ")),"") | D28: A | E28: Le rapport entre la longueur réelle d'un objet sur le terrain et la longueur de cet objet sur le plan
A29: NFS70-003-3 | D29: B | E29: La précision du plan
D30: C | E30: Le rapport entre la longueur d'un objet sur le plan et la longueur réelle de cet objet sur le terrain
D31: D | E31: Je ne sais pas
A33: I | B33: 1-6_016ce | C33: E | D33: Lorsque la profondeur d'un réseau est marquée au sol, elle indique la profondeur :
A34: P | C34: =IF(C33="E",IF(A34="P",IF(A33="I","p i","p"),IF(A33="I","i"," ")),"") -> p i | D34: A | E34: Du fil de l'eau du réseau ou de son fourreau
A35: NFS70-003-3 | D35: B | E35: De la génératrice supérieure du réseau ou de son fourreau
D36: C | E36: Du grillage avertisseur du réseau
D37: D | E37: Je ne sais pas
B39: 1-6_018 | C39: E | D39: Pour une échelle de plan au 1/200, 20 mètres sur le terrain correspondent sur le plan à :
D40: A | E40: 2 cm
A41: NFS70-003-3 | D41: B | E41: 10 cm
D42: C | E42: 20 cm
D43: D | E43: Je ne sais pas
B46: 1-6_027 | C46: E | D46: Pour une échelle de plan au 1/200, 1 cm sur le plan représente combien sur le terrain ?
C47: =IF(C46="E",IF(A47="P",IF(A46="I","p i","p"),IF(A46="I","i"," ")),"") | D47: A | E47: Deux mètres
A48: NFS70-003-3 | D48: B | E48: Vingt mètres
D49: C | E49: Deux cents mètres
D50: D | E50: Je ne sais pas
...

Sheet 2.1
A1: =Bilan!B14 -> 2.1 DICT
C3: E | D3: Total
B4: Nb quest. | C4: =COUNTIF(C8:C629,C3) -> 3 | D4: =COUNTA(B8:B629) -> 3
B5: Illust. | C5: =COUNTIF(C8:C629,"i")+COUNTIF(C8:C629,"p i") -> 0 | D5: =COUNTIF(A8:A629,"I") -> 0
B6: Prio | C6: =COUNTIF(C8:C629,"p")+COUNTIF(C8:C629,"p i") -> 1 | D6: =COUNTIF(A8:A629,"P") -> 1
B8: 2-1_004 | C8: E | D8: Qui doit établir la DICT ?
A9: P | C9: =IF(C8="E",IF(A9="P",IF(A8="I","p i","p"),IF(A8="I","i"," ")),"") -> p | D9: A | E9: Le maître d’ouvrage
A10: R554-25I | D10: B | E10: L’exécutant des travaux
D11: C | E11: L’exploitant de réseau
D12: D | E12: Je ne sais pas
B14: 2-1_005 | C14: E | D14: Qui doit envoyer la DICT aux exploitants d'ouvrages ?
D15: A | E15: L'exécutant des travaux ou son Prestataire d'Aide à la Déclaration
A16: R554-25I | D16: B | E16: Le téléservice du guichet unique
D17: C | E17: Le responsable de projet ou son Prestataire d'Aide à la Déclaration
D18: D | E18: Je ne sais pas
B20: 2-1_008 | C20: E | D20: Je dois réaliser des travaux à l'aplomb d'une ligne aérienne et je dois prendre en compte la hauteur des conducteurs. Que faire ?
C21: =IF(C20="E",IF(A21="P",IF(A20="I","p i","p"),IF(A20="I","i"," ")),"") | D21: A | E21: Je me réfère au récépissé de DICT et au guide technique
A22: R554-25 | D22: B | E22: Je vérifie visuellement que la hauteur de surplomb est suffisante
D23: C | E23: J'utilise une perche graduée isolante pour mesurer la hauteur de la ligne
D24: D | E24: Je ne sais pas
C83: =IF(C82="E",IF(A83="P",IF(A82="I","p i","p"),IF(A82="I","i"," ")),"")
C90: =IF(C89="E",IF(A90="P",IF(A89="I","p i","p"),IF(A89="I","i"," ")),"")
C97: =IF(C96="E",IF(A97="P",IF(A96="I","p i","p"),IF(A96="I","i"," ")),"")
C104: =IF(C103="E",IF(A104="P",IF(A103="I","p i","p"),IF(A103="I","i"," ")),"")
C111: =IF(C110="E",IF(A111="P",IF(A110="I","p i","p"),IF(A110="I","i"," ")),"")
C118: =IF(C117="E",IF(A118="P",IF(A117="I","p i","p"),IF(A117="I","i"," ")),"")
C125: =IF(C124="E",IF(A125="P",IF(A124="I","p i","p"),IF(A124="I","i"," ")),"")
C132: =IF(C131="E",IF(A132="P",IF(A131="I","p i","p"),IF(A131="I","i"," ")),"")
C139: =IF(C138="E",IF(A139="P",IF(A138="I","p i","p"),IF(A138="I","i"," ")),"")
C146: =IF(C145="E",IF(A146="P",IF(A145="I","p i","p"),IF(A145="I","i"," ")),"")
C153: =IF(C152="E",IF(A153="P",IF(A152="I","p i","p"),IF(A152="I","i"," ")),"")
C160: =IF(C159="E",IF(A160="P",IF(A159="I","p i","p"),IF(A159="I","i"," ")),"")
C161: =IF(C160="E",IF(A161="Prioritaire",IF(A160="I","p i","p"),IF(A160="I","i"," ")),"")
C167: =IF(C166="E",IF(A167="P",IF(A166="I","p i","p"),IF(A166="I","i"," ")),"")
C174: =IF(C173="E",IF(A174="P",IF(A173="I","p i","p"),IF(A173="I","i"," ")),"")
C181: =IF(C180="E",IF(A181="P",IF(A180="I","p i","p"),IF(A180="I","i"," ")),"")
C188: =IF(C187="E",IF(A188="P",IF(A187="I","p i","p"),IF(A187="I","i"," ")),"")
C195: =IF(C194="E",IF(A195="P",IF(A194="I","p i","p"),IF(A194="I","i"," ")),"")
C202: =IF(C201="E",IF(A202="P",IF(A201="I","p i","p"),IF(A201="I","i"," ")),"")
C209: =IF(C208="E",IF(A209="P",IF(A208="I","p i","p"),IF(A208="I","i"," ")),"")
...

Sheet 2.2
A1: =Bilan!B15 -> 2.2 Analyse des réponses, du DCE et du marché
C3: E | D3: Total
B4: Nb quest. | C4: =COUNTIF(C8:C702,C3) -> 17 | D4: =COUNTA(B8:B702) -> 17
B5: Illust. | C5: =COUNTIF(C8:C702,"i")+COUNTIF(C8:C702,"p i") -> 4 | D5: =COUNTIF(A8:A702,"I") -> 4
B6: Prio | C6: =COUNTIF(C8:C702,"p")+COUNTIF(C8:C702,"p i") -> 3 | D6: =COUNTIF(A8:A702,"P") -> 3
B8: 2-2_001 | C8: E | D8: Si un déclarant n'a pas reçu de réponse à sa DICT dans les délais, pour quel réseau parmi les suivants doit-il attendre avant de commencer les travaux ?
A9: P | C9: =IF(C8="E",IF(A9="P",IF(A8="I","p i","p"),IF(A8="I","i"," ")),"") -> p | D9: A | E9: Eclairage public
A10: R554-26VI | D10: B | E10: Télécommunication
D11: C | E11: Adduction d'eau
D12: D | E12: Je ne sais pas
B14: 2-2_002 | C14: E | D14: Après avoir relancé les exploitants n'ayant pas répondu dans le délai réglementaire à la DICT, je peux commencer les travaux 2 jours après cette relance même sans réponse d'un exploitant :
C15: =IF(C14="E",IF(A15="P",IF(A14="I","p i","p"),IF(A14="I","i"," ")),"") | D15: A | E15: D'un réseau de transport d'hydrocarbures
A16: R554-26VI | D16: B | E16: D'un réseau électrique
D17: C | E17: D'un réseau téléphonique
D18: D | E18: Je ne sais pas
B20: 2-2_004 | C20: E | D20: De combien de jours (sauf jours fériés) dispose l'exploitant pour répondre à une DICT dématérialisée ?
A21: P | C21: =IF(C20="E",IF(A21="P",IF(A20="I","p i","p"),IF(A20="I","i"," ")),"") -> p | D21: A | E21: 7 jours
A22: R554-26I | C22: =IF(C21="E",IF(A22="P",IF(A21="I","p i","p"),IF(A21="I","i"," ")),"") | D22: B | E22: 9 jours
D23: C | E23: 15 jours
D24: D | E24: Je ne sais pas
B26: 2-2_005 | C26: E | D26: De combien de jours (sauf jours fériés) dispose l'exploitant pour répondre à une DICT NON dématérialisée (courrier, fax...) ?
A27: P | C27: =IF(C26="E",IF(A27="P",IF(A26="I","p i","p"),IF(A26="I","i"," ")),"") -> p | D27: A | E27: 7 jours
A28: R554-26I | D28: B | E28: 9 jours
D29: C | E29: 15 jours
D30: D | E30: Je ne sais pas
B32: 2-2_006 | C32: E | D32: Suite à une relance pour non réponse à une DICT, l'exploitant doit répondre dans un délai de :
C33: =IF(C32="E",IF(A33="P",IF(A32="I","p i","p"),IF(A32="I","i"," ")),"") | D33: A | E33: 2 jours ouvrés
A34: R554-26VI | D34: B | E34: 7 jours ouvrés
D35: C | E35: 9 jours ouvrés
D36: D | E36: Je ne sais pas
B38: 2-2_007 | C38: E | D38: Suite à une DICT, dans quel cas les plans des réseaux peuvent ne pas être joints au récépissé fourni par l'exploitant ?
D39: A | E39: L'exploitant prévoit une réunion sur site
A40: R554-26I | D40: B | E40: Aucun réseau sensible pour la sécurité n'est présent dans l'emprise des travaux
D41: C | E41: Un seul réseau est présent dans l'emprise des travaux
D42: D | E42: Je ne sais pas
B44: 2-2_009 | C44: E | D44: Je reçois l'ordre de démarrage des travaux d'un marché pour lequel aucun réseau sensible pour la sécurité n'est présent dans l'emprise des travaux :
C45: =IF(C44="E",IF(A45="P",IF(A44="I","p i","p"),IF(A44="I","i"," ")),"") | D45: A | E45: Je demande au maître d'ouvrage de réaliser des investigations complémentaires pour vérifier l'exactitude des renseignements donnés par les plans et ne démarre pas les travaux tant que je n'ai pas de réponse
A46: R554-23III | D46: B | E46: Je démarre les travaux en appliquant les précautions prévues dans les clauses techniques et financières
D47: C | E47: Je démarre les travaux sans précaution particulière puisqu'il n'y a pas de réseau sensible pour la sécurité
D48: D | E48: Je ne sais pas
...

Sheet 2.3
A1: =Bilan!B16 -> 2.3 Compétences des personnels
C3: E | D3: Total
B4: Nb quest. | C4: =COUNTIF(C8:C620,C3) -> 16 | D4: =COUNTA(B8:B620) -> 16
B5: Illust. | C5: =COUNTIF(C8:C620,"i")+COUNTIF(C8:C620,"p i") -> 14 | D5: =COUNTIF(A8:A620,"I") -> 14
B6: Prio | C6: =COUNTIF(C8:C620,"p")+COUNTIF(C8:C620,"p i") -> 4 | D6: =COUNTIF(A8:A620,"P") -> 4
A8: I | B8: 2-3_003 | C8: E | D8: Que dois-je faire si je découvre un câble électrique dénudé ?
C9: =IF(C8="E",IF(A9="P",IF(A8="I","p i","p"),IF(A8="I","i"," ")),"") -> i | D9: A | E9: Je mets des lunettes de protection
A10: R554-31II | D10: B | E10: Je m'écarte tout de suite de la zone
D11: C | E11: Je dégage le câble en évitant de le toucher
D12: D | E12: Je ne sais pas
B14: 2-3_004 | C14: E | D14: Une entreprise exécutant des travaux non urgents doit délivrer une autorisation d'intervention à proximité des réseaux (AIPR) :
A15: P | C15: =IF(C14="E",IF(A15="P",IF(A14="I","p i","p"),IF(A14="I","i"," ")),"") -> p | D15: A | E15: Uniquement à l'encadrant des travaux
A16: A15-2-12/art21I | D16: B | E16: A l'encadrant des travaux et aux conducteurs d'engins intervenant sur le chantier
D17: C | E17: Uniquement aux conducteurs d'engins intervenant sur le chantier
D18: D | E18: Je ne sais pas
A20: I | B20: 2-3_011 | C20: E | D20: Quels sont les risques principaux liés à un réseau d'assainissement ?
C21: =IF(C20="E",IF(A21="P",IF(A20="I","p i","p"),IF(A20="I","i"," ")),"") -> i | D21: A | E21: Asphyxie et intoxication
A22: § 3.9 du GT | D22: B | E22: Electrisation et électrocution
D23: C | E23: Hydrocution
D24: D | E24: Je ne sais pas
A26: I | B26: 2-3_013e | C26: E | D26: Pendant toute la durée de travaux à proximité d'un réseau de gaz, il faut dans tous les cas :
A27: P | C27: =IF(C26="E",IF(A27="P",IF(A26="I","p i","p"),IF(A26="I","i"," ")),"") -> p i | D27: A | E27: Maintenir les accès aux vannes d’arrêt
A28: R554-31II | D28: B | E28: Interdire tout matériel électrique
D29: C | E29: Porter un masque respiratoire
D30: D | E30: Je ne sais pas
A32: I | B32: 2-3_015e | C32: E | D32: Un conducteur d'engin peut démarrer le terrassement dès qu'il a les informations sur :
A33: P | C33: =IF(C32="E",IF(A33="P",IF(A32="I","p i","p"),IF(A32="I","i"," ")),"") -> p i | D33: A | E33: L' ouvrage souterrain sur lequel il doit travailler
A34: R554-27 I | D34: B | E34: Les réseaux dangereux situés dans la zone de travail (gaz, électricité)
D35: C | E35: Tous les ouvrages souterrains signalés par le marquage-piquetage
D36: D | E36: Je ne sais pas
A38: I | B38: 2-3_016 | C38: E | D38: Lorsque le réseau annoncé et marqué n'a pas été trouvé dans l'emprise des travaux mentionnée dans la DICT, peut-on creuser en dehors de cette emprise ?
C39: =IF(C38="E",IF(A39="P",IF(A38="I","p i","p"),IF(A38="I","i"," ")),"") -> i | D39: A | E39: Oui, mais uniquement dans l'environnement immédiat de cette zone (moins de 3 mètres)
A40: R. 554-25 II | D40: B | E40: Oui, lorsqu'aucun élément ne signale de réseau (pas de coffret, de borne incendie…)
D41: C | E41: Non
D42: E | E42: Je ne sais pas
B44: 2-3_018 | C44: E | D44: Dans le cadre d'un avis de travaux urgents (ATU) et en présence d'un réseau de transport de matières dangereuses (TMD). Il faut :
D45: A | E45: Uniquement appeler l'exploitant du réseau de TMD avant le démarrage des travaux
A46: R554-32 / art3 A | D46: B | E46: Appeler l'exploitant du réseau de TMD avant le démarrage des travaux et lui envoyer l'ATU
D47: C | E47: Uniquement envoyer l'ATU à l'exploitant du réseau deTMD si les travaux démarrent plus de 24h après cet envoi.
D48: D | E48: Je ne sais pas
...

Sheet 2.4
A1: =Bilan!B17 -> 2.4 Application du guide technique
C3: E | D3: Total
B4: Nb quest. | C4: =COUNTIF(C8:C641,C3) -> 28 | D4: =COUNTA(B8:B641) -> 28
B5: Illust. | C5: =COUNTIF(C8:C641,"i")+COUNTIF(C8:C641,"p i") -> 16 | D5: =COUNTIF(A8:A641,"I") -> 16
B6: Prio | C6: =COUNTIF(C8:C641,"p")+COUNTIF(C8:C641,"p i") -> 4 | D6: =COUNTIF(A8:A641,"P") -> 4
A8: I | B8: 2-4_002 | C8: E | D8: Si l'on ne connaît pas la tension de la ligne électrique, il faut que le godet se trouve toujours à plus de :
A9: P | C9: =IF(C8="E",IF(A9="P",IF(A8="I","p i","p"),IF(A8="I","i"," ")),"") -> p i | D9: A | E9: 1 mètre
A10: § 6 du GT | D10: B | E10: 2 mètres
A11: TC OPERATEUR | D11: C | E11: 5 mètres
D12: D | E12: Je ne sais pas
A14: I | B14: 2-4_003 | C14: E | D14: Quand je travaille près d'une ligne aérienne à très haute tension (plus de 50 000 Volts), je dois rester à plus de 5 mètres : | F14: x
C15: =IF(C14="E",IF(A15="P",IF(A14="I","p i","p"),IF(A14="I","i"," ")),"") -> i | D15: A | E15: Du fil électrique le plus proche
A16: § 6.1 du GT | D16: B | E16: Du sol
D17: C | E17: Du pylône
D18: D | E18: Je ne sais pas
A20: I | B20: 2-4_004 | C20: E | D20: Quand je travaille près d'une ligne aérienne haute tension (plus de 1000 Volts), le godet doit toujours se trouver à plus de :
C21: =IF(C20="E",IF(A21="P",IF(A20="I","p i","p"),IF(A20="I","i"," ")),"") -> i | D21: A | E21: 3 mètres
A22: § 6 du GT | D22: B | E22: 5 mètres
D23: C | E23: 7 mètres
D24: D | E24: Je ne sais pas
B26: 2-4_007 | C26: E | D26: Avec une pelle hydraulique (précision annoncée : 0,15 m), jusqu'à quelle distance du marquage d'un réseau rigide de diamètre 60 mm et de classe de précision A peut-on terrasser sans précaution particulière ?
C27: =IF(C26="E",IF(A27="P",IF(A26="I","p i","p"),IF(A26="I","i"," ")),"") | D27: A | E27: 0,40 + 0,15 = 0,55 m
A28: GT - 5.2.5 | D28: B | E28: 0,40 m
D29: C | E29: 0,40 - 0,15 = 0,25 m
D30: D | E30: Je ne sais pas
B32: 2-4_008 | C32: E | D32: Avec une pelle hydraulique (précision annoncée : 0,15 m), jusqu'à quelle distance du marquage d'un réseau souple de diamètre 60 mm et de classe de précision A peut-on terrasser sans précaution particulière ?
D33: A | E33: 0,50 - 0,15 = 0,35 m
A34: GT - 5.2.5 | D34: B | E34: 0,50 m
D35: C | E35: 0,50 + 0,15 = 0,65 m
D36: D | E36: Je ne sais pas
A39: I | B39: 2-4_009 | C39: E | D39: Au dessus d'un réseau, on peut utiliser un engin lourd (pelle hydraulique, raboteuse, BRH…) :
C40: =IF(C39="E",IF(A40="P",IF(A39="I","p i","p"),IF(A39="I","i"," ")),"") -> i | D40: A | E40: Jusqu'à la découverte du grillage avertisseur
A41: Fiche AT-PEL du GT | D41: B | E41: Pour enlever la couche de surface dure
A42: TC OPERATEUR | D42: C | E42: Jusqu'à 10 cm du réseau enterré
D43: D | E43: Je ne sais pas
B45: 2-4_010 | C45: E | D45: Le remplacement d'un potelet sans élargissement de la fouille initiale est dispensé de DT et DICT lorsqu'il s'effectue :
C46: =IF(C45="E",IF(A46="P",IF(A45="I","p i","p"),IF(A45="I","i"," ")),"") | D46: A | E46: A moins de 70 cm de profondeur et à plus d'1 mètre de tout affleurant
A47: R554-1b) | D47: B | E47: A moins de 40 cm de profondeur et à plus de 50 cm de tout affleurant
D48: C | E48: A moins de 40 cm de profondeur et à plus d'1 mètre de tout affleurant
D49: D | E49: Je ne sais pas
...

Sheet 2.5
A1: =Bilan!B18 -> 2.5 Lecture des indices et affleurants
C3: E | D3: Total
B4: Nb quest. | C4: =COUNTIF(C8:C613,C3) -> 25 | D4: =COUNTA(B8:B613) -> 25
B5: Illust. | C5: =COUNTIF(C8:C613,"i")+COUNTIF(C8:C613,"p i") -> 23 | D5: =COUNTIF(A8:A613,"I") -> 23
B6: Prio | C6: =COUNTIF(C8:C613,"p")+COUNTIF(C8:C613,"p i") -> 1 | D6: =COUNTIF(A8:A613,"P") -> 1
A8: I | B8: 2-5_001 | C8: E | D8: Quelles canalisations peuvent changer brusquement de profondeur ?
C9: =IF(C8="E",IF(A9="P",IF(A8="I","p i","p"),IF(A8="I","i"," ")),"") -> i | D9: A | E9: Uniquement les réseaux de gaz
A10: GT - § 2.2 | D10: B | E10: Uniquement les réseaux électriques
D11: C | E11: Tous les types de réseaux
D12: E | E12: Je ne sais pas
A14: I | B14: 2-5_003ce | C14: E | D14: Lors d'un terrassement au dessus d'une canalisation, le grillage avertisseur risque d'être absent :
A15: P | C15: =IF(C14="E",IF(A15="P",IF(A14="I","p i","p"),IF(A14="I","i"," ")),"") -> p i | D15: A | E15: Lorsque la canalisation est classée non sensible pour la sécurité (assainissement par exemple)
A16: A13-7-00/art12 | D16: B | E16: Lorsque la canalisation est flexible
D17: C | E17: Pour tous les types de canalisation
D18: D | E18: Je ne sais pas
E19: A B C C
A20: I | B20: 2-5_004 | C20: E | D20: Laquelle de ces bornes signale un réseau enterré sensible pour la sécurité ?
C21: =IF(C20="E",IF(A21="P",IF(A20="I","p i","p"),IF(A20="I","i"," ")),"") -> i | D21: A | E21: -
A22: A5-3-14/art7-3 | D22: B | E22: -
D23: C | E23: -
D24: D | E24: Je ne sais pas
A28: I | B28: 2-5_006 | C28: E | D28: Je vais creuser dans une zone sans marquage à proximité de ce bâtiment :
C29: =IF(C28="E",IF(A29="P",IF(A28="I","p i","p"),IF(A28="I","i"," ")),"") -> i | D29: A | E29: J’ouvre la porte pour connaître les réseaux et leurs directions
A30: GT - § 3.1.2 | D30: B | E30: Je creuse en faisant attention
D31: C | E31: Je demande une vérification des réseaux et de leur emplacement
D32: D | E32: Je ne sais pas
B34: 2-5_007 | C34: E | D34: Lorsqu'un indice ou affleurant (coffret…) montre l’existence d’un branchement souterrain, comment prendre en compte ce branchement ?
C35: =IF(C34="E",IF(A35="P",IF(A34="I","p i","p"),IF(A34="I","i"," ")),"") | D35: A | E35: Le branchement se trouve forcément sur le chemin le plus court entre l’affleurant et le réseau principal
A36: GT - § 5.2.7 | D36: B | E36: J’applique des précautions particulières de fouille dans une bande de 2 m de large centrée sur le marquage du branchement
D37: C | E37: J'ouvre l'affleurant pour connaître la direction du branchement
D38: D | E38: Je ne sais pas
A40: I | B40: 2-5_008 | C40: E | D40: En creusant, je rencontre un grillage avertisseur jaune. Il signale généralement un réseau :
C41: =IF(C40="E",IF(A41="P",IF(A40="I","p i","p"),IF(A40="I","i"," ")),"") -> i | D41: A | E41: D’électricité
A42: A13-7-00/art12 | D42: B | E42: De téléphone
A43: TC OPERATEUR | D43: C | E43: De gaz
D44: E | E44: Je ne sais pas
A45: I | B45: 2-5_009 | C45: E | D45: En creusant, je rencontre un grillage avertisseur rouge. Il signale généralement un réseau :
C46: =IF(C45="E",IF(A46="P",IF(A45="I","p i","p"),IF(A45="I","i"," ")),"") -> i | D46: A | E46: D’électricité
A47: D14-11-88/art19 | D47: B | E47: De téléphone
A48: TC OPERATEUR | D48: C | E48: De gaz
...

Sheet 2.6
A1: =Bilan!B19 -> 2.6 Travaux sans tranchée
C3: C | D3: E | E3: O | F3: Total
B4: Nb quest. | C4: =COUNTIF(C8:C613,C3) -> 1 | D4: =COUNTIF(D8:D613,D3) -> 1 | E4: =COUNTIF(E8:E613,E3) -> 1 | F4: =COUNTA(B8:B613) -> 1
B5: Illust. | C5: =COUNTIF(C8:C613,"i")+COUNTIF(C8:C613,"p i") -> 1 | D5: =COUNTIF(D8:D613,"i")+COUNTIF(D8:D613,"p i") -> 1 | E5: =COUNTIF(E8:E613,"i")+COUNTIF(E8:E613,"p i") -> 1 | F5: =COUNTIF(A8:A613,"I") -> 1
B6: Prio | C6: =COUNTIF(C8:C613,"p")+COUNTIF(C8:C613,"p i") -> 0 | D6: =COUNTIF(D8:D613,"p")+COUNTIF(D8:D613,"p i") -> 0 | E6: =COUNTIF(E8:E613,"p")+COUNTIF(E8:E613,"p i") -> 0 | F6: =COUNTIF(A8:A613,"P") -> 0
A8: I | B8: 2-6_002 | C8: C | D8: E | E8: O | F8: Lors de travaux sans tranchée avec fusée pneumatique, la trajectoire de la fusée doit être surveillée :
C9: =IF(C8="C",IF(A9="P",IF(A8="I","p i","p"),IF(A8="I","i","")),"") -> i | D9: =IF(D8="E",IF(A9="P",IF(A8="I","p i","p"),IF(A8="I","i"," ")),"") -> i | E9: =IF(E8="O",IF(A9="P",IF(A8="I","p i","p"),IF(A8="I","i"," ")),"") -> i | F9: A | G9: Au lancement
A10: Fiche ST-FUS1 du GT | F10: B | G10: A la fin du parcours
F11: C | G11: Durant tout le parcours
F12: D | G12: Je ne sais pas
C116: =IF(C115="C",IF(A116="P",IF(A115="I","p i","p"),IF(A115="I","i","")),"") | D116: =IF(D115="E",IF(A116="P",IF(A115="I","p i","p"),IF(A115="I","i"," ")),"") | E116: =IF(E115="O",IF(A116="P",IF(A115="I","p i","p"),IF(A115="I","i"," ")),"")
C123: =IF(C122="C",IF(A123="P",IF(A122="I","p i","p"),IF(A122="I","i","")),"") | D123: =IF(D122="E",IF(A123="P",IF(A122="I","p i","p"),IF(A122="I","i"," ")),"") | E123: =IF(E122="O",IF(A123="P",IF(A122="I","p i","p"),IF(A122="I","i"," ")),"")
C130: =IF(C129="C",IF(A130="P",IF(A129="I","p i","p"),IF(A129="I","i","")),"") | D130: =IF(D129="E",IF(A130="P",IF(A129="I","p i","p"),IF(A129="I","i"," ")),"") | E130: =IF(E129="O",IF(A130="P",IF(A129="I","p i","p"),IF(A129="I","i"," ")),"")
C137: =IF(C136="C",IF(A137="P",IF(A136="I","p i","p"),IF(A136="I","i","")),"") | D137: =IF(D136="E",IF(A137="P",IF(A136="I","p i","p"),IF(A136="I","i"," ")),"") | E137: =IF(E136="O",IF(A137="P",IF(A136="I","p i","p"),IF(A136="I","i"," ")),"")
C144: =IF(C143="C",IF(A144="P",IF(A143="I","p i","p"),IF(A143="I","i","")),"") | D144: =IF(D143="E",IF(A144="P",IF(A143="I","p i","p"),IF(A143="I","i"," ")),"") | E144: =IF(E143="O",IF(A144="P",IF(A143="I","p i","p"),IF(A143="I","i"," ")),"")
C145: =IF(C144="C",IF(A145="Prioritaire",IF(A144="I","p i","p"),IF(A144="I","i","")),"") | D145: =IF(D144="E",IF(A145="Prioritaire",IF(A144="I","p i","p"),IF(A144="I","i"," ")),"") | E145: =IF(E144="O",IF(A145="Prioritaire",IF(A144="I","p i","p"),IF(A144="I","i"," ")),"")
C151: =IF(C150="C",IF(A151="P",IF(A150="I","p i","p"),IF(A150="I","i","")),"") | D151: =IF(D150="E",IF(A151="P",IF(A150="I","p i","p"),IF(A150="I","i"," ")),"") | E151: =IF(E150="O",IF(A151="P",IF(A150="I","p i","p"),IF(A150="I","i"," ")),"")
C158: =IF(C157="C",IF(A158="P",IF(A157="I","p i","p"),IF(A157="I","i","")),"") | D158: =IF(D157="E",IF(A158="P",IF(A157="I","p i","p"),IF(A157="I","i"," ")),"") | E158: =IF(E157="O",IF(A158="P",IF(A157="I","p i","p"),IF(A157="I","i"," ")),"")
C165: =IF(C164="C",IF(A165="P",IF(A164="I","p i","p"),IF(A164="I","i","")),"") | D165: =IF(D164="E",IF(A165="P",IF(A164="I","p i","p"),IF(A164="I","i"," ")),"") | E165: =IF(E164="O",IF(A165="P",IF(A164="I","p i","p"),IF(A164="I","i"," ")),"")
C172: =IF(C171="C",IF(A172="P",IF(A171="I","p i","p"),IF(A171="I","i","")),"") | D172: =IF(D171="E",IF(A172="P",IF(A171="I","p i","p"),IF(A171="I","i"," ")),"") | E172: =IF(E171="O",IF(A172="P",IF(A171="I","p i","p"),IF(A171="I","i"," ")),"")
C179: =IF(C178="C",IF(A179="P",IF(A178="I","p i","p"),IF(A178="I","i","")),"") | D179: =IF(D178="E",IF(A179="P",IF(A178="I","p i","p"),IF(A178="I","i"," ")),"") | E179: =IF(E178="O",IF(A179="P",IF(A178="I","p i","p"),IF(A178="I","i"," ")),"")
C186: =IF(C185="C",IF(A186="P",IF(A185="I","p i","p"),IF(A185="I","i","")),"") | D186: =IF(D185="E",IF(A186="P",IF(A185="I","p i","p"),IF(A185="I","i"," ")),"") | E186: =IF(E185="O",IF(A186="P",IF(A185="I","p i","p"),IF(A185="I","i"," ")),"")
C193: =IF(C192="C",IF(A193="P",IF(A192="I","p i","p"),IF(A192="I","i","")),"") | D193: =IF(D192="E",IF(A193="P",IF(A192="I","p i","p"),IF(A192="I","i"," ")),"") | E193: =IF(E192="O",IF(A193="P",IF(A192="I","p i","p"),IF(A192="I","i"," ")),"")
C200: =IF(C199="C",IF(A200="P",IF(A199="I","p i","p"),IF(A199="I","i","")),"") | D200: =IF(D199="E",IF(A200="P",IF(A199="I","p i","p"),IF(A199="I","i"," ")),"") | E200: =IF(E199="O",IF(A200="P",IF(A199="I","p i","p"),IF(A199="I","i"," ")),"")
C207: =IF(C206="C",IF(A207="P",IF(A206="I","p i","p"),IF(A206="I","i","")),"") | D207: =IF(D206="E",IF(A207="P",IF(A206="I","p i","p"),IF(A206="I","i"," ")),"") | E207: =IF(E206="O",IF(A207="P",IF(A206="I","p i","p"),IF(A206="I","i"," ")),"")
C214: =IF(C213="C",IF(A214="P",IF(A213="I","p i","p"),IF(A213="I","i","")),"") | D214: =IF(D213="E",IF(A214="P",IF(A213="I","p i","p"),IF(A213="I","i"," ")),"") | E214: =IF(E213="O",IF(A214="P",IF(A213="I","p i","p"),IF(A213="I","i"," ")),"")
C221: =IF(C220="C",IF(A221="P",IF(A220="I","p i","p"),IF(A220="I","i","")),"") | D221: =IF(D220="E",IF(A221="P",IF(A220="I","p i","p"),IF(A220="I","i"," ")),"") | E221: =IF(E220="O",IF(A221="P",IF(A220="I","p i","p"),IF(A220="I","i"," ")),"")
C228: =IF(C227="C",IF(A228="P",IF(A227="I","p i","p"),IF(A227="I","i","")),"") | D228: =IF(D227="E",IF(A228="P",IF(A227="I","p i","p"),IF(A227="I","i"," ")),"") | E228: =IF(E227="O",IF(A228="P",IF(A227="I","p i","p"),IF(A227="I","i"," ")),"")
... C430: =IF(C429="C",IF(A430="P",IF(A429="I","p i","p"),IF(A429="I","i","")),"") | D430: =IF(D429="E",IF(A430="P",IF(A429="I","p i","p"),IF(A429="I","i"," ")),"") | E430: =IF(E429="O",IF(A430="P",IF(A429="I","p i","p"),IF(A429="I","i"," ")),"")
C431: =IF(C430="C",IF(A431="Prioritaire",IF(A430="I","p i","p"),IF(A430="I","i","")),"") | D431: =IF(D430="E",IF(A431="Prioritaire",IF(A430="I","p i","p"),IF(A430="I","i"," ")),"") | E431: =IF(E430="O",IF(A431="Prioritaire",IF(A430="I","p i","p"),IF(A430="I","i"," ")),"")

Sheet 3.1
A1: =Bilan!B21 -> 3.1 Constat d'arrêt ou de sursis
C3: E | D3: Total
B4: Nb quest. | C4: =COUNTIF(C8:C547,C3) -> 7 | D4: =COUNTA(B8:B547) -> 7
B5: Illust. | C5: =COUNTIF(C8:C547,"i")+COUNTIF(C8:C547,"p i") -> 5 | D5: =COUNTIF(A8:A547,"I") -> 5
B6: Prio | C6: =COUNTIF(C8:C547,"p")+COUNTIF(C8:C547,"p i") -> 1 | D6: =COUNTIF(A8:A547,"P") -> 1
A8: I | B8: 3-1_002 | C8: E | D8: Si en cours de chantier, l'opérateur découvre un réseau sans marquage au sol susceptible de gêner les travaux, que doit-il faire ?
A9: P | C9: =IF(C8="E",IF(A9="P",IF(A8="I","p i","p"),IF(A8="I","i"," ")),"") -> p i | D9: A | E9: Arrêter immédiatement les travaux et en référer au responsable de projet
A10: R554-28I | D10: B | E10: Compléter le marquage et continuer les travaux
D11: C | E11: Couper la canalisation car elle est probablement abandonnée
D12: D | E12: Je ne sais pas
B14: 3-1_005 | C14: E | D14: Suite à la découverte d'un réseau non identifié nécessitant un constat d'arrêt de travaux, celui-ci est signé par l'exécutant des travaux ainsi que par :
C15: =IF(C14="E",IF(A15="P",IF(A14="I","p i","p"),IF(A14="I","i"," ")),"") | D15: A | E15: L'exploitant du réseau concerné
A16: NFS70-003-1/AnC | D16: B | E16: Le responsable de projet
D17: C | E17: L'inspecteur du travail
D18: D | E18: Je ne sais pas
A20: I | B20: 3-1_007e | C20: E | D20: Dans une tranchée, un câble électrique mal placé gêne le chantier :
C21: =IF(C20="E",IF(A21="P",IF(A20="I","p i","p"),IF(A20="I","i"," ")),"") -> i | D21: A | E21: Je suspends les travaux aux abords du câble
A22: R554-28I | D22: B | E22: J'impose le port de gants isolants aux personnels
D23: C | E23: Je fais déplacer le câble hors de la tranchée
D24: D | E24: Je ne sais pas
B26: 3-1_010 | C26: E | D26: Lors de travaux, l'executant de travaux découvre un réseau qui présente un écart notable de localisation mettant en cause la poursuite du chantier. Que doit faire l'encadrant du chantier ?
C27: =IF(C26="E",IF(A27="P",IF(A26="I","p i","p"),IF(A26="I","i"," ")),"") | D27: A | E27: Poursuivre le chantier en prenant toutes les mesures de sécurité nécessaires puis informer le maître d'ouvrage et l'exploitant du réseau en cause pour se dégager de toute responsabilité
A28: R554-28I | D28: B | E28: Arrêter les travaux, alerter le responsable de projet (maître d'ouvrage) et attendre sa décision écrite sur les mesures à prendre
D29: C | E29: Contacter directement l'exploitant du réseau en cause qui doit immédiatement procéder à la mise en sécurité du réseau
D30: D | E30: Je ne sais pas
A33: I | B33: 3-1_011e | C33: E | D33: Dans une fouille, je découvre un câble électrique non cartographié. Comment dois-je le considérer ?
C34: =IF(C33="E",IF(A34="P",IF(A33="I","p i","p"),IF(A33="I","i"," ")),"") -> i | D34: A | E34: Comme étant hors tension
D35: B | E35: Comme étant sous tension
D36: C | E36: Comme étant hors service
D37: D | E37: Je ne sais pas
A39: I | B39: 3-1_013 | C39: E | D39: Un opérateur devant soutenir un câble électrique m'informe que celui-ci est endommagé. Que dois-je faire ?
C40: =IF(C39="E",IF(A40="P",IF(A39="I","p i","p"),IF(A39="I","i"," ")),"") -> i | D40: A | E40: Je fais doubler le nombre de sangles
A41: NF C 18-510 | D41: B | E41: Je fais arrêter l'opération et j'alerte l'exploitant
D42: C | E42: Je le fais réparer avec du ruban adhésif avant de faire le soutènement
D43: D | E43: Je ne sais pas
A45: I | B45: 3-1_014e | C45: E | D45: Un opérateur m'informe qu'une canalisation d'un réseau sensible à dégager est emprisonnée dans du béton. Que dois-je faire ?
C46: =IF(C45="E",IF(A46="P",IF(A45="I","p i","p"),IF(A45="I","i"," ")),"") -> i | D46: A | E46: Je lui demande de la dégager à l'aide d'un petit marteur piqueur
A47: NF C 18-510 | D47: B | E47: Je lui demande de la dégager avec une barre à mine isolante
D48: C | E48: Je demande la mise hors tension à l'exploitant
D49: D | E49: Je ne sais pas
...

Sheet 3.2
A1: =Bilan!B22 -> 3.2 Constat de dommage
C3: E | D3: Total
B4: Nb quest. | C4: =COUNTIF(C8:C607,C3) -> 14 | D4: =COUNTA(B8:B638) -> 15
B5: Illust. | C5: =COUNTIF(C8:C607,"i")+COUNTIF(C8:C607,"p i") -> 9 | D5: =COUNTIF(A8:A638,"I") -> 10
B6: Prio | C6: =COUNTIF(C8:C607,"p")+COUNTIF(C8:C607,"p i") -> 3 | D6: =COUNTIF(A8:A638,"P") -> 3
B8: 3-2_003 | C8: E | D8: Le remplissage d’un constat contradictoire en cas de dommage est fait conjointement par :
C9: =IF(C8="E",IF(A9="P",IF(A8="I","p i","p"),IF(A8="I","i"," ")),"") | D9: A | E9: L’entreprise exécutant les travaux et l’exploitant du réseau concerné
A10: NFS70-003-1/AnE | D10: B | E10: L’entreprise exécutant les travaux et le responsable de projet (ou maître d’ouvrage)
D11: C | E11: Le responsable de projet (ou maître d’ouvrage) et l’exploitant de réseau concerné
D12: D | E12: Je ne sais pas
B14: 3-2_004ce | C14: E | D14: En cas d’endommagement d'un réseau de gaz, indiquez la consigne parmi les suivantes qui ne fait pas partie intégrante de la règle des 4A :
C15: =IF(C14="E",IF(A15="P",IF(A14="I","p i","p"),IF(A14="I","i"," ")),"") | D15: A | E15: Accueillir les secours
A16: A15-2-12/An5-3 | D16: B | E16: Alerter les pompiers
D17: C | E17: Arrêter la fuite
D18: D | E18: Je ne sais pas
B20: 3-2_005 | C20: E | D20: Un opérateur d’engin a touché une canalisation de gaz avec le godet provoquant une légère éraflure. Que faire ?
A21: P | C21: =IF(C20="E",IF(A21="P",IF(A20="I","p i","p"),IF(A20="I","i"," ")),"") -> p | D21: A | E21: Entourer la conduite d’un adhésif résistant
A22: R554-31II | D22: B | E22: Arrêter les travaux dans la zone et contacter l’exploitant ainsi que le responsable de projet afin de leur signaler l’incident
D23: C | E23: Continuer le travail car la canalisation est protégée par la protection cathodique
D24: D | E24: Je ne sais pas
B26: 3-2_009 | C26: E | D26: En cas d’endommagement d’une canalisation de gaz avec fuite, en tant qu'encadrant de chantier, j’alerte dans l’ordre :
C27: =IF(C26="E",IF(A27="P",IF(A26="I","p i","p"),IF(A26="I","i"," ")),"") | D27: A | E27: Les pompiers, l’exploitant, le responsable de projet (ou maître d'ouvrage)
A28: R554-31II | D28: B | E28: L’exploitant, la police, les pompiers
D29: C | E29: Le responsable de projet (ou maître d'ouvrage), le 112, l’exploitant
D30: D | E30: Je ne sais pas
A32: I | B32: 3-2_014e | C32: E | D32: Un opérateur vient de prendre une décharge électrique, mais ça a l'air d'aller. Que dois-je faire ?
C33: =IF(C32="E",IF(A33="P",IF(A32="I","p i","p"),IF(A32="I","i"," ")),"") -> i | D33: A | E33: Rien de particulier, il continue son travail
A34: A15-2-12/An5-3 | D34: B | E34: J'en parle à un collègue pour qu’il le surveille
D35: C | E35: Je le fais accompagner à un service médical pour un électrocardiogramme
D36: D | E36: Je ne sais pas
A38: I | B38: 3-2_011 | C38: E | D38: Suite à un accident, j'appelle les pompiers. Je peux raccrocher dès que :
C39: =IF(C38="E",IF(A39="P",IF(A38="I","p i","p"),IF(A38="I","i"," ")),"") -> i | D39: A | E39: J'ai indiqué la nature et le lieu de l'accident
A40: A15-2-12/An5-3 | D40: B | E40: J'ai fourni le nombre de victimes et leur nom
D41: C | E41: Le pompier me le demande
D42: D | E42: Je ne sais pas
A44: I | B44: 3-2_013 | C44: E | D44: Une personne prend une décharge électrique et reste en contact avec le câble électrique. Je m'écarte et j'appelle en tout premier ? | F44: x
C45: =IF(C44="E",IF(A45="P",IF(A44="I","p i","p"),IF(A44="I","i"," ")),"") -> i | D45: A | E45: Les pompiers
A46: A15-2-12/An5-3 | D46: B | E46: L'exploitant
D47: C | E47: le responsable de projet (ou maître d'ouvrage)
D48: D | E48: Je ne sais pas
...

Sheet 3.3
A1: =Bilan!B23 -> 3.3 Opérations sur chantier
C3: E | D3: Total
B4: Nb quest. | C4: =COUNTIF(C8:C575,C3) -> 34 | D4: =COUNTA(B8:B575) -> 34
B5: Illust. | C5: =COUNTIF(C8:C575,"i")+COUNTIF(C8:C575,"p i") -> 28 | D5: =COUNTIF(A8:A575,"I") -> 28
B6: Prio | C6: =COUNTIF(C8:C575,"p")+COUNTIF(C8:C575,"p i") -> 1 | D6: =COUNTIF(A8:A575,"P") -> 1
A9: I | B9: 3-3_001 | C9: E | D9: Lors d'une fuite d'une canalisation de gaz, les personnes situées à proximité sont exposées à un risque :
C10: =IF(C9="E",IF(A10="P",IF(A9="I","p i","p"),IF(A9="I","i"," ")),"") -> i | D10: A | E10: De brulure
A11: GT - § 3.3 | D11: B | E11: De fièvre
D12: C | E12: D'eczéma
D13: D | E13: Je ne sais pas
A15: I | B15: 3-3_003 | C15: E | D15: Suite à un choc sur une canalisation de gaz, je considère :
C16: =IF(C15="E",IF(A16="P",IF(A15="I","p i","p"),IF(A15="I","i"," ")),"") -> i | D16: A | E16: Qu'il n'y a pas de risque, s'il n'y a pas d'odeur de gaz
A17: GT - § 3.3.3.4 | D17: B | E17: Qu'il n'y a pas de risque, s'il n'y a pas de sifflement
D18: C | E18: Qu'il y a toujours un risque
D19: D | E19: Je ne sais pas
A21: I | B21: 3-3_004 | C21: E | D21: Dans le cas de contact avec un fil électrique nu, la personne concernée risque la mort par :
C22: =IF(C21="E",IF(A22="P",IF(A21="I","p i","p"),IF(A21="I","i"," ")),"") -> i | D22: A | E22: Electrocution
A23: GT - § 3.1.4 | D23: B | E23: Intoxication
D24: C | E24: Asphyxie
D25: D | E25: Je ne sais pas
A27: I | B27: 3-3_005 | C27: E | D27: Lors d'un contact avec un conducteur électrique isolé endommagé, la personne concernée risque :
C28: =IF(C27="E",IF(A28="P",IF(A27="I","p i","p"),IF(A27="I","i"," ")),"") -> i | D28: A | E28: Seulement l'électrisation
A29: GT - § 3.1.4 | D29: B | E29: Seulement une brulure
D30: C | E30: L'électrisation et une brulure
D31: D | E31: Je ne sais pas
A33: I | B33: 3-3_007 | C33: E | D33: Je dois dégager une canalisation, mais je ne connais pas sa profondeur. Après avoir cassé la surface dure, je peux utiliser :
C34: =IF(C33="E",IF(A34="P",IF(A33="I","p i","p"),IF(A33="I","i"," ")),"") -> i | D34: A | E34: Un marteau piqueur
A35: GT - § 5.3.1 et Fiche AT-TED | D35: B | E35: Un camion aspirateur muni d'un embout souple
D36: C | E36: Une mini-pelle
D37: D | E37: Je ne sais pas
