Workbook
Name OLE_LINK1: '1.2'!#REF!
Name OLE_LINK1_1: '1.6'!#REF!

Sheet Bilan
P1: Fichier publié le 19/08/2021
C4: QCM CONCEPTEUR "C" | F4: QCM ENCADRANT "E" | I4: QCM OPERATEUR "O" | L4: Nombre Questions | P4: Légendes :
C5: Nb | D5: Prio. | E5: Illust. | F5: Nb | G5: Prio. | H5: Illust. | I5: Nb | J5: Prio. | K5: Illust. | L5: Nb | M5: Prio. | N5: Illust. | P5: QCM illustré (1) | T5: I
B6: 1. Responsable de projet avant les chantiers | P6: QCM dit "prioritaire" | T6: P
B7: 1.1 DT | C7: ='1.1'!C$4 -> 17 | D7: ='1.1'!C$6 -> 3 | E7: ='1.1'!C$5 -> 2 | F7: ='1.1'!D$4 -> 11 | G7: ='1.1'!D$6 -> 2 | H7: ='1.1'!D$5 -> 2 | I7: ='1.1'!E$4 -> 0 | J7: ='1.1'!E$6 -> 0 | K7: ='1.1'!E$5 -> 0 | L7: ='1.1'!F$4 -> 17 | M7: ='1.1'!F$6 -> 3 | N7: ='1.1'!F$5 -> 2 | P7: QCM du "tronc commun Opérateur" | T7: TC OPERATEUR
B8: 1.2 Analyse des réponses - IC - Cartographie | C8: ='1.2'!C$4 -> 16 | D8: ='1.2'!C$6 -> 1 | E8: ='1.2'!C$5 -> 2 | F8: ='1.2'!D$4 -> 9 | G8: ='1.2'!D$6 -> 0 | H8: ='1.2'!D$5 -> 2 | I8: ='1.2'!E$4 -> 2 | J8: ='1.2'!E$6 -> 0 | K8: ='1.2'!E$5 -> 2 | L8: ='1.2'!F$4 -> 16 | M8: ='1.2'!F$6 -> 1 | N8: ='1.2'!F$5 -> 2 | P8: Référerences réglementaires du QCM | T8: R554-25
B9: 1.3 Clauses dans les marchés et DCE | C9: ='1.3'!C$4 -> 4 | D9: ='1.3'!C$6 -> 0 | E9: ='1.3'!C$5 -> 0 | F9: ='1.3'!D$4 -> 2 | G9: ='1.3'!D$6 -> 0 | H9: ='1.3'!D$5 -> 0 | I9: ='1.3'!E$4 -> 0 | J9: ='1.3'!E$6 -> 0 | K9: ='1.3'!E$5 -> 0 | L9: ='1.3'!F$4 -> 4 | M9: ='1.3'!F$6 -> 0 | N9: ='1.3'!F$5 -> 0
B10: 1.4 Marquage - Piquetage | C10: ='1.4'!C$4 -> 7 | D10: ='1.4'!C$6 -> 1 | E10: ='1.4'!C$5 -> 3 | F10: ='1.4'!D$4 -> 7 | G10: ='1.4'!D$6 -> 1 | H10: ='1.4'!D$5 -> 3 | I10: ='1.4'!E$4 -> 4 | J10: ='1.4'!E$6 -> 0 | K10: ='1.4'!E$5 -> 4 | L10: ='1.4'!F$4 -> 8 | M10: ='1.4'!F$6 -> 1 | N10: ='1.4'!F$5 -> 4 | P10: (1) Toutes les illustrations sont dans le fichier ZIP joint
B11: 1.5 Compétences des personnels | C11: ='1.5'!C$4 -> 2 | D11: ='1.5'!C$6 -> 0 | E11: ='1.5'!C$5 -> 0 | F11: ='1.5'!D$4 -> 0 | G11: ='1.5'!D$6 -> 0 | H11: ='1.5'!D$5 -> 0 | I11: ='1.5'!E$4 -> 0 | J11: ='1.5'!E$6 -> 0 | K11: ='1.5'!E$5 -> 0 | L11: ='1.5'!F$4 -> 2 | M11: ='1.5'!F$6 -> 0 | N11: ='1.5'!F$5 -> 0 | P11: Nota important : parmi les 250 QCM de ce fichier, 103 ont fait l'objet d'une modification ou ont été ajoutée. Elle sont publiées pour information sur le site du GU le 19/08/2021
B12: 1.6 Cartographie | C12: ='1.6'!C$4 -> 8 | D12: ='1.6'!C$6 -> 1 | E12: ='1.6'!C$5 -> 1 | F12: ='1.6'!D$4 -> 8 | G12: ='1.6'!D$6 -> 1 | H12: ='1.6'!D$5 -> 1 | I12: ='1.6'!E$4 -> 1 | J12: ='1.6'!E$6 -> 0 | K12: ='1.6'!E$5 -> 1 | L12: ='1.6'!F$4 -> 9 | M12: ='1.6'!F$6 -> 1 | N12: ='1.6'!F$5 -> 2 | P12: en application du V de l'article 3 Arrêté du 22 décembre 2015 relatif au contrôle des compétences des personnes intervenant dans les travaux à proximité des réseaux
B13: 2. Exécutants avant les chantiers | P13: et seront suceptibles de figurer à l'examen à complter du 19 novembre 2021
B14: 2.1 DICT | C14: ='2.1'!C$4 -> 3 | D14: ='2.1'!C$6 -> 1 | E14: ='2.1'!C$5 -> 0 | F14: ='2.1'!D$4 -> 3 | G14: ='2.1'!D$6 -> 1 | H14: ='2.1'!D$5 -> 0 | I14: ='2.1'!E$4 -> 0 | J14: ='2.1'!E$6 -> 0 | K14: ='2.1'!E$5 -> 0 | L14: ='2.1'!F$4 -> 3 | M14: ='2.1'!F$6 -> 1 | N14: ='2.1'!F$5 -> 0 | P14: 1-1_007 | Q14: 1-5_011 | R14: 2-4_014 | S14: 2-5_026 | T14: 3-2_017o | U14: 3-3_051
B15: 2.2 Analyse des réponses, du DCE et du marché | C15: ='2.2'!C$4 -> 18 | D15: ='2.2'!C$6 -> 3 | E15: ='2.2'!C$5 -> 4 | F15: ='2.2'!D$4 -> 17 | G15: ='2.2'!D$6 -> 3 | H15: ='2.2'!D$5 -> 4 | I15: ='2.2'!E$4 -> 0 | J15: ='2.2'!E$6 -> 0 | K15: ='2.2'!E$5 -> 0 | L15: ='2.2'!F$4 -> 18 | M15: ='2.2'!F$6 -> 3 | N15: ='2.2'!F$5 -> 4 | P15: 1-1_012 | Q15: 1-6_011 | R15: 2-4_019o | S15: 2-5_031 | T15: 3-2_028 | U15: 3-3_052
B16: 2.3 Compétences des personnels | C16: ='2.3'!C$4 -> 5 | D16: ='2.3'!C$6 -> 1 | E16: ='2.3'!C$5 -> 3 | F16: ='2.3'!D$4 -> 16 | G16: ='2.3'!D$6 -> 4 | H16: ='2.3'!D$5 -> 14 | I16: ='2.3'!E$4 -> 14 | J16: ='2.3'!E$6 -> 1 | K16: ='2.3'!E$5 -> 14 | L16: ='2.3'!F$4 -> 18 | M16: ='2.3'!F$6 -> 4 | N16: ='2.3'!F$5 -> 16 | P16: 1-1_013 | Q16: 1-6_016ce | R16: 2-4_019ce | S16: 2-5_032 | T16: 3-2_029 | U16: 3-3_053
B17: 2.4 Application du guide technique | C17: ='2.4'!C$4 -> 23 | D17: ='2.4'!C$6 -> 3 | E17: ='2.4'!C$5 -> 12 | F17: ='2.4'!D$4 -> 28 | G17: ='2.4'!D$6 -> 4 | H17: ='2.4'!D$5 -> 16 | I17: ='2.4'!E$4 -> 23 | J17: ='2.4'!E$6 -> 2 | K17: ='2.4'!E$5 -> 19 | L17: ='2.4'!F$4 -> 38 | M17: ='2.4'!F$6 -> 5 | N17: ='2.4'!F$5 -> 26 | P17: 1-1_015 | Q17: 1-6_018 | R17: 2-4_033 | S17: 2-5_033 | T17: 3-3_007
B18: 2.5 Lecture des indices et affleurants | C18: ='2.5'!C$4 -> 21 | D18: ='2.5'!C$6 -> 1 | E18: ='2.5'!C$5 -> 19 | F18: ='2.5'!D$4 -> 25 | G18: ='2.5'!D$6 -> 1 | H18: ='2.5'!D$5 -> 23 | I18: ='2.5'!E$4 -> 24 | J18: ='2.5'!E$6 -> 0 | K18: ='2.5'!E$5 -> 24 | L18: ='2.5'!F$4 -> 28 | M18: ='2.5'!F$6 -> 1 | N18: ='2.5'!F$5 -> 26 | P18: 1-1_016 | Q18: 2-1_005 | R18: 2-4_036 | S18: 3-1_010 | T18: 3-3_008
B19: 2.6 Travaux sans tranchée | C19: ='2.6'!C$4 -> 1 | D19: ='2.6'!C$6 -> 0 | E19: ='2.6'!C$5 -> 1 | F19: ='2.6'!D$4 -> 1 | G19: ='2.6'!D$6 -> 0 | H19: ='2.6'!D$5 -> 1 | I19: ='2.6'!E$4 -> 1 | J19: ='2.6'!E$6 -> 0 | K19: ='2.6'!E$5 -> 1 | L19: ='2.6'!F$4 -> 1 | M19: ='2.6'!F$6 -> 0 | N19: ='2.6'!F$5 -> 1 | P19: 1-1_031 | Q19: 2-2_007 | R19: 2-4_038 | S19: 3-1_011 | T19: 3-3_009
B20: 3. Au cours du chantier | P20: 1-1_032 | Q20: 2-2_008 | R20: 2-4_042 | S20: 3-1_011e | T20: 3-3_011
B21: 3.1 Constat d'arrêt ou de sursis | C21: ='3.1'!C$4 -> 3 | D21: ='3.1'!C$6 -> 1 | E21: ='3.1'!C$5 -> 1 | F21: ='3.1'!D$4 -> 7 | G21: ='3.1'!D$6 -> 1 | H21: ='3.1'!D$5 -> 5 | I21: ='3.1'!E$4 -> 11 | J21: ='3.1'!E$6 -> 1 | K21: ='3.1'!E$5 -> 11 | L21: ='3.1'!F$4 -> 18 | M21: ='3.1'!F$6 -> 2 | N21: ='3.1'!F$5 -> 16 | P21: 1-1_033 | Q21: 2-2_009 | R21: 2-4_043 | S21: 3-1_012 | T21: 3-3_015
B22: 3.2 Constat de dommage | C22: ='3.2'!C$4 -> 7 | D22: ='3.2'!C$6 -> 2 | E22: ='3.2'!C$5 -> 4 | F22: ='3.2'!D$4 -> 14 | G22: ='3.2'!D$6 -> 3 | H22: ='3.2'!D$5 -> 9 | I22: ='3.2'!E$4 -> 15 | J22: ='3.2'!E$6 -> 2 | K22: ='3.2'!E$5 -> 15 | L22: ='3.2'!F$4 -> 24 | M22: ='3.2'!F$6 -> 4 | N22: ='3.2'!F$5 -> 19 | P22: 1-2_003 | Q22: 2-2_014 | R22: 2-4_044 | S22: 3-1_013 | T22: 3-3_017
B23: 3.3 Opérations sur chantier | C23: ='3.3'!C$4 -> 20 | D23: ='3.3'!C$6 -> 1 | E23: ='3.3'!C$5 -> 16 | F23: ='3.3'!D$4 -> 34 | G23: ='3.3'!D$6 -> 1 | H23: ='3.3'!D$5 -> 28 | I23: ='3.3'!E$4 -> 36 | J23: ='3.3'!E$6 -> 0 | K23: ='3.3'!E$5 -> 35 | L23: ='3.3'!F$4 -> 46 | M23: ='3.3'!F$6 -> 1 | N23: ='3.3'!F$5 -> 39 | P23: 1-2_004 | Q23: 2-2_015 | R23: 2-4_045 | S23: 3-1_014o | T23: 3-3_033
B24: TOTAL | C24: =SUM(C7:C23) -> 155 | D24: =SUM(D7:D23) -> 19 | E24: =SUM(E7:E23) -> 68 | F24: =SUM(F7:F23) -> 182 | G24: =SUM(G7:G23) -> 22 | H24: =SUM(H7:H23) -> 108 | I24: =SUM(I7:I23) -> 131 | J24: =SUM(J7:J23) -> 6 | ... N24: =SUM(N7:N23) -> 157 | P24: 1-2_006 | Q24: 2-3_018 | R24: 2-4_046 | S24: 3-1_014e | T24: 3-3_041
P25: 1-2_007 | Q25: 2-3_020 | R25: 2-4_047 | S25: 3-1_015 | T25: 3-3_042
P26: 1-2_009 | Q26: 2-3_016 | R26: 2-4_048 | S26: 3-1_016 | T26: 3-3_043
P27: 1-2_023 | Q27: 2-3_028 | R27: 2-5_005 | S27: 3-1_017 | T27: 3-3_044
P28: 1-3_011 | Q28: 2-3_029 | R28: 2-5_008 | S28: 3-1_018 | T28: 3-3_045
P29: 1-3_012 | Q29: 2-4_004 | R29: 2-5_009 | S29: 3-1_019 | T29: 3-3_046
P30: 1-4_004 | Q30: 2-4_007 | R30: 2-5_010 | S30: 3-1_020 | T30: 3-3_047
P31: 1-4_008 | Q31: 2-4_008 | R31: 2-5_011 | S31: 3-2_014e | T31: 3-3_048
P32: 1-5_001 | Q32: 2-4_011 | R32: 2-5_012 | S32: 3-2_014 | T32: 3-3_049
P33: 1-5_002 | Q33: 2-4_012 | R33: 2-5_013 | S33: 3-2_017e | T33: 3-3_050

Sheet 1.1
A1: =Bilan!B7 -> 1.1 DT
C3: C | D3: E | E3: O | F3: Total
B4: Nb quest. | C4: =COUNTIF(C8:C660,C3) -> 17 | D4: =COUNTIF(D8:D660,D3) -> 11 | E4: =COUNTIF(E8:E660,E3) -> 0 | F4: =COUNTA(B8:B660) -> 17
B5: Illust. | C5: =COUNTIF(C8:C660,"i")+COUNTIF(C8:C660,"p i") -> 2 | D5: =COUNTIF(D8:D660,"i")+COUNTIF(D8:D660,"p i") -> 2 | E5: =COUNTIF(E8:E660,"i")+COUNTIF(E8:E660,"p i") -> 0 | F5: =COUNTIF(A8:A660,"I") -> 2
B6: Prio | C6: =COUNTIF(C8:C660,"p")+COUNTIF(C8:C660,"p i") -> 3 | D6: =COUNTIF(D8:D660,"p")+COUNTIF(D8:D660,"p i") -> 2 | E6: =COUNTIF(E8:E660,"p")+COUNTIF(E8:E660,"p i") -> 0 | F6: =COUNTIF(A8:A660,"P") -> 3
B8: 1-1_001 | C8: C | F8: Si je ne prévois pas de clause particulière dans le marché de travaux, je devrai renouveler la DT au bout de :
C9: =IF(C8="C",IF(A9="P",IF(A8="I","p i","p"),IF(A8="I","i","")),"") | D9: =IF(D8="E",IF(A9="P",IF(A8="I","p i","p"),IF(A8="I","i"," ")),"") | E9: =IF(E8="O",IF(A9="P",IF(A8="I","p i","p"),IF(A8="I","i"," ")),"") | F9: A | G9: 1 mois
A10: R554-33I | F10: B | G10: 3 mois
F11: C | G11: 6 mois
F12: D | G12: Je ne sais pas
B14: 1-1_002 | C14: C | D14: E | F14: Qui doit établir la DT ?
A15: P | C15: =IF(C14="C",IF(A15="P",IF(A14="I","p i","p"),IF(A14="I","i","")),"") -> p | D15: =IF(D14="E",IF(A15="P",IF(A14="I","p i","p"),IF(A14="I","i"," ")),"") -> p | E15: =IF(E14="O",IF(A15="P",IF(A14="I","p i","p"),IF(A14="I","i"," ")),"") | F15: A | G15: Le responsable de projet
A16: R554-21 | F16: B | G16: L’exécutant des travaux
F17: C | G17: L’exploitant de réseau
F18: D | G18: Je ne sais pas
B20: 1-1_003 | C20: C | D20: E | F20: Qui doit envoyer la DT aux exploitants des réseaux concernés ?
C21: =IF(C20="C",IF(A21="P",IF(A20="I","p i","p"),IF(A20="I","i","")),"") | D21: =IF(D20="E",IF(A21="P",IF(A20="I","p i","p"),IF(A20="I","i"," ")),"") | E21: =IF(E20="O",IF(A21="P",IF(A20="I","p i","p"),IF(A20="I","i"," ")),"") | F21: A | G21: Le guichet unique
A22: R554-21 | F22: B | G22: Le responsable de projet
F23: C | G23: Le responsable de l'entreprise exécutant les travaux
F24: D | G24: Je ne sais pas
B26: 1-1_005 | C26: C | F26: Le responsable de projet doit inclure obligatoirement dans le dossier de consultation des entreprises :
A27: P | C27: =IF(C26="C",IF(A27="P",IF(A26="I","p i","p"),IF(A26="I","i","")),"") -> p | D27: =IF(D26="E",IF(A27="P",IF(A26="I","p i","p"),IF(A26="I","i"," ")),"") | E27: =IF(E26="O",IF(A27="P",IF(A26="I","p i","p"),IF(A26="I","i"," ")),"") | F27: A | G27: Le plan de récolement
A28: R554-23I | F28: B | G28: Les DT et leurs récépissés, ainsi que le résultat des investigations complémentaires éventuellement réalisées
F29: C | G29: Les DICT et leurs récépissés
F30: D | G30: Je ne sais pas
B32: 1-1_006 | C32: C | D32: E | F32: Parmi les travaux suivants, quels sont ceux qui répondent à la définition de "Travaux Urgents" ?
C33: =IF(C32="C",IF(A33="P",IF(A32="I","p i","p"),IF(A32="I","i","")),"") | D33: =IF(D32="E",IF(A33="P",IF(A32="I","p i","p"),IF(A32="I","i"," ")),"") | E33: =IF(E32="O",IF(A33="P",IF(A32="I","p i","p"),IF(A32="I","i"," ")),"") | F33: A | G33: Les travaux de rétablissement d'un service public après une coupure accidentelle
A34: R554-32 | F34: B | G34: Les travaux de raccordement d’une nouvelle habitation
F35: C | G35: La pose de mobiliers urbains pour une manifestation
F36: D | G36: Je ne sais pas
B38: 1-1_007 | C38: C | D38: E | F38: La procédure d'Avis de Travaux Urgents diffère notamment selon :
C39: =IF(C38="C",IF(A39="P",IF(A38="I","p i","p"),IF(A38="I","i","")),"") | D39: =IF(D38="E",IF(A39="P",IF(A38="I","p i","p"),IF(A38="I","i"," ")),"") | E39: =IF(E38="O",IF(A39="P",IF(A38="I","p i","p"),IF(A38="I","i"," ")),"") | F39: A | G39: Le délai d'intervention et le type de réseaux présents
A40: R554-32 | F40: B | G40: Le gestionnaire du lieu d'intervention
F41: C | G41: La personne qui l'envoie
F42: D | G42: Je ne sais pas
B45: 1-1_008 | C45: C | D45: E | F45: Dans lequel des cas suivants le responsable de projet est dispensé de DT ?
C46: =IF(C45="C",IF(A46="P",IF(A45="I","p i","p"),IF(A45="I","i","")),"") | D46: =IF(D45="E",IF(A46="P",IF(A45="I","p i","p"),IF(A45="I","i"," ")),"") | E46: =IF(E45="O",IF(A46="P",IF(A45="I","p i","p"),IF(A45="I","i"," ")),"") | F46: A | G46: Le reprofilage de fossés
A47: R554-1 | F47: B | G47: Les travaux agricoles ou horticoles à moins de 40 cm de profondeur
F48: C | G48: Le décapage d'une chaussée à moins de 15 cm de profondeur
F49: D | G49: Je ne sais pas
...

Sheet 1.2
A1: =Bilan!B8 -> 1.2 Analyse des réponses - IC - Cartographie
C3: C | D3: E | E3: O | F3: Total
B4: Nb quest. | C4: =COUNTIF(C8:C684,C3) -> 16 | D4: =COUNTIF(D8:D684,D3) -> 9 | E4: =COUNTIF(E8:E684,E3) -> 2 | F4: =COUNTA(B8:B684) -> 16
B5: Illust. | C5: =COUNTIF(C8:C684,"i")+COUNTIF(C8:C684,"p i") -> 2 | D5: =COUNTIF(D8:D684,"i")+COUNTIF(D8:D684,"p i") -> 2 | E5: =COUNTIF(E8:E684,"i")+COUNTIF(E8:E684,"p i") -> 2 | F5: =COUNTIF(A8:A684,"I") -> 2
B6: Prio | C6: =COUNTIF(C8:C684,"p")+COUNTIF(C8:C684,"p i") -> 1 | D6: =COUNTIF(D8:D684,"p")+COUNTIF(D8:D684,"p i") -> 0 | E6: =COUNTIF(E8:E684,"p")+COUNTIF(E8:E684,"p i") -> 0 | F6: =COUNTIF(A8:A684,"P") -> 1
B8: 1-2_001 | C8: C | F8: De combien de jours (sauf jours fériés) dispose l'exploitant pour répondre à une DT, dématérialisée (hors recours à des mesures de localisation) ?
C9: =IF(C8="C",IF(A9="P",IF(A8="I","p i","p"),IF(A8="I","i","")),"") | F9: A | G9: 7
A10: R554-22I | F10: B | G10: 9
F11: C | G11: 15
F12: D | G12: Je ne sais pas
B14: 1-2_002 | C14: C | F14: De combien de jours (sauf jours fériés) dispose l'exploitant pour répondre à une DT NON dématérialisée (envoi des formulaires par courrier) et hors recours à des mesures de localisation ?
C15: =IF(C14="C",IF(A15="P",IF(A14="I","p i","p"),IF(A14="I","i","")),"") | F15: A | G15: 7
A16: R554-22I | F16: B | G16: 9
F17: C | G17: 15
F18: E | G18: Je ne sais pas
B20: 1-2_003 | C20: C | F20: Quelle information doit obligatoirement être fournie par l'exploitant sur le récépissé de la déclaration de projet de travaux (DT) ?
C21: =IF(C20="C",IF(A21="P",IF(A20="I","p i","p"),IF(A20="I","i","")),"") | F21: A | G21: La profondeur maximale à laquelle les travaux peuvent être effectués
A22: A15-2-12/art5 | F22: B | G22: Les résultats des investigations complémentaires
F23: C | G23: La classe de précision des données de localisation des réseaux
F24: D | G24: Je ne sais pas
B26: 1-2_004 | C26: C | F26: Après réception du récépissé de déclaration de projet de travaux (DT), lorsque des investigations complémentaires sont demandées, qui doit les commander ?
A27: P | C27: =IF(C26="C",IF(A27="P",IF(A26="I","p i","p"),IF(A26="I","i","")),"") -> p | D27: =IF(D26="E",IF(A27="P",IF(A26="I","p i","p"),IF(A26="I","i"," ")),"") | F27: A | G27: Le responsable de projet
A28: A15-2-12/art7III | F28: B | G28: L'exploitant de réseau
F29: C | G29: L'exécutant des travaux
F30: D | G30: Je ne sais pas
B32: 1-2_006 | C32: C | F32: Après réception du récépissé de déclaration de projet de travaux (DT), laquelle de ces conditions permet d'être dispensé d'investigations complémentaires ?
F33: A | G33: Les travaux prévus sont des travaux sans tranchée
A34: R554-23III | F34: B | G34: La zone terrassée est supérieure à 100 m²
F35: C | G35: Les travaux prévus sont des travaux de surface ne dépassant pas 10 cm de profondeur
F36: D | G36: Je ne sais pas
B38: 1-2_007 | C38: C | F38: Pour un récolement, le responsable de projet (ou maître d'ouvrage) est dispensé de recourir à un prestataire certifié lorsque les relevés concernent un tronçon neuf :
F39: A | G39: Posé par une technique sans tranchée
A40: R554-34 | F40: B | G40: Qui sera exploité par le responsable de projet
F41: C | G41: Dont le responsable de projet confiera l’exploitation à un tiers
F42: D | G42: Je ne sais pas
B45: 1-2_009 | C45: C | D45: E | F45: Un exploitant de réseau mentionne la classe de précision C dans les plans envoyés en réponse à une DT ou une DICT. Cela signifie que l'incertitude maximale de localisation pour le réseau principal est :
C46: =IF(C45="C",IF(A46="P",IF(A45="I","p i","p"),IF(A45="I","i","")),"") | D46: =IF(D45="E",IF(A46="P",IF(A45="I","p i","p"),IF(A45="I","i"," ")),"") | F46: A | G46: Inférieure ou égale à 50 cm
A47: A15-2-12/art1-3° | F47: B | G47: Inférieure ou égale à 1,5 m
F48: C | G48: Supérieure à 1,5 m
F49: D | G49: Je ne sais pas
...

Sheet 1.3
A1: =Bilan!B9 -> 1.3 Clauses dans les marchés et DCE
C3: C | D3: E | E3: O | F3: Total
B4: Nb quest. | C4: =COUNTIF(C8:C623,C3) -> 4 | D4: =COUNTIF(D8:D623,D3) -> 2 | E4: =COUNTIF(E8:E623,E3) -> 0 | F4: =COUNTA(B8:B623) -> 4
B5: Illust. | C5: =COUNTIF(C8:C623,"i")+COUNTIF(C8:C623,"p i") -> 0 | D5: =COUNTIF(D8:D623,"i")+COUNTIF(D8:D623,"p i") -> 0 | E5: =COUNTIF(E8:E623,"i")+COUNTIF(E8:E623,"p i") -> 0 | F5: =COUNTIF(A8:A623,"I") -> 0
B6: Prio | C6: =COUNTIF(C8:C623,"p")+COUNTIF(C8:C623,"p i") -> 0 | D6: =COUNTIF(D8:D623,"p")+COUNTIF(D8:D623,"p i") -> 0 | E6: =COUNTIF(E8:E623,"p")+COUNTIF(E8:E623,"p i") -> 0 | F6: =COUNTIF(A8:A623,"P") -> 0
B8: 1-3_001 | C8: C | D8: E | F8: Si le marché de travaux ne prévoit pas de clauses spécifiques, la DT :
A9: R554-22V | F9: A | G9: Reste valide sans limite de temps
F10: B | G10: Est seulement valide 3 mois
F11: C | G11: Est seulement valide 6 mois
F12: D | G12: Je ne sais pas
B14: 1-3_003 | C14: C | D14: E | F14: Dans le cas où un exploitant de réseau sensible ne répond pas dans le délai réglementaire à la DICT et à sa relance, l'exécutant :
C15: =IF(C14="C",IF(A15="P",IF(A14="I","p i","p"),IF(A14="I","i","")),"") | D15: =IF(D14="E",IF(A15="P",IF(A14="I","p i","p"),IF(A14="I","i"," ")),"") | E15: =IF(E14="O",IF(A15="P",IF(A14="I","p i","p"),IF(A14="I","i"," ")),"") | F15: A | G15: Ne démarre pas les travaux et ne subit pas de préjudice lié au report
A16: R554-26VI | F16: B | G16: Démarre les travaux après un délai complémentaire de 9 jours
F17: C | G17: Démarre les travaux en prenant les précautions particulières prévues par le guide technique
F18: D | G18: Je ne sais pas
B21: 1-3_011 | C21: C | F21: En cas de travaux dispensés d'investigations complémentaires, le responsable de projet doit prévoir des clauses techniques et financières dans le marché, s'il n'effectue pas d'opérations de localisation, lorsque les réseaux situés dans l'emprise du projet sont :
C22: =IF(C21="C",IF(A22="P",IF(A21="I","p i","p"),IF(A21="I","i","")),"") | D22: =IF(D21="E",IF(A22="P",IF(A21="I","p i","p"),IF(A21="I","i"," ")),"") | E22: =IF(E21="O",IF(A22="P",IF(A21="I","p i","p"),IF(A21="I","i"," ")),"") | F22: A | G22: En classe de précision A
A23: R554-23 | F23: B | G23: En classe de précision B ou C
F24: C | G24: En arrêt définitif d'exploitation
F25: D | G25: Je ne sais pas
B27: 1-3_012 | C27: C | F27: Le responsable de projet doit prévoir des clauses techniques et financières dans le marché lorsque des réseaux situés dans l'emprise du projet sont en classe de précision B ou C et sont :
C28: =IF(C27="C",IF(A28="P",IF(A27="I","p i","p"),IF(A27="I","i","")),"") | D28: =IF(D27="E",IF(A28="P",IF(A27="I","p i","p"),IF(A27="I","i"," ")),"") | E28: =IF(E27="O",IF(A28="P",IF(A27="I","p i","p"),IF(A27="I","i"," ")),"") | F28: A | G28: Uniquement des réseaux sensibles
A29: R554-23 | F29: B | G29: Uniquement des réseaux non sensibles
F30: C | G30: Des réseaux sensibles ou non sensibles
F31: D | G31: Je ne sais pas
C70: =IF(C69="C",IF(A70="P",IF(A69="I","p i","p"),IF(A69="I","i","")),"") | D70: =IF(D69="E",IF(A70="P",IF(A69="I","p i","p"),IF(A69="I","i"," ")),"") | E70: =IF(E69="O",IF(A70="P",IF(A69="I","p i","p"),IF(A69="I","i"," ")),"")
C77: =IF(C76="C",IF(A77="P",IF(A76="I","p i","p"),IF(A76="I","i","")),"") | D77: =IF(D76="E",IF(A77="P",IF(A76="I","p i","p"),IF(A76="I","i"," ")),"") | E77: =IF(E76="O",IF(A77="P",IF(A76="I","p i","p"),IF(A76="I","i"," ")),"")
C84: =IF(C83="C",IF(A84="P",IF(A83="I","p i","p"),IF(A83="I","i","")),"") | D84: =IF(D83="E",IF(A84="P",IF(A83="I","p i","p"),IF(A83="I","i"," ")),"") | E84: =IF(E83="O",IF(A84="P",IF(A83="I","p i","p"),IF(A83="I","i"," ")),"")
C91: =IF(C90="C",IF(A91="P",IF(A90="I","p i","p"),IF(A90="I","i","")),"") | D91: =IF(D90="E",IF(A91="P",IF(A90="I","p i","p"),IF(A90="I","i"," ")),"") | E91: =IF(E90="O",IF(A91="P",IF(A90="I","p i","p"),IF(A90="I","i"," ")),"")
C98: =IF(C97="C",IF(A98="P",IF(A97="I","p i","p"),IF(A97="I","i","")),"") | D98: =IF(D97="E",IF(A98="P",IF(A97="I","p i","p"),IF(A97="I","i"," ")),"") | E98: =IF(E97="O",IF(A98="P",IF(A97="I","p i","p"),IF(A97="I","i"," ")),"")
C105: =IF(C104="C",IF(A105="P",IF(A104="I","p i","p"),IF(A104="I","i","")),"") | D105: =IF(D104="E",IF(A105="P",IF(A104="I","p i","p"),IF(A104="I","i"," ")),"") | E105: =IF(E104="O",IF(A105="P",IF(A104="I","p i","p"),IF(A104="I","i"," ")),"")
C112: =IF(C111="C",IF(A112="P",IF(A111="I","p i","p"),IF(A111="I","i","")),"") | D112: =IF(D111="E",IF(A112="P",IF(A111="I","p i","p"),IF(A111="I","i"," ")),"") | E112: =IF(E111="O",IF(A112="P",IF(A111="I","p i","p"),IF(A111="I","i"," ")),"")
C119: =IF(C118="C",IF(A119="P",IF(A118="I","p i","p"),IF(A118="I","i","")),"") | D119: =IF(D118="E",IF(A119="P",IF(A118="I","p i","p"),IF(A118="I","i"," ")),"") | E119: =IF(E118="O",IF(A119="P",IF(A118="I","p i","p"),IF(A118="I","i"," ")),"")
C126: =IF(C125="C",IF(A126="P",IF(A125="I","p i","p"),IF(A125="I","i","")),"") | D126: =IF(D125="E",IF(A126="P",IF(A125="I","p i","p"),IF(A125="I","i"," ")),"") | E126: =IF(E125="O",IF(A126="P",IF(A125="I","p i","p"),IF(A125="I","i"," ")),"")
C133: =IF(C132="C",IF(A133="P",IF(A132="I","p i","p"),IF(A132="I","i","")),"") | D133: =IF(D132="E",IF(A133="P",IF(A132="I","p i","p"),IF(A132="I","i"," ")),"") | E133: =IF(E132="O",IF(A133="P",IF(A132="I","p i","p"),IF(A132="I","i"," ")),"")
C140: =IF(C139="C",IF(A140="P",IF(A139="I","p i","p"),IF(A139="I","i","")),"") | D140: =IF(D139="E",IF(A140="P",IF(A139="I","p i","p"),IF(A139="I","i"," ")),"") | E140: =IF(E139="O",IF(A140="P",IF(A139="I","p i","p"),IF(A139="I","i"," ")),"")
C147: =IF(C146="C",IF(A147="P",IF(A146="I","p i","p"),IF(A146="I","i","")),"") | D147: =IF(D146="E",IF(A147="P",IF(A146="I","p i","p"),IF(A146="I","i"," ")),"") | E147: =IF(E146="O",IF(A147="P",IF(A146="I","p i","p"),IF(A146="I","i"," ")),"")
C154: =IF(C153="C",IF(A154="P",IF(A153="I","p i","p"),IF(A153="I","i","")),"") | D154: =IF(D153="E",IF(A154="P",IF(A153="I","p i","p"),IF(A153="I","i"," ")),"") | E154: =IF(E153="O",IF(A154="P",IF(A153="I","p i","p"),IF(A153="I","i"," ")),"")
C155: =IF(C154="C",IF(A155="Prioritaire",IF(A154="I","p i","p"),IF(A154="I","i","")),"") | D155: =IF(D154="E",IF(A155="Prioritaire",IF(A154="I","p i","p"),IF(A154="I","i"," ")),"") | E155: =IF(E154="O",IF(A155="Prioritaire",IF(A154="I","p i","p"),IF(A154="I","i"," ")),"")
C161: =IF(C160="C",IF(A161="P",IF(A160="I","p i","p"),IF(A160="I","i","")),"") | D161: =IF(D160="E",IF(A161="P",IF(A160="I","p i","p"),IF(A160="I","i"," ")),"") | E161: =IF(E160="O",IF(A161="P",IF(A160="I","p i","p"),IF(A160="I","i"," ")),"")
...

Sheet 1.4
A1: =Bilan!B10 -> 1.4 Marquage - Piquetage
C3: C | D3: E | E3: O | F3: Total
B4: Nb quest. | C4: =COUNTIF(C8:C646,C3) -> 7 | D4: =COUNTIF(D8:D646,D3) -> 7 | E4: =COUNTIF(E8:E646,E3) -> 4 | F4: =COUNTA(B8:B646) -> 8
B5: Illust. | C5: =COUNTIF(C8:C646,"i")+COUNTIF(C8:C646,"p i") -> 3 | D5: =COUNTIF(D8:D646,"i")+COUNTIF(D8:D646,"p i") -> 3 | E5: =COUNTIF(E8:E646,"i")+COUNTIF(E8:E646,"p i") -> 4 | F5: =COUNTIF(A8:A646,"I") -> 4
B6: Prio | C6: =COUNTIF(C8:C646,"p")+COUNTIF(C8:C646,"p i") -> 1 | D6: =COUNTIF(D8:D646,"p")+COUNTIF(D8:D646,"p i") -> 1 | E6: =COUNTIF(E8:E646,"p")+COUNTIF(E8:E646,"p i") -> 0 | F6: =COUNTIF(A8:A646,"P") -> 1
B8: 1-4_001 | C8: C | D8: E | F8: Lorsque l’exploitant de réseau ne fournit pas de plan en réponse à la DICT, qui a la responsabilité du marquage-piquetage dans le cadre d'une réunion sur site ?
C9: =IF(C8="C",IF(A9="P",IF(A8="I","p i","p"),IF(A8="I","i","")),"") | D9: =IF(D8="E",IF(A9="P",IF(A8="I","p i","p"),IF(A8="I","i"," ")),"") | E9: =IF(E8="O",IF(A9="P",IF(A8="I","p i","p"),IF(A8="I","i"," ")),"") | F9: A | G9: L’entreprise de travaux
A10: R554-27III | F10: B | G10: Le responsable du projet (ou maître d'ouvrage)
F11: C | G11: L’exploitant du réseau
F12: D | G12: Je ne sais pas
B14: 1-4_002 | C14: C | D14: E | F14: Lorsque l’exploitant a joint un plan au récépissé de DICT, qui a la responsabilité d'effectuer le marquage-piquetage ? | Q14: Prioritaire
A15: P | C15: =IF(C14="C",IF(A15="P",IF(A14="I","p i","p"),IF(A14="I","i","")),"") -> p | D15: =IF(D14="E",IF(A15="P",IF(A14="I","p i","p"),IF(A14="I","i"," ")),"") -> p | E15: =IF(E14="O",IF(A15="P",IF(A14="I","p i","p"),IF(A14="I","i"," ")),"") | F15: A | G15: L’entreprise de travaux
A16: R554-27I | F16: B | G16: Le responsable du projet (ou maître d'ouvrage)
F17: C | G17: L’exploitant
F18: E | G18: Je ne sais pas
B20: 1-4_004 | C20: C | D20: E | F20: Pourquoi le compte rendu de marquage-piquetage doit être transmis à l’exécutant des travaux ?
F21: A | G21: Pour assurer la traçabilité des informations de localisation des réseaux existants
A22: R554-27 | F22: B | G22: Pour permettre à l'exécutant de produire un plan projet du réseau neuf à poser
F23: C | G23: Pour transférer à l'exécutant toute la responsabilité des travaux réalisés
F24: D | G24: Je ne sais pas
B27: 1-4_005 | C27: C | D27: E | F27: Le marquage piquetage doit être effectué pour tout réseau situé dans l'emprise des travaux augmentée de :
C28: =IF(C27="C",IF(A28="P",IF(A27="I","p i","p"),IF(A27="I","i","")),"") | D28: =IF(D27="E",IF(A28="P",IF(A27="I","p i","p"),IF(A27="I","i"," ")),"") | E28: =IF(E27="O",IF(A28="P",IF(A27="I","p i","p"),IF(A27="I","i"," ")),"") | F28: A | G28: 1,5 mètres
A29: R554-27I | F29: B | G29: 2 mètres
F30: C | G30: 3 mètres
F31: D | G31: Je ne sais pas
A33: I | B33: 1-4_006 | C33: C | D33: E | E33: O | F33: Qui doit maintenir en état le marquage piquetage pendant toute la durée des travaux ?
C34: =IF(C33="C",IF(A34="P",IF(A33="I","p i","p"),IF(A33="I","i","")),"") -> i | D34: =IF(D33="E",IF(A34="P",IF(A33="I","p i","p"),IF(A33="I","i"," ")),"") -> i | E34: =IF(E33="O",IF(A34="P",IF(A33="I","p i","p"),IF(A33="I","i"," ")),"") -> i | F34: A | G34: Le service technique de la commune
A35: R554-27IV | F35: B | G35: L’exploitant du réseau
F36: C | G36: L'exécutant des travaux
F37: D | G37: Je ne sais pas
A39: I | B39: 1-4_006b | E39: O | F39: Pendant combien de temps faut-il maintenir en bon état le marquage piquetage ?
C40: =IF(C39="C",IF(A40="P",IF(A39="I","p i","p"),IF(A39="I","i","")),"") | D40: =IF(D39="E",IF(A40="P",IF(A39="I","p i","p"),IF(A39="I","i"," ")),"") | E40: =IF(E39="O",IF(A40="P",IF(A39="I","p i","p"),IF(A39="I","i"," ")),"") -> i | F40: A | G40: Jusqu'à l'enlèvement de la couche dure de la chaussée
A41: R554-27IV | F41: B | G41: Jusqu'à la fin du terrassement avec les engins lourds
F42: C | G42: Pendant toute la durée du chantier
F43: D | G43: Je ne sais pas
A45: I | B45: 1-4_007 | C45: C | D45: E | E45: O | F45: Sur un chantier, un marquage au sol de couleur jaune signale un réseau :
C46: =IF(C45="C",IF(A46="P",IF(A45="I","p i","p"),IF(A45="I","i","")),"") -> i | D46: =IF(D45="E",IF(A46="P",IF(A45="I","p i","p"),IF(A45="I","i"," ")),"") -> i | E46: =IF(E45="O",IF(A46="P",IF(A45="I","p i","p"),IF(A45="I","i"," ")),"") -> i | F46: A | G46: D'eaux usées
A47: NF S 70-003-1 | F47: B | G47: De gaz
A48: annexe E | F48: C | G48: De télécommunication
F49: D | G49: Je ne sais pas
...

Sheet 1.5
A1: =Bilan!B11 -> 1.5 Compétences des personnels
C3: C | D3: E | E3: O | F3: Total
B4: Nb quest. | C4: =COUNTIF(C14:C624,C3) -> 2 | D4: =COUNTIF(D14:D624,D3) -> 0 | E4: =COUNTIF(E14:E624,E3) -> 0 | F4: =COUNTA(B14:B624) -> 2
B5: Illust. | C5: =COUNTIF(C14:C624,"i")+COUNTIF(C14:C624,"p i") -> 0 | D5: =COUNTIF(D14:D624,"i")+COUNTIF(D14:D624,"p i") -> 0 | E5: =COUNTIF(E14:E624,"i")+COUNTIF(E14:E624,"p i") -> 0 | F5: =COUNTIF(A14:A624,"I") -> 0
B6: Prio | C6: =COUNTIF(C14:C624,"p")+COUNTIF(C14:C624,"p i") -> 0 | D6: =COUNTIF(D14:D624,"p")+COUNTIF(D14:D624,"p i") -> 0 | E6: =COUNTIF(E14:E624,"p")+COUNTIF(E14:E624,"p i") -> 0 | F6: =COUNTIF(A14:A624,"P") -> 0
B8: 1-5_001 | C8: C | D8: E | F8: Lequel de ces éléments ne permet pas la délivrance de l'Autorisation d'Intervention à Proximité des Réseaux ?
F9: A | G9: Un diplôme obtenu depuis plus de 5 ans
A10: A15-2-12/art21I-3° | F10: B | G10: Une attestation de compétences en cours de validité
F11: C | G11: Un CACES en cours de validité prenant en compte la réforme anti-endommagement
F12: D | G12: Je ne sais pas
B14: 1-5_002 | C14: C | F14: Un responsable de projet (ou maître d'ouvrage) prévoit de faire intervenir plusieurs entreprises sur un même chantier de travaux. L'autorisation d'intervention à proximité des réseaux (AIPR) niveau concepteur est requise pour au moins :
C15: =IF(C14="C",IF(A15="P",IF(A14="I","p i","p"),IF(A14="I","i","")),"") | D15: =IF(D14="E",IF(A15="P",IF(A14="I","p i","p"),IF(A14="I","i"," ")),"") | E15: =IF(E14="O",IF(A15="P",IF(A14="I","p i","p"),IF(A14="I","i"," ")),"") | F15: A | G15: Une personne chargée par le responsable de projet (ou maître d'ouvrage) de préparer et suivre le projet de travaux
A16: A15-2-12/art21I | F16: B | G16: Deux personnes chargées par le responsable de projet (ou maître d'ouvrage) de préparer et suivre le projet de travaux
F17: C | G17: L'ensemble des personnes chargées par le responsable de projet (ou maître d'ouvrage) de préparer et suivre le projet de travaux
F18: D | G18: Je ne sais pas
B21: 1-5_011 | C21: C | F21: L'exploitant de réseau doit-il prévoir, pour au moins une personne travaillant pour son compte, une AIPR "concepteur" ?
C22: =IF(C21="C",IF(A22="P",IF(A21="I","p i","p"),IF(A21="I","i","")),"") | D22: =IF(D21="E",IF(A22="P",IF(A21="I","p i","p"),IF(A21="I","i"," ")),"") | E22: =IF(E21="O",IF(A22="P",IF(A21="I","p i","p"),IF(A21="I","i"," ")),"") | F22: A | G22: Jamais
A23: A15-2-12/art21I | F23: B | G23: Toujours, pour répondre aux DICT qu'il reçoit
F24: C | G24: Uniquement lorsqu'il intervient comme responsable de projet de travaux
F25: D | G25: Je ne sais pas
C36: =IF(C35="C",IF(A36="P",IF(A35="I","p i","p"),IF(A35="I","i","")),"") | D36: =IF(D35="E",IF(A36="P",IF(A35="I","p i","p"),IF(A35="I","i"," ")),"") | E36: =IF(E35="O",IF(A36="P",IF(A35="I","p i","p"),IF(A35="I","i"," ")),"")
C43: =IF(C42="C",IF(A43="P",IF(A42="I","p i","p"),IF(A42="I","i","")),"") | D43: =IF(D42="E",IF(A43="P",IF(A42="I","p i","p"),IF(A42="I","i"," ")),"") | E43: =IF(E42="O",IF(A43="P",IF(A42="I","p i","p"),IF(A42="I","i"," ")),"")
C50: =IF(C49="C",IF(A50="P",IF(A49="I","p i","p"),IF(A49="I","i","")),"") | D50: =IF(D49="E",IF(A50="P",IF(A49="I","p i","p"),IF(A49="I","i"," ")),"") | E50: =IF(E49="O",IF(A50="P",IF(A49="I","p i","p"),IF(A49="I","i"," ")),"")
C57: =IF(C56="C",IF(A57="P",IF(A56="I","p i","p"),IF(A56="I","i","")),"") | D57: =IF(D56="E",IF(A57="P",IF(A56="I","p i","p"),IF(A56="I","i"," ")),"") | E57: =IF(E56="O",IF(A57="P",IF(A56="I","p i","p"),IF(A56="I","i"," ")),"")
C64: =IF(C63="C",IF(A64="P",IF(A63="I","p i","p"),IF(A63="I","i","")),"") | D64: =IF(D63="E",IF(A64="P",IF(A63="I","p i","p"),IF(A63="I","i"," ")),"") | E64: =IF(E63="O",IF(A64="P",IF(A63="I","p i","p"),IF(A63="I","i"," ")),"")
C71: =IF(C70="C",IF(A71="P",IF(A70="I","p i","p"),IF(A70="I","i","")),"") | D71: =IF(D70="E",IF(A71="P",IF(A70="I","p i","p"),IF(A70="I","i"," ")),"") | E71: =IF(E70="O",IF(A71="P",IF(A70="I","p i","p"),IF(A70="I","i"," ")),"")
C78: =IF(C77="C",IF(A78="P",IF(A77="I","p i","p"),IF(A77="I","i","")),"") | D78: =IF(D77="E",IF(A78="P",IF(A77="I","p i","p"),IF(A77="I","i"," ")),"") | E78: =IF(E77="O",IF(A78="P",IF(A77="I","p i","p"),IF(A77="I","i"," ")),"")
C85: =IF(C84="C",IF(A85="P",IF(A84="I","p i","p"),IF(A84="I","i","")),"") | D85: =IF(D84="E",IF(A85="P",IF(A84="I","p i","p"),IF(A84="I","i"," ")),"") | E85: =IF(E84="O",IF(A85="P",IF(A84="I","p i","p"),IF(A84="I","i"," ")),"")
C92: =IF(C91="C",IF(A92="P",IF(A91="I","p i","p"),IF(A91="I","i","")),"") | D92: =IF(D91="E",IF(A92="P",IF(A91="I","p i","p"),IF(A91="I","i"," ")),"") | E92: =IF(E91="O",IF(A92="P",IF(A91="I","p i","p"),IF(A91="I","i"," ")),"")
C99: =IF(C98="C",IF(A99="P",IF(A98="I","p i","p"),IF(A98="I","i","")),"") | D99: =IF(D98="E",IF(A99="P",IF(A98="I","p i","p"),IF(A98="I","i"," ")),"") | E99: =IF(E98="O",IF(A99="P",IF(A98="I","p i","p"),IF(A98="I","i"," ")),"")
C106: =IF(C105="C",IF(A106="P",IF(A105="I","p i","p"),IF(A105="I","i","")),"") | D106: =IF(D105="E",IF(A106="P",IF(A105="I","p i","p"),IF(A105="I","i"," ")),"") | E106: =IF(E105="O",IF(A106="P",IF(A105="I","p i","p"),IF(A105="I","i"," ")),"")
C113: =IF(C112="C",IF(A113="P",IF(A112="I","p i","p"),IF(A112="I","i","")),"") | D113: =IF(D112="E",IF(A113="P",IF(A112="I","p i","p"),IF(A112="I","i"," ")),"") | E113: =IF(E112="O",IF(A113="P",IF(A112="I","p i","p"),IF(A112="I","i"," ")),"")
... C155: =IF(C154="C",IF(A155="P",IF(A154="I","p i","p"),IF(A154="I","i","")),"") | D155: =IF(D154="E",IF(A155="P",IF(A154="I","p i","p"),IF(A154="I","i"," ")),"") | E155: =IF(E154="O",IF(A155="P",IF(A154="I","p i","p"),IF(A154="I","i"," ")),"")
C156: =IF(C155="C",IF(A156="Prioritaire",IF(A155="I","p i","p"),IF(A155="I","i","")),"") | D156: =IF(D155="E",IF(A156="Prioritaire",IF(A155="I","p i","p"),IF(A155="I","i"," ")),"") | E156: =IF(E155="O",IF(A156="Prioritaire",IF(A155="I","p i","p"),IF(A155="I","i"," ")),"")
C162: =IF(C161="C",IF(A162="P",IF(A161="I","p i","p"),IF(A161="I","i","")),"") | D162: =IF(D161="E",IF(A162="P",IF(A161="I","p i","p"),IF(A161="I","i"," ")),"") | E162: =IF(E161="O",IF(A162="P",IF(A161="I","p i","p"),IF(A161="I","i"," ")),"")
C169: =IF(C168="C",IF(A169="P",IF(A168="I","p i","p"),IF(A168="I","i","")),"") | D169: =IF(D168="E",IF(A169="P",IF(A168="I","p i","p"),IF(A168="I","i"," ")),"") | E169: =IF(E168="O",IF(A169="P",IF(A168="I","p i","p"),IF(A168="I","i"," ")),"")
C176: =IF(C175="C",IF(A176="P",IF(A175="I","p i","p"),IF(A175="I","i","")),"") | D176: =IF(D175="E",IF(A176="P",IF(A175="I","p i","p"),IF(A175="I","i"," ")),"") | E176: =IF(E175="O",IF(A176="P",IF(A175="I","p i","p"),IF(A175="I","i"," ")),"")
C183: =IF(C182="C",IF(A183="P",IF(A182="I","p i","p"),IF(A182="I","i","")),"") | D183: =IF(D182="E",IF(A183="P",IF(A182="I","p i","p"),IF(A182="I","i"," ")),"") | E183: =IF(E182="O",IF(A183="P",IF(A182="I","p i","p"),IF(A182="I","i"," ")),"")
C190: =IF(C189="C",IF(A190="P",IF(A189="I","p i","p"),IF(A189="I","i","")),"") | D190: =IF(D189="E",IF(A190="P",IF(A189="I","p i","p"),IF(A189="I","i"," ")),"") | E190: =IF(E189="O",IF(A190="P",IF(A189="I","p i","p"),IF(A189="I","i"," ")),"")
C197: =IF(C196="C",IF(A197="P",IF(A196="I","p i","p"),IF(A196="I","i","")),"") | D197: =IF(D196="E",IF(A197="P",IF(A196="I","p i","p"),IF(A196="I","i"," ")),"") | E197: =IF(E196="O",IF(A197="P",IF(A196="I","p i","p"),IF(A196="I","i"," ")),"")
...

Sheet 1.6
A1: =Bilan!B12 -> 1.6 Cartographie
C3: C | D3: E | E3: O | F3: Total
B4: Nb quest. | C4: =COUNTIF(C8:C545,C3) -> 8 | D4: =COUNTIF(D8:D545,D3) -> 8 | E4: =COUNTIF(E8:E545,E3) -> 1 | F4: =COUNTA(B8:B545) -> 9
B5: Illust. | C5: =COUNTIF(C8:C545,"i")+COUNTIF(C8:C545,"p i") -> 1 | D5: =COUNTIF(D8:D545,"i")+COUNTIF(D8:D545,"p i") -> 1 | E5: =COUNTIF(E8:E545,"i")+COUNTIF(E8:E545,"p i") -> 1 | F5: =COUNTIF(A8:A545,"I") -> 2
B6: Prio | C6: =COUNTIF(C8:C545,"p")+COUNTIF(C8:C545,"p i") -> 1 | D6: =COUNTIF(D8:D545,"p")+COUNTIF(D8:D545,"p i") -> 1 | E6: =COUNTIF(E8:E545,"p")+COUNTIF(E8:E545,"p i") -> 0 | F6: =COUNTIF(A8:A545,"P") -> 1
B8: 1-6_001 | C8: C | D8: E | F8: En matière de cartographie, laquelle de ces affirmations est exacte ?
C9: =IF(C8="C",IF(A9="P",IF(A8="I","p i","p"),IF(A8="I","i","")),"") | D9: =IF(D8="E",IF(A9="P",IF(A8="I","p i","p"),IF(A8="I","i"," ")),"") | E9: =IF(E8="O",IF(A9="P",IF(A8="I","p i","p"),IF(A8="I","i"," ")),"") | F9: A | G9: La classe de précision figure dans le récépissé de l’exploitant à une DT ou DICT
A10: A15-2-12/art5 | F10: B | G10: Tous les branchements gaz sont reportés sur la cartographie
F11: C | G11: Les indications quant à la position des ouvrages enterrés figurant sur les plans sont précises à plus ou moins 40 cm
F12: D | G12: Je ne sais pas
B14: 1-6_003 | C14: C | D14: E | F14: En topographie, le terme planimétrie se rapporte à la localisation d'un point :
C15: =IF(C14="C",IF(A15="P",IF(A14="I","p i","p"),IF(A14="I","i","")),"") | D15: =IF(D14="E",IF(A15="P",IF(A14="I","p i","p"),IF(A14="I","i"," ")),"") | E15: =IF(E14="O",IF(A15="P",IF(A14="I","p i","p"),IF(A14="I","i"," ")),"") | F15: A | G15: A l'horizontale
A16: NFS70-003-3 | F16: B | G16: A la verticale
F17: C | G17: Sur une droite
F18: D | G18: Je ne sais pas
B20: 1-6_004 | C20: C | D20: E | F20: La génératrice supérieure d'un réseau enterré est :
C21: =IF(C20="C",IF(A21="P",IF(A20="I","p i","p"),IF(A20="I","i","")),"") | D21: =IF(D20="E",IF(A21="P",IF(A20="I","p i","p"),IF(A20="I","i"," ")),"") | E21: =IF(E20="O",IF(A21="P",IF(A20="I","p i","p"),IF(A20="I","i"," ")),"") | F21: A | G21: Le point le plus haut de la paroi extérieure de ce réseau ou de son fourreau
A22: A15-2-12/art15 | F22: B | G22: Le fil d'eau de ce réseau ou de son fourreau
F23: C | G23: L'axe central de ce réseau ou de son fourreau
F24: D | G24: Je ne sais pas
B27: 1-6_011 | C27: C | D27: E | F27: L'échelle d'un plan est :
C28: =IF(C27="C",IF(A28="P",IF(A27="I","p i","p"),IF(A27="I","i","")),"") | D28: =IF(D27="E",IF(A28="P",IF(A27="I","p i","p"),IF(A27="I","i"," ")),"") | E28: =IF(E27="O",IF(A28="P",IF(A27="I","p i","p"),IF(A27="I","i"," ")),"") | F28: A | G28: Le rapport entre la longueur réelle d'un objet sur le terrain et la longueur de cet objet sur le plan
A29: NFS70-003-3 | F29: B | G29: La précision du plan
F30: C | G30: Le rapport entre la longueur d'un objet sur le plan et la longueur réelle de cet objet sur le terrain
F31: D | G31: Je ne sais pas
A33: I | B33: 1-6_016ce | C33: C | D33: E | F33: Lorsque la profondeur d'un réseau est marquée au sol, elle indique la profondeur :
A34: P | C34: =IF(C33="C",IF(A34="P",IF(A33="I","p i","p"),IF(A33="I","i","")),"") -> p i | D34: =IF(D33="E",IF(A34="P",IF(A33="I","p i","p"),IF(A33="I","i"," ")),"") -> p i | E34: =IF(E33="O",IF(A34="P",IF(A33="I","p i","p"),IF(A33="I","i"," ")),"") | F34: A | G34: Du fil de l'eau du réseau ou de son fourreau
A35: NFS70-003-3 | F35: B | G35: De la génératrice supérieure du réseau ou de son fourreau
F36: C | G36: Du grillage avertisseur du réseau
F37: D | G37: Je ne sais pas
A39: I | B39: 1-6_016o | E39: O | F39: Lorsque la profondeur d'un réseau est marquée au sol, elle indique la profondeur :
C40: =IF(C39="C",IF(A40="P",IF(A39="I","p i","p"),IF(A39="I","i","")),"") | D40: =IF(D39="E",IF(A40="P",IF(A39="I","p i","p"),IF(A39="I","i"," ")),"") | E40: =IF(E39="O",IF(A40="P",IF(A39="I","p i","p"),IF(A39="I","i"," ")),"") -> i | F40: A | G40: Du fond de fouille (sous le tuyau)
A41: NFS70-003-3 | F41: B | G41: De la génératrice supérieure du réseau (au dessus du tuyau)
F42: C | G42: Du grillage avertisseur du réseau
F43: D | G43: Je ne sais pas
B45: 1-6_018 | C45: C | D45: E | F45: Pour une échelle de plan au 1/200, 20 mètres sur le terrain correspondent sur le plan à :
F46: A | G46: 2 cm
A47: NFS70-003-3 | F47: B | G47: 10 cm
F48: C | G48: 20 cm
F49: D | G49: Je ne sais pas
...

Sheet 2.1
A1: =Bilan!B14 -> 2.1 DICT
C3: C | D3: E | E3: O | F3: Total
B4: Nb quest. | C4: =COUNTIF(C8:C629,C3) -> 3 | D4: =COUNTIF(D8:D629,D3) -> 3 | E4: =COUNTIF(E8:E629,E3) -> 0 | F4: =COUNTA(B8:B629) -> 3
B5: Illust. | C5: =COUNTIF(C8:C629,"i")+COUNTIF(C8:C629,"p i") -> 0 | D5: =COUNTIF(D8:D629,"i")+COUNTIF(D8:D629,"p i") -> 0 | E5: =COUNTIF(E8:E629,"i")+COUNTIF(E8:E629,"p i") -> 0 | F5: =COUNTIF(A8:A629,"I") -> 0
B6: Prio | C6: =COUNTIF(C8:C629,"p")+COUNTIF(C8:C629,"p i") -> 1 | D6: =COUNTIF(D8:D629,"p")+COUNTIF(D8:D629,"p i") -> 1 | E6: =COUNTIF(E8:E629,"p")+COUNTIF(E8:E629,"p i") -> 0 | F6: =COUNTIF(A8:A629,"P") -> 1
B8: 2-1_004 | C8: C | D8: E | F8: Qui doit établir la DICT ?
A9: P | C9: =IF(C8="C",IF(A9="P",IF(A8="I","p i","p"),IF(A8="I","i","")),"") -> p | D9: =IF(D8="E",IF(A9="P",IF(A8="I","p i","p"),IF(A8="I","i"," ")),"") -> p | E9: =IF(E8="O",IF(A9="P",IF(A8="I","p i","p"),IF(A8="I","i"," ")),"") | F9: A | G9: Le maître d’ouvrage
A10: R554-25I | F10: B | G10: L’exécutant des travaux
F11: C | G11: L’exploitant de réseau
F12: D | G12: Je ne sais pas
B14: 2-1_005 | C14: C | D14: E | F14: Qui doit envoyer la DICT aux exploitants d'ouvrages ?
F15: A | G15: L'exécutant des travaux ou son Prestataire d'Aide à la Déclaration
A16: R554-25I | F16: B | G16: Le téléservice du guichet unique
F17: C | G17: Le responsable de projet ou son Prestataire d'Aide à la Déclaration
F18: D | G18: Je ne sais pas
B20: 2-1_008 | C20: C | D20: E | F20: Je dois réaliser des travaux à l'aplomb d'une ligne aérienne et je dois prendre en compte la hauteur des conducteurs. Que faire ?
C21: =IF(C20="C",IF(A21="P",IF(A20="I","p i","p"),IF(A20="I","i","")),"") | D21: =IF(D20="E",IF(A21="P",IF(A20="I","p i","p"),IF(A20="I","i"," ")),"") | E21: =IF(E20="O",IF(A21="P",IF(A20="I","p i","p"),IF(A20="I","i"," ")),"") | F21: A | G21: Je me réfère au récépissé de DICT et au guide technique
A22: R554-25 | F22: B | G22: Je vérifie visuellement que la hauteur de surplomb est suffisante
F23: C | G23: J'utilise une perche graduée isolante pour mesurer la hauteur de la ligne
F24: D | G24: Je ne sais pas
C83: =IF(C82="C",IF(A83="P",IF(A82="I","p i","p"),IF(A82="I","i","")),"") | D83: =IF(D82="E",IF(A83="P",IF(A82="I","p i","p"),IF(A82="I","i"," ")),"") | E83: =IF(E82="O",IF(A83="P",IF(A82="I","p i","p"),IF(A82="I","i"," ")),"")
C90: =IF(C89="C",IF(A90="P",IF(A89="I","p i","p"),IF(A89="I","i","")),"") | D90: =IF(D89="E",IF(A90="P",IF(A89="I","p i","p"),IF(A89="I","i"," ")),"") | E90: =IF(E89="O",IF(A90="P",IF(A89="I","p i","p"),IF(A89="I","i"," ")),"")
C97: =IF(C96="C",IF(A97="P",IF(A96="I","p i","p"),IF(A96="I","i","")),"") | D97: =IF(D96="E",IF(A97="P",IF(A96="I","p i","p"),IF(A96="I","i"," ")),"") | E97: =IF(E96="O",IF(A97="P",IF(A96="I","p i","p"),IF(A96="I","i"," ")),"")
C104: =IF(C103="C",IF(A104="P",IF(A103="I","p i","p"),IF(A103="I","i","")),"") | D104: =IF(D103="E",IF(A104="P",IF(A103="I","p i","p"),IF(A103="I","i"," ")),"") | E104: =IF(E103="O",IF(A104="P",IF(A103="I","p i","p"),IF(A103="I","i"," ")),"")
C111: =IF(C110="C",IF(A111="P",IF(A110="I","p i","p"),IF(A110="I","i","")),"") | D111: =IF(D110="E",IF(A111="P",IF(A110="I","p i","p"),IF(A110="I","i"," ")),"") | E111: =IF(E110="O",IF(A111="P",IF(A110="I","p i","p"),IF(A110="I","i"," ")),"")
C118: =IF(C117="C",IF(A118="P",IF(A117="I","p i","p"),IF(A117="I","i","")),"") | D118: =IF(D117="E",IF(A118="P",IF(A117="I","p i","p"),IF(A117="I","i"," ")),"") | E118: =IF(E117="O",IF(A118="P",IF(A117="I","p i","p"),IF(A117="I","i"," ")),"")
C125: =IF(C124="C",IF(A125="P",IF(A124="I","p i","p"),IF(A124="I","i","")),"") | D125: =IF(D124="E",IF(A125="P",IF(A124="I","p i","p"),IF(A124="I","i"," ")),"") | E125: =IF(E124="O",IF(A125="P",IF(A124="I","p i","p"),IF(A124="I","i"," ")),"")
C132: =IF(C131="C",IF(A132="P",IF(A131="I","p i","p"),IF(A131="I","i","")),"") | D132: =IF(D131="E",IF(A132="P",IF(A131="I","p i","p"),IF(A131="I","i"," ")),"") | E132: =IF(E131="O",IF(A132="P",IF(A131="I","p i","p"),IF(A131="I","i"," ")),"")
C139: =IF(C138="C",IF(A139="P",IF(A138="I","p i","p"),IF(A138="I","i","")),"") | D139: =IF(D138="E",IF(A139="P",IF(A138="I","p i","p"),IF(A138="I","i"," ")),"") | E139: =IF(E138="O",IF(A139="P",IF(A138="I","p i","p"),IF(A138="I","i"," ")),"")
C146: =IF(C145="C",IF(A146="P",IF(A145="I","p i","p"),IF(A145="I","i","")),"") | D146: =IF(D145="E",IF(A146="P",IF(A145="I","p i","p"),IF(A145="I","i"," ")),"") | E146: =IF(E145="O",IF(A146="P",IF(A145="I","p i","p"),IF(A145="I","i"," ")),"")
C153: =IF(C152="C",IF(A153="P",IF(A152="I","p i","p"),IF(A152="I","i","")),"") | D153: =IF(D152="E",IF(A153="P",IF(A152="I","p i","p"),IF(A152="I","i"," ")),"") | E153: =IF(E152="O",IF(A153="P",IF(A152="I","p i","p"),IF(A152="I","i"," ")),"")
C160: =IF(C159="C",IF(A160="P",IF(A159="I","p i","p"),IF(A159="I","i","")),"") | D160: =IF(D159="E",IF(A160="P",IF(A159="I","p i","p"),IF(A159="I","i"," ")),"") | E160: =IF(E159="O",IF(A160="P",IF(A159="I","p i","p"),IF(A159="I","i"," ")),"")
C161: =IF(C160="C",IF(A161="Prioritaire",IF(A160="I","p i","p"),IF(A160="I","i","")),"") | D161: =IF(D160="E",IF(A161="Prioritaire",IF(A160="I","p i","p"),IF(A160="I","i"," ")),"") | E161: =IF(E160="O",IF(A161="Prioritaire",IF(A160="I","p i","p"),IF(A160="I","i"," ")),"")
C167: =IF(C166="C",IF(A167="P",IF(A166="I","p i","p"),IF(A166="I","i","")),"") | D167: =IF(D166="E",IF(A167="P",IF(A166="I","p i","p"),IF(A166="I","i"," ")),"") | E167: =IF(E166="O",IF(A167="P",IF(A166="I","p i","p"),IF(A166="I","i"," ")),"")
C174: =IF(C173="C",IF(A174="P",IF(A173="I","p i","p"),IF(A173="I","i","")),"") | D174: =IF(D173="E",IF(A174="P",IF(A173="I","p i","p"),IF(A173="I","i"," ")),"") | E174: =IF(E173="O",IF(A174="P",IF(A173="I","p i","p"),IF(A173="I","i"," ")),"")
C181: =IF(C180="C",IF(A181="P",IF(A180="I","p i","p"),IF(A180="I","i","")),"") | D181: =IF(D180="E",IF(A181="P",IF(A180="I","p i","p"),IF(A180="I","i"," ")),"") | E181: =IF(E180="O",IF(A181="P",IF(A180="I","p i","p"),IF(A180="I","i"," ")),"")
C188: =IF(C187="C",IF(A188="P",IF(A187="I","p i","p"),IF(A187="I","i","")),"") | D188: =IF(D187="E",IF(A188="P",IF(A187="I","p i","p"),IF(A187="I","i"," ")),"") | E188: =IF(E187="O",IF(A188="P",IF(A187="I","p i","p"),IF(A187="I","i"," ")),"")
C195: =IF(C194="C",IF(A195="P",IF(A194="I","p i","p"),IF(A194="I","i","")),"") | D195: =IF(D194="E",IF(A195="P",IF(A194="I","p i","p"),IF(A194="I","i"," ")),"") | E195: =IF(E194="O",IF(A195="P",IF(A194="I","p i","p"),IF(A194="I","i"," ")),"")
C202: =IF(C201="C",IF(A202="P",IF(A201="I","p i","p"),IF(A201="I","i","")),"") | D202: =IF(D201="E",IF(A202="P",IF(A201="I","p i","p"),IF(A201="I","i"," ")),"") | E202: =IF(E201="O",IF(A202="P",IF(A201="I","p i","p"),IF(A201="I","i"," ")),"")
C209: =IF(C208="C",IF(A209="P",IF(A208="I","p i","p"),IF(A208="I","i","")),"") | D209: =IF(D208="E",IF(A209="P",IF(A208="I","p i","p"),IF(A208="I","i"," ")),"") | E209: =IF(E208="O",IF(A209="P",IF(A208="I","p i","p"),IF(A208="I","i"," ")),"")
...

Sheet 2.2
A1: =Bilan!B15 -> 2.2 Analyse des réponses, du DCE et du marché
C3: C | D3: E | E3: O | F3: Total
B4: Nb quest. | C4: =COUNTIF(C8:C708,C3) -> 18 | D4: =COUNTIF(D8:D708,D3) -> 17 | E4: =COUNTIF(E8:E708,E3) -> 0 | F4: =COUNTA(B8:B708) -> 18
B5: Illust. | C5: =COUNTIF(C8:C708,"i")+COUNTIF(C8:C708,"p i") -> 4 | D5: =COUNTIF(D8:D708,"i")+COUNTIF(D8:D708,"p i") -> 4 | E5: =COUNTIF(E8:E708,"i")+COUNTIF(E8:E708,"p i") -> 0 | F5: =COUNTIF(A8:A708,"I") -> 4
B6: Prio | C6: =COUNTIF(C8:C708,"p")+COUNTIF(C8:C708,"p i") -> 3 | D6: =COUNTIF(D8:D708,"p")+COUNTIF(D8:D708,"p i") -> 3 | E6: =COUNTIF(E8:E708,"p")+COUNTIF(E8:E708,"p i") -> 0 | F6: =COUNTIF(A8:A708,"P") -> 3
B8: 2-2_001 | C8: C | D8: E | F8: Si un déclarant n'a pas reçu de réponse à sa DICT dans les délais, pour quel réseau parmi les suivants doit-il attendre avant de commencer les travaux ?
A9: P | C9: =IF(C8="C",IF(A9="P",IF(A8="I","p i","p"),IF(A8="I","i","")),"") -> p | D9: =IF(D8="E",IF(A9="P",IF(A8="I","p i","p"),IF(A8="I","i"," ")),"") -> p | E9: =IF(E8="O",IF(A9="P",IF(A8="I","p i","p"),IF(A8="I","i"," ")),"") | F9: A | G9: Eclairage public
A10: R554-26VI | F10: B | G10: Télécommunication
F11: C | G11: Adduction d'eau
F12: D | G12: Je ne sais pas
B14: 2-2_002 | C14: C | D14: E | F14: Après avoir relancé les exploitants n'ayant pas répondu dans le délai réglementaire à la DICT, je peux commencer les travaux 2 jours après cette relance même sans réponse d'un exploitant :
C15: =IF(C14="C",IF(A15="P",IF(A14="I","p i","p"),IF(A14="I","i","")),"") | D15: =IF(D14="E",IF(A15="P",IF(A14="I","p i","p"),IF(A14="I","i"," ")),"") | E15: =IF(E14="O",IF(A15="P",IF(A14="I","p i","p"),IF(A14="I","i"," ")),"") | F15: A | G15: D'un réseau de transport d'hydrocarbures
A16: R554-26VI | F16: B | G16: D'un réseau électrique
F17: C | G17: D'un réseau téléphonique
F18: D | G18: Je ne sais pas
B20: 2-2_004 | C20: C | D20: E | F20: De combien de jours (sauf jours fériés) dispose l'exploitant pour répondre à une DICT dématérialisée ?
A21: P | C21: =IF(C20="C",IF(A21="P",IF(A20="I","p i","p"),IF(A20="I","i","")),"") -> p | D21: =IF(D20="E",IF(A21="P",IF(A20="I","p i","p"),IF(A20="I","i"," ")),"") -> p | E21: =IF(E20="O",IF(A21="P",IF(A20="I","p i","p"),IF(A20="I","i"," ")),"") | F21: A | G21: 7 jours
A22: R554-26I | C22: =IF(C21="C",IF(A22="P",IF(A21="I","p i","p"),IF(A21="I","i","")),"") | D22: =IF(D21="E",IF(A22="P",IF(A21="I","p i","p"),IF(A21="I","i"," ")),"") | E22: =IF(E21="O",IF(A22="P",IF(A21="I","p i","p"),IF(A21="I","i"," ")),"") | F22: B | G22: 9 jours
F23: C | G23: 15 jours
F24: D | G24: Je ne sais pas
B26: 2-2_005 | C26: C | D26: E | F26: De combien de jours (sauf jours fériés) dispose l'exploitant pour répondre à une DICT NON dématérialisée (courrier, fax...) ?
A27: P | C27: =IF(C26="C",IF(A27="P",IF(A26="I","p i","p"),IF(A26="I","i","")),"") -> p | D27: =IF(D26="E",IF(A27="P",IF(A26="I","p i","p"),IF(A26="I","i"," ")),"") -> p | E27: =IF(E26="O",IF(A27="P",IF(A26="I","p i","p"),IF(A26="I","i"," ")),"") | F27: A | G27: 7 jours
A28: R554-26I | F28: B | G28: 9 jours
F29: C | G29: 15 jours
F30: D | G30: Je ne sais pas
B32: 2-2_006 | C32: C | D32: E | F32: Suite à une relance pour non réponse à une DICT, l'exploitant doit répondre dans un délai de :
C33: =IF(C32="C",IF(A33="P",IF(A32="I","p i","p"),IF(A32="I","i","")),"") | D33: =IF(D32="E",IF(A33="P",IF(A32="I","p i","p"),IF(A32="I","i"," ")),"") | E33: =IF(E32="O",IF(A33="P",IF(A32="I","p i","p"),IF(A32="I","i"," ")),"") | F33: A | G33: 2 jours ouvrés
A34: R554-26VI | F34: B | G34: 7 jours ouvrés
F35: C | G35: 9 jours ouvrés
F36: D | G36: Je ne sais pas
B38: 2-2_007 | C38: C | D38: E | F38: Suite à une DICT, dans quel cas les plans des réseaux peuvent ne pas être joints au récépissé fourni par l'exploitant ?
F39: A | G39: L'exploitant prévoit une réunion sur site
A40: R554-26I | F40: B | G40: Aucun réseau sensible pour la sécurité n'est présent dans l'emprise des travaux
F41: C | G41: Un seul réseau est présent dans l'emprise des travaux
F42: D | G42: Je ne sais pas
B44: 2-2_008 | C44: C | F44: Lorsque le dossier de consultation d’un marché de travaux ne contient pas les récépissés de DT, le responsable de projet (ou maître d'ouvrage) :
C45: =IF(C44="C",IF(A45="P",IF(A44="I","p i","p"),IF(A44="I","i","")),"") | F45: A | G45: Attribue son marché en l’état, dès lors que les entreprises candidates n’ont pas demandé à disposer de ces éléments
A46: R554-23I | F46: B | G46: Fait les DT en vue de transmettre leurs récépissés aux candidats avant attribution du marché
F47: C | G47: Précise que la responsabilité d'identification des réseaux est du ressort exclusif de l'exécutant des travaux
F48: D | G48: Je ne sais pas
...

Sheet 2.3
A1: =Bilan!B16 -> 2.3 Compétences des personnels
C3: C | D3: E | E3: O | F3: Total
B4: Nb quest. | C4: =COUNTIF(C8:C632,C3) -> 5 | D4: =COUNTIF(D8:D632,D3) -> 16 | E4: =COUNTIF(E8:E632,E3) -> 14 | F4: =COUNTA(B8:B632) -> 18
B5: Illust. | C5: =COUNTIF(C8:C632,"i")+COUNTIF(C8:C632,"p i") -> 3 | D5: =COUNTIF(D8:D632,"i")+COUNTIF(D8:D632,"p i") -> 14 | E5: =COUNTIF(E8:E632,"i")+COUNTIF(E8:E632,"p i") -> 14 | F5: =COUNTIF(A8:A632,"I") -> 16
B6: Prio | C6: =COUNTIF(C8:C632,"p")+COUNTIF(C8:C632,"p i") -> 1 | D6: =COUNTIF(D8:D632,"p")+COUNTIF(D8:D632,"p i") -> 4 | E6: =COUNTIF(E8:E632,"p")+COUNTIF(E8:E632,"p i") -> 1 | F6: =COUNTIF(A8:A632,"P") -> 4
A8: I | B8: 2-3_003 | D8: E | E8: O | F8: Que dois-je faire si je découvre un câble électrique dénudé ?
C9: =IF(C8="C",IF(A9="P",IF(A8="I","p i","p"),IF(A8="I","i","")),"") | D9: =IF(D8="E",IF(A9="P",IF(A8="I","p i","p"),IF(A8="I","i"," ")),"") -> i | E9: =IF(E8="O",IF(A9="P",IF(A8="I","p i","p"),IF(A8="I","i"," ")),"") -> i | F9: A | G9: Je mets des lunettes de protection
A10: R554-31II | F10: B | G10: Je m'écarte tout de suite de la zone
F11: C | G11: Je dégage le câble en évitant de le toucher
F12: D | G12: Je ne sais pas
B14: 2-3_004 | C14: C | D14: E | F14: Une entreprise exécutant des travaux non urgents doit délivrer une autorisation d'intervention à proximité des réseaux (AIPR) :
A15: P | C15: =IF(C14="C",IF(A15="P",IF(A14="I","p i","p"),IF(A14="I","i","")),"") -> p | D15: =IF(D14="E",IF(A15="P",IF(A14="I","p i","p"),IF(A14="I","i"," ")),"") -> p | E15: =IF(E14="O",IF(A15="P",IF(A14="I","p i","p"),IF(A14="I","i"," ")),"") | F15: A | G15: Uniquement à l'encadrant des travaux
A16: A15-2-12/art21I | F16: B | G16: A l'encadrant des travaux et aux conducteurs d'engins intervenant sur le chantier
F17: C | G17: Uniquement aux conducteurs d'engins intervenant sur le chantier
F18: D | G18: Je ne sais pas
A20: I | B20: 2-3_011 | D20: E | E20: O | F20: Quels sont les risques principaux liés à un réseau d'assainissement ?
C21: =IF(C20="C",IF(A21="P",IF(A20="I","p i","p"),IF(A20="I","i","")),"") | D21: =IF(D20="E",IF(A21="P",IF(A20="I","p i","p"),IF(A20="I","i"," ")),"") -> i | E21: =IF(E20="O",IF(A21="P",IF(A20="I","p i","p"),IF(A20="I","i"," ")),"") -> i | F21: A | G21: Asphyxie et intoxication
A22: § 3.9 du GT | F22: B | G22: Electrisation et électrocution
F23: C | G23: Hydrocution
F24: D | G24: Je ne sais pas
A26: I | B26: 2-3_013e | D26: E | F26: Pendant toute la durée de travaux à proximité d'un réseau de gaz, il faut dans tous les cas :
A27: P | C27: =IF(C26="C",IF(A27="P",IF(A26="I","p i","p"),IF(A26="I","i","")),"") | D27: =IF(D26="E",IF(A27="P",IF(A26="I","p i","p"),IF(A26="I","i"," ")),"") -> p i | E27: =IF(E26="O",IF(A27="P",IF(A26="I","p i","p"),IF(A26="I","i"," ")),"") | F27: A | G27: Maintenir les accès aux vannes d’arrêt
A28: R554-31II | F28: B | G28: Interdire tout matériel électrique
F29: C | G29: Porter un masque respiratoire
F30: D | G30: Je ne sais pas
A32: I | B32: 2-3_013o | E32: O | F32: Pendant toute la durée de travaux à proximité d'un réseau de gaz, il faut dans tous les cas :
C33: =IF(C32="C",IF(A33="P",IF(A32="I","p i","p"),IF(A32="I","i","")),"") | D33: =IF(D32="E",IF(A33="P",IF(A32="I","p i","p"),IF(A32="I","i"," ")),"") | E33: =IF(E32="O",IF(A33="P",IF(A32="I","p i","p"),IF(A32="I","i"," ")),"") -> i | F33: A | G33: Maintenir les accès aux vannes d’arrêt
A34: R554-31II | F34: B | G34: Interdire tout matériel électrique
F35: C | G35: Porter un masque respiratoire
F36: D | G36: Je ne sais pas
A38: I | B38: 2-3_015e | D38: E | F38: Un conducteur d'engin peut démarrer le terrassement dès qu'il a les informations sur :
A39: P | C39: =IF(C38="C",IF(A39="P",IF(A38="I","p i","p"),IF(A38="I","i","")),"") | D39: =IF(D38="E",IF(A39="P",IF(A38="I","p i","p"),IF(A38="I","i"," ")),"") -> p i | E39: =IF(E38="O",IF(A39="P",IF(A38="I","p i","p"),IF(A38="I","i"," ")),"") | F39: A | G39: L' ouvrage souterrain sur lequel il doit travailler
A40: R554-27 I | F40: B | G40: Les réseaux dangereux situés dans la zone de travail (gaz, électricité)
F41: C | G41: Tous les ouvrages souterrains signalés par le marquage-piquetage
F42: D | G42: Je ne sais pas
A44: I | B44: 2-3_015o | E44: O | F44: Un conducteur d'engin peut démarrer le terrassement dès qu'il a les informations sur :
C45: =IF(C44="C",IF(A45="P",IF(A44="I","p i","p"),IF(A44="I","i","")),"") | D45: =IF(D44="E",IF(A45="P",IF(A44="I","p i","p"),IF(A44="I","i"," ")),"") | E45: =IF(E44="O",IF(A45="P",IF(A44="I","p i","p"),IF(A44="I","i"," ")),"") -> i | F45: A | G45: L' ouvrage souterrain sur lequel il doit travailler
A46: R554-27 I | F46: B | G46: Les réseaux dangereux situés dans la zone de travail (gaz, électricité)
F47: C | G47: Tous les ouvrages souterrains signalés par le marquage-piquetage
F48: D | G48: Je ne sais pas
...

Sheet 2.4
A1: =Bilan!B17 -> 2.4 Application du guide technique
C3: C | D3: E | E3: O | F3: Total
B4: Nb quest. | C4: =COUNTIF(C8:C706,C3) -> 23 | D4: =COUNTIF(D8:D706,D3) -> 28 | E4: =COUNTIF(E8:E706,E3) -> 23 | F4: =COUNTA(B8:B706) -> 38
B5: Illust. | C5: =COUNTIF(C8:C706,"i")+COUNTIF(C8:C706,"p i") -> 12 | D5: =COUNTIF(D8:D706,"i")+COUNTIF(D8:D706,"p i") -> 16 | E5: =COUNTIF(E8:E706,"i")+COUNTIF(E8:E706,"p i") -> 19 | F5: =COUNTIF(A8:A706,"I") -> 26
B6: Prio | C6: =COUNTIF(C8:C706,"p")+COUNTIF(C8:C706,"p i") -> 3 | D6: =COUNTIF(D8:D706,"p")+COUNTIF(D8:D706,"p i") -> 4 | E6: =COUNTIF(E8:E706,"p")+COUNTIF(E8:E706,"p i") -> 2 | F6: =COUNTIF(A8:A706,"P") -> 5
A8: I | B8: 2-4_002 | C8: C | D8: E | E8: O | F8: Si l'on ne connaît pas la tension de la ligne électrique, il faut que le godet se trouve toujours à plus de :
A9: P | C9: =IF(C8="C",IF(A9="P",IF(A8="I","p i","p"),IF(A8="I","i","")),"") -> p i | D9: =IF(D8="E",IF(A9="P",IF(A8="I","p i","p"),IF(A8="I","i"," ")),"") -> p i | E9: =IF(E8="O",IF(A9="P",IF(A8="I","p i","p"),IF(A8="I","i"," ")),"") -> p i | F9: A | G9: 1 mètre
A10: § 6 du GT | F10: B | G10: 2 mètres
A11: TC OPERATEUR | F11: C | G11: 5 mètres
F12: D | G12: Je ne sais pas
A14: I | B14: 2-4_003 | C14: C | D14: E | E14: O | F14: Quand je travaille près d'une ligne aérienne à très haute tension (plus de 50 000 Volts), je dois rester à plus de 5 mètres : | H14: x
C15: =IF(C14="C",IF(A15="P",IF(A14="I","p i","p"),IF(A14="I","i","")),"") -> i | D15: =IF(D14="E",IF(A15="P",IF(A14="I","p i","p"),IF(A14="I","i"," ")),"") -> i | E15: =IF(E14="O",IF(A15="P",IF(A14="I","p i","p"),IF(A14="I","i"," ")),"") -> i | F15: A | G15: Du fil électrique le plus proche
A16: § 6.1 du GT | F16: B | G16: Du sol
F17: C | G17: Du pylône
F18: D | G18: Je ne sais pas
A20: I | B20: 2-4_004 | C20: C | D20: E | E20: O | F20: Quand je travaille près d'une ligne aérienne haute tension (plus de 1000 Volts), le godet doit toujours se trouver à plus de :
C21: =IF(C20="C",IF(A21="P",IF(A20="I","p i","p"),IF(A20="I","i","")),"") -> i | D21: =IF(D20="E",IF(A21="P",IF(A20="I","p i","p"),IF(A20="I","i"," ")),"") -> i | E21: =IF(E20="O",IF(A21="P",IF(A20="I","p i","p"),IF(A20="I","i"," ")),"") -> i | F21: A | G21: 3 mètres
A22: § 6 du GT | F22: B | G22: 5 mètres
F23: C | G23: 7 mètres
F24: D | G24: Je ne sais pas
B26: 2-4_007 | C26: C | D26: E | E26: O | F26: Avec une pelle hydraulique (précision annoncée : 0,15 m), jusqu'à quelle distance du marquage d'un réseau rigide de diamètre 60 mm et de classe de précision A peut-on terrasser sans précaution particulière ?
C27: =IF(C26="C",IF(A27="P",IF(A26="I","p i","p"),IF(A26="I","i","")),"") | D27: =IF(D26="E",IF(A27="P",IF(A26="I","p i","p"),IF(A26="I","i"," ")),"") | F27: A | G27: 0,40 + 0,15 = 0,55 m
A28: GT - 5.2.5 | F28: B | G28: 0,40 m
F29: C | G29: 0,40 - 0,15 = 0,25 m
F30: D | G30: Je ne sais pas
B32: 2-4_008 | C32: C | D32: E | E32: O | F32: Avec une pelle hydraulique (précision annoncée : 0,15 m), jusqu'à quelle distance du marquage d'un réseau souple de diamètre 60 mm et de classe de précision A peut-on terrasser sans précaution particulière ?
F33: A | G33: 0,50 - 0,15 = 0,35 m
A34: GT - 5.2.5 | F34: B | G34: 0,50 m
F35: C | G35: 0,50 + 0,15 = 0,65 m
F36: D | G36: Je ne sais pas
A39: I | B39: 2-4_009 | C39: C | D39: E | E39: O | F39: Au dessus d'un réseau, on peut utiliser un engin lourd (pelle hydraulique, raboteuse, BRH…) :
C40: =IF(C39="C",IF(A40="P",IF(A39="I","p i","p"),IF(A39="I","i","")),"") -> i | D40: =IF(D39="E",IF(A40="P",IF(A39="I","p i","p"),IF(A39="I","i"," ")),"") -> i | E40: =IF(E39="O",IF(A40="P",IF(A39="I","p i","p"),IF(A39="I","i"," ")),"") -> i | F40: A | G40: Jusqu'à la découverte du grillage avertisseur
A41: Fiche AT-PEL du GT | F41: B | G41: Pour enlever la couche de surface dure
A42: TC OPERATEUR | F42: C | G42: Jusqu'à 10 cm du réseau enterré
F43: D | G43: Je ne sais pas
B45: 2-4_010 | C45: C | D45: E | F45: Le remplacement d'un potelet sans élargissement de la fouille initiale est dispensé de DT et DICT lorsqu'il s'effectue :
C46: =IF(C45="C",IF(A46="P",IF(A45="I","p i","p"),IF(A45="I","i","")),"") | D46: =IF(D45="E",IF(A46="P",IF(A45="I","p i","p"),IF(A45="I","i"," ")),"") | F46: A | G46: A moins de 70 cm de profondeur et à plus d'1 mètre de tout affleurant
A47: R554-1b) | F47: B | G47: A moins de 40 cm de profondeur et à plus de 50 cm de tout affleurant
F48: C | G48: A moins de 40 cm de profondeur et à plus d'1 mètre de tout affleurant
F49: D | G49: Je ne sais pas
...

Sheet 2.5
A1: =Bilan!B18 -> 2.5 Lecture des indices et affleurants
C3: C | D3: E | E3: O | F3: Total
B4: Nb quest. | C4: =COUNTIF(C8:C631,C3) -> 21 | D4: =COUNTIF(D8:D631,D3) -> 25 | E4: =COUNTIF(E8:E631,E3) -> 24 | F4: =COUNTA(B8:B631) -> 28
